<?xml version="1.0"?><robot name="ted">
	<link name="0">
		<visual>
			<geometry>
				<cylinder length="0.6573633218766318" radius="0.2871398936343106"/>
			</geometry>
		</visual>
		<collision>
			<geometry>
				<cylinder length="0.6573633218766318" radius="0.2871398936343106"/>
			</geometry>
		</collision>
		<inertial>
			<mass value="0.2412296096159241"/>
			<inertia ixx="0.0003" iyy="0.0003" izz="0.0003"/>
		</inertial>
	</link>
	<link name="11">
		<visual>
			<geometry>
				<cylinder length="0.1496859812569581" radius="0.9082787273646443"/>
			</geometry>
		</visual>
		<collision>
			<geometry>
				<cylinder length="0.1496859812569581" radius="0.9082787273646443"/>
			</geometry>
		</collision>
		<inertial>
			<mass value="0.03348456968220448"/>
			<inertia ixx="0.0003" iyy="0.0003" izz="0.0003"/>
		</inertial>
	</link>
	<link name="22">
		<visual>
			<geometry>
				<cylinder length="0.7750099995097031" radius="0.03879150919790486"/>
			</geometry>
		</visual>
		<collision>
			<geometry>
				<cylinder length="0.7750099995097031" radius="0.03879150919790486"/>
			</geometry>
		</collision>
		<inertial>
			<mass value="0.3347560652499726"/>
			<inertia ixx="0.0003" iyy="0.0003" izz="0.0003"/>
		</inertial>
	</link>
	<link name="23">
		<visual>
			<geometry>
				<cylinder length="0.7750099995097031" radius="0.03879150919790486"/>
			</geometry>
		</visual>
		<collision>
			<geometry>
				<cylinder length="0.7750099995097031" radius="0.03879150919790486"/>
			</geometry>
		</collision>
		<inertial>
			<mass value="0.3347560652499726"/>
			<inertia ixx="0.0003" iyy="0.0003" izz="0.0003"/>
		</inertial>
	</link>
	<link name="24">
		<visual>
			<geometry>
				<cylinder length="0.7750099995097031" radius="0.03879150919790486"/>
			</geometry>
		</visual>
		<collision>
			<geometry>
				<cylinder length="0.7750099995097031" radius="0.03879150919790486"/>
			</geometry>
		</collision>
		<inertial>
			<mass value="0.3347560652499726"/>
			<inertia ixx="0.0003" iyy="0.0003" izz="0.0003"/>
		</inertial>
	</link>
	<link name="15">
		<visual>
			<geometry>
				<cylinder length="0.1496859812569581" radius="0.9082787273646443"/>
			</geometry>
		</visual>
		<collision>
			<geometry>
				<cylinder length="0.1496859812569581" radius="0.9082787273646443"/>
			</geometry>
		</collision>
		<inertial>
			<mass value="0.03348456968220448"/>
			<inertia ixx="0.0003" iyy="0.0003" izz="0.0003"/>
		</inertial>
	</link>
	<link name="26">
		<visual>
			<geometry>
				<cylinder length="0.7750099995097031" radius="0.03879150919790486"/>
			</geometry>
		</visual>
		<collision>
			<geometry>
				<cylinder length="0.7750099995097031" radius="0.03879150919790486"/>
			</geometry>
		</collision>
		<inertial>
			<mass value="0.3347560652499726"/>
			<inertia ixx="0.0003" iyy="0.0003" izz="0.0003"/>
		</inertial>
	</link>
	<link name="27">
		<visual>
			<geometry>
				<cylinder length="0.7750099995097031" radius="0.03879150919790486"/>
			</geometry>
		</visual>
		<collision>
			<geometry>
				<cylinder length="0.7750099995097031" radius="0.03879150919790486"/>
			</geometry>
		</collision>
		<inertial>
			<mass value="0.3347560652499726"/>
			<inertia ixx="0.0003" iyy="0.0003" izz="0.0003"/>
		</inertial>
	</link>
	<link name="28">
		<visual>
			<geometry>
				<cylinder length="0.7750099995097031" radius="0.03879150919790486"/>
			</geometry>
		</visual>
		<collision>
			<geometry>
				<cylinder length="0.7750099995097031" radius="0.03879150919790486"/>
			</geometry>
		</collision>
		<inertial>
			<mass value="0.3347560652499726"/>
			<inertia ixx="0.0003" iyy="0.0003" izz="0.0003"/>
		</inertial>
	</link>
	<joint name="0_to_11" type="revolute">
		<parent link="0"/>
		<child link="11"/>
		<axis xyz="1 0 0"/>
		<limit effort="1" velocity="1"/>
		<origin rpy="7.052425458248692 2.6296361898905904 4.506113772165355" xyz="0.5826968548142001 0.7319186353717901 0.2558917238483778"/>
	</joint>
	<joint name="11_to_22" type="fixed">
		<parent link="11"/>
		<child link="22"/>
		<axis xyz="1 0 0"/>
		<limit effort="1" velocity="1"/>
		<origin rpy="3.6117890591241237 1.6373332929494908 4.089191677937729" xyz="0.7518519160738443 0.05442155615922484 0.04235412016236306"/>
	</joint>
	<joint name="11_to_23" type="fixed">
		<parent link="11"/>
		<child link="23"/>
		<axis xyz="1 0 0"/>
		<limit effort="1" velocity="1"/>
		<origin rpy="5.417683588686185 1.6373332929494908 4.089191677937729" xyz="0.7518519160738443 0.05442155615922484 0.04235412016236306"/>
	</joint>
	<joint name="11_to_24" type="fixed">
		<parent link="11"/>
		<child link="24"/>
		<axis xyz="1 0 0"/>
		<limit effort="1" velocity="1"/>
		<origin rpy="7.2235781182482475 1.6373332929494908 4.089191677937729" xyz="0.7518519160738443 0.05442155615922484 0.04235412016236306"/>
	</joint>
	<joint name="0_to_15" type="revolute">
		<parent link="0"/>
		<child link="15"/>
		<axis xyz="1 0 0"/>
		<limit effort="1" velocity="1"/>
		<origin rpy="10.578638187373038 2.6296361898905904 4.506113772165355" xyz="0.5826968548142001 0.7319186353717901 0.2558917238483778"/>
	</joint>
	<joint name="15_to_26" type="fixed">
		<parent link="15"/>
		<child link="26"/>
		<axis xyz="1 0 0"/>
		<limit effort="1" velocity="1"/>
		<origin rpy="3.6117890591241237 1.6373332929494908 4.089191677937729" xyz="0.7518519160738443 0.05442155615922484 0.04235412016236306"/>
	</joint>
	<joint name="15_to_27" type="fixed">
		<parent link="15"/>
		<child link="27"/>
		<axis xyz="1 0 0"/>
		<limit effort="1" velocity="1"/>
		<origin rpy="5.417683588686185 1.6373332929494908 4.089191677937729" xyz="0.7518519160738443 0.05442155615922484 0.04235412016236306"/>
	</joint>
	<joint name="15_to_28" type="fixed">
		<parent link="15"/>
		<child link="28"/>
		<axis xyz="1 0 0"/>
		<limit effort="1" velocity="1"/>
		<origin rpy="7.2235781182482475 1.6373332929494908 4.089191677937729" xyz="0.7518519160738443 0.05442155615922484 0.04235412016236306"/>
	</joint>
</robot>
