<?xml version="1.0"?><robot name="ted">
	<link name="0">
		<visual>
			<geometry>
				<cylinder length="0.6708473124047619" radius="0.5355623986449429"/>
			</geometry>
		</visual>
		<collision>
			<geometry>
				<cylinder length="0.6708473124047619" radius="0.5355623986449429"/>
			</geometry>
		</collision>
		<inertial>
			<mass value="0.5301131038898502"/>
			<inertia ixx="0.0003" iyy="0.0003" izz="0.0003"/>
		</inertial>
	</link>
	<link name="11">
		<visual>
			<geometry>
				<cylinder length="0.750495612183022" radius="0.7761980235104629"/>
			</geometry>
		</visual>
		<collision>
			<geometry>
				<cylinder length="0.750495612183022" radius="0.7761980235104629"/>
			</geometry>
		</collision>
		<inertial>
			<mass value="0.6608165995406313"/>
			<inertia ixx="0.0003" iyy="0.0003" izz="0.0003"/>
		</inertial>
	</link>
	<link name="22">
		<visual>
			<geometry>
				<cylinder length="0.5363185494668233" radius="0.2766123611849439"/>
			</geometry>
		</visual>
		<collision>
			<geometry>
				<cylinder length="0.5363185494668233" radius="0.2766123611849439"/>
			</geometry>
		</collision>
		<inertial>
			<mass value="0.36466399389028514"/>
			<inertia ixx="0.0003" iyy="0.0003" izz="0.0003"/>
		</inertial>
	</link>
	<link name="23">
		<visual>
			<geometry>
				<cylinder length="0.5363185494668233" radius="0.2766123611849439"/>
			</geometry>
		</visual>
		<collision>
			<geometry>
				<cylinder length="0.5363185494668233" radius="0.2766123611849439"/>
			</geometry>
		</collision>
		<inertial>
			<mass value="0.36466399389028514"/>
			<inertia ixx="0.0003" iyy="0.0003" izz="0.0003"/>
		</inertial>
	</link>
	<link name="24">
		<visual>
			<geometry>
				<cylinder length="0.5363185494668233" radius="0.2766123611849439"/>
			</geometry>
		</visual>
		<collision>
			<geometry>
				<cylinder length="0.5363185494668233" radius="0.2766123611849439"/>
			</geometry>
		</collision>
		<inertial>
			<mass value="0.36466399389028514"/>
			<inertia ixx="0.0003" iyy="0.0003" izz="0.0003"/>
		</inertial>
	</link>
	<link name="15">
		<visual>
			<geometry>
				<cylinder length="0.750495612183022" radius="0.7761980235104629"/>
			</geometry>
		</visual>
		<collision>
			<geometry>
				<cylinder length="0.750495612183022" radius="0.7761980235104629"/>
			</geometry>
		</collision>
		<inertial>
			<mass value="0.6608165995406313"/>
			<inertia ixx="0.0003" iyy="0.0003" izz="0.0003"/>
		</inertial>
	</link>
	<link name="26">
		<visual>
			<geometry>
				<cylinder length="0.5363185494668233" radius="0.2766123611849439"/>
			</geometry>
		</visual>
		<collision>
			<geometry>
				<cylinder length="0.5363185494668233" radius="0.2766123611849439"/>
			</geometry>
		</collision>
		<inertial>
			<mass value="0.36466399389028514"/>
			<inertia ixx="0.0003" iyy="0.0003" izz="0.0003"/>
		</inertial>
	</link>
	<link name="27">
		<visual>
			<geometry>
				<cylinder length="0.5363185494668233" radius="0.2766123611849439"/>
			</geometry>
		</visual>
		<collision>
			<geometry>
				<cylinder length="0.5363185494668233" radius="0.2766123611849439"/>
			</geometry>
		</collision>
		<inertial>
			<mass value="0.36466399389028514"/>
			<inertia ixx="0.0003" iyy="0.0003" izz="0.0003"/>
		</inertial>
	</link>
	<link name="28">
		<visual>
			<geometry>
				<cylinder length="0.5363185494668233" radius="0.2766123611849439"/>
			</geometry>
		</visual>
		<collision>
			<geometry>
				<cylinder length="0.5363185494668233" radius="0.2766123611849439"/>
			</geometry>
		</collision>
		<inertial>
			<mass value="0.36466399389028514"/>
			<inertia ixx="0.0003" iyy="0.0003" izz="0.0003"/>
		</inertial>
	</link>
	<joint name="0_to_11" type="revolute">
		<parent link="0"/>
		<child link="11"/>
		<axis xyz="1 0 0"/>
		<limit effort="1" velocity="1"/>
		<origin rpy="11.584333380566894 1.932982834810668 4.437734220967872" xyz="0.904066690124414 0.49412361786727677 0.5722745687416606"/>
	</joint>
	<joint name="11_to_22" type="revolute">
		<parent link="11"/>
		<child link="22"/>
		<axis xyz="1 0 0"/>
		<limit effort="1" velocity="1"/>
		<origin rpy="10.565530740733406 2.483966454281209 2.496973003856025" xyz="0.6319107371297262 0.6266655193750771 0.9152500838659247"/>
	</joint>
	<joint name="11_to_23" type="revolute">
		<parent link="11"/>
		<child link="23"/>
		<axis xyz="1 0 0"/>
		<limit effort="1" velocity="1"/>
		<origin rpy="15.848296111100108 2.483966454281209 2.496973003856025" xyz="0.6319107371297262 0.6266655193750771 0.9152500838659247"/>
	</joint>
	<joint name="11_to_24" type="revolute">
		<parent link="11"/>
		<child link="24"/>
		<axis xyz="1 0 0"/>
		<limit effort="1" velocity="1"/>
		<origin rpy="21.131061481466812 2.483966454281209 2.496973003856025" xyz="0.6319107371297262 0.6266655193750771 0.9152500838659247"/>
	</joint>
	<joint name="0_to_15" type="revolute">
		<parent link="0"/>
		<child link="15"/>
		<axis xyz="1 0 0"/>
		<limit effort="1" velocity="1"/>
		<origin rpy="17.37650007085034 1.932982834810668 4.437734220967872" xyz="0.904066690124414 0.49412361786727677 0.5722745687416606"/>
	</joint>
	<joint name="15_to_26" type="revolute">
		<parent link="15"/>
		<child link="26"/>
		<axis xyz="1 0 0"/>
		<limit effort="1" velocity="1"/>
		<origin rpy="10.565530740733406 2.483966454281209 2.496973003856025" xyz="0.6319107371297262 0.6266655193750771 0.9152500838659247"/>
	</joint>
	<joint name="15_to_27" type="revolute">
		<parent link="15"/>
		<child link="27"/>
		<axis xyz="1 0 0"/>
		<limit effort="1" velocity="1"/>
		<origin rpy="15.848296111100108 2.483966454281209 2.496973003856025" xyz="0.6319107371297262 0.6266655193750771 0.9152500838659247"/>
	</joint>
	<joint name="15_to_28" type="revolute">
		<parent link="15"/>
		<child link="28"/>
		<axis xyz="1 0 0"/>
		<limit effort="1" velocity="1"/>
		<origin rpy="21.131061481466812 2.483966454281209 2.496973003856025" xyz="0.6319107371297262 0.6266655193750771 0.9152500838659247"/>
	</joint>
</robot>
