<?xml version="1.0"?><robot name="ted">
	<link name="0">
		<visual>
			<geometry>
				<cylinder length="0.9307606622335557" radius="0.612155293778461"/>
			</geometry>
		</visual>
		<collision>
			<geometry>
				<cylinder length="0.9307606622335557" radius="0.612155293778461"/>
			</geometry>
		</collision>
		<inertial>
			<mass value="0.23407871841241357"/>
			<inertia ixx="0.0003" iyy="0.0003" izz="0.0003"/>
		</inertial>
	</link>
	<link name="11">
		<visual>
			<geometry>
				<cylinder length="0.45000327052615274" radius="0.875127749692599"/>
			</geometry>
		</visual>
		<collision>
			<geometry>
				<cylinder length="0.45000327052615274" radius="0.875127749692599"/>
			</geometry>
		</collision>
		<inertial>
			<mass value="0.4083755482210827"/>
			<inertia ixx="0.0003" iyy="0.0003" izz="0.0003"/>
		</inertial>
	</link>
	<link name="22">
		<visual>
			<geometry>
				<cylinder length="0.5813812536232463" radius="0.9352171682302326"/>
			</geometry>
		</visual>
		<collision>
			<geometry>
				<cylinder length="0.5813812536232463" radius="0.9352171682302326"/>
			</geometry>
		</collision>
		<inertial>
			<mass value="0.43293422327698383"/>
			<inertia ixx="0.0003" iyy="0.0003" izz="0.0003"/>
		</inertial>
	</link>
	<link name="23">
		<visual>
			<geometry>
				<cylinder length="0.5813812536232463" radius="0.9352171682302326"/>
			</geometry>
		</visual>
		<collision>
			<geometry>
				<cylinder length="0.5813812536232463" radius="0.9352171682302326"/>
			</geometry>
		</collision>
		<inertial>
			<mass value="0.43293422327698383"/>
			<inertia ixx="0.0003" iyy="0.0003" izz="0.0003"/>
		</inertial>
	</link>
	<link name="24">
		<visual>
			<geometry>
				<cylinder length="0.5813812536232463" radius="0.9352171682302326"/>
			</geometry>
		</visual>
		<collision>
			<geometry>
				<cylinder length="0.5813812536232463" radius="0.9352171682302326"/>
			</geometry>
		</collision>
		<inertial>
			<mass value="0.43293422327698383"/>
			<inertia ixx="0.0003" iyy="0.0003" izz="0.0003"/>
		</inertial>
	</link>
	<joint name="0_to_11" type="fixed">
		<parent link="0"/>
		<child link="11"/>
		<axis xyz="1 0 0"/>
		<limit effort="1" velocity="1"/>
		<origin rpy="5.957113464629277 1.1621065363046357 5.3823881901385535" xyz="0.5711361873981222 0.06355420971682557 0.8084972414942933"/>
	</joint>
	<joint name="0_to_22" type="revolute">
		<parent link="0"/>
		<child link="22"/>
		<axis xyz="1 0 0"/>
		<limit effort="1" velocity="1"/>
		<origin rpy="12.042250346720872 3.4761228631540915 4.603208052221171" xyz="0.33766691322269415 0.9268574764629836 0.5396408670947822"/>
	</joint>
	<joint name="0_to_23" type="revolute">
		<parent link="0"/>
		<child link="23"/>
		<axis xyz="1 0 0"/>
		<limit effort="1" velocity="1"/>
		<origin rpy="16.05633379562783 3.4761228631540915 4.603208052221171" xyz="0.33766691322269415 0.9268574764629836 0.5396408670947822"/>
	</joint>
	<joint name="0_to_24" type="revolute">
		<parent link="0"/>
		<child link="24"/>
		<axis xyz="1 0 0"/>
		<limit effort="1" velocity="1"/>
		<origin rpy="20.070417244534788 3.4761228631540915 4.603208052221171" xyz="0.33766691322269415 0.9268574764629836 0.5396408670947822"/>
	</joint>
</robot>
