<?xml version="1.0"?><robot name="ted">
	<link name="0">
		<visual>
			<geometry>
				<cylinder length="0.13868832693064048" radius="0.0941142212143401"/>
			</geometry>
		</visual>
		<collision>
			<geometry>
				<cylinder length="0.13868832693064048" radius="0.0941142212143401"/>
			</geometry>
		</collision>
		<inertial>
			<mass value="0.25557090861487364"/>
			<inertia ixx="0.0003" iyy="0.0003" izz="0.0003"/>
		</inertial>
	</link>
	<link name="11">
		<visual>
			<geometry>
				<cylinder length="0.5972762551418295" radius="0.9339401678585683"/>
			</geometry>
		</visual>
		<collision>
			<geometry>
				<cylinder length="0.5972762551418295" radius="0.9339401678585683"/>
			</geometry>
		</collision>
		<inertial>
			<mass value="0.6127226568258675"/>
			<inertia ixx="0.0003" iyy="0.0003" izz="0.0003"/>
		</inertial>
	</link>
	<link name="22">
		<visual>
			<geometry>
				<cylinder length="0.582604179302883" radius="0.4334042317981647"/>
			</geometry>
		</visual>
		<collision>
			<geometry>
				<cylinder length="0.582604179302883" radius="0.4334042317981647"/>
			</geometry>
		</collision>
		<inertial>
			<mass value="0.24348454094182403"/>
			<inertia ixx="0.0003" iyy="0.0003" izz="0.0003"/>
		</inertial>
	</link>
	<link name="13">
		<visual>
			<geometry>
				<cylinder length="0.5972762551418295" radius="0.9339401678585683"/>
			</geometry>
		</visual>
		<collision>
			<geometry>
				<cylinder length="0.5972762551418295" radius="0.9339401678585683"/>
			</geometry>
		</collision>
		<inertial>
			<mass value="0.6127226568258675"/>
			<inertia ixx="0.0003" iyy="0.0003" izz="0.0003"/>
		</inertial>
	</link>
	<link name="24">
		<visual>
			<geometry>
				<cylinder length="0.582604179302883" radius="0.4334042317981647"/>
			</geometry>
		</visual>
		<collision>
			<geometry>
				<cylinder length="0.582604179302883" radius="0.4334042317981647"/>
			</geometry>
		</collision>
		<inertial>
			<mass value="0.24348454094182403"/>
			<inertia ixx="0.0003" iyy="0.0003" izz="0.0003"/>
		</inertial>
	</link>
	<link name="15">
		<visual>
			<geometry>
				<cylinder length="0.5972762551418295" radius="0.9339401678585683"/>
			</geometry>
		</visual>
		<collision>
			<geometry>
				<cylinder length="0.5972762551418295" radius="0.9339401678585683"/>
			</geometry>
		</collision>
		<inertial>
			<mass value="0.6127226568258675"/>
			<inertia ixx="0.0003" iyy="0.0003" izz="0.0003"/>
		</inertial>
	</link>
	<link name="26">
		<visual>
			<geometry>
				<cylinder length="0.582604179302883" radius="0.4334042317981647"/>
			</geometry>
		</visual>
		<collision>
			<geometry>
				<cylinder length="0.582604179302883" radius="0.4334042317981647"/>
			</geometry>
		</collision>
		<inertial>
			<mass value="0.24348454094182403"/>
			<inertia ixx="0.0003" iyy="0.0003" izz="0.0003"/>
		</inertial>
	</link>
	<joint name="0_to_11" type="revolute">
		<parent link="0"/>
		<child link="11"/>
		<axis xyz="1 0 0"/>
		<limit effort="1" velocity="1"/>
		<origin rpy="10.482826076826889 1.1928635817862638 3.7910199246240417" xyz="0.906111785756376 0.6088507627519042 0.8074769347017581"/>
	</joint>
	<joint name="11_to_22" type="fixed">
		<parent link="11"/>
		<child link="22"/>
		<axis xyz="1 0 0"/>
		<limit effort="1" velocity="1"/>
		<origin rpy="5.0912508561899035 4.482540211693693 2.5212869038653714" xyz="0.42934882003675234 0.5938646043363082 0.40037446801187415"/>
	</joint>
	<joint name="0_to_13" type="revolute">
		<parent link="0"/>
		<child link="13"/>
		<axis xyz="1 0 0"/>
		<limit effort="1" velocity="1"/>
		<origin rpy="15.724239115240334 1.1928635817862638 3.7910199246240417" xyz="0.906111785756376 0.6088507627519042 0.8074769347017581"/>
	</joint>
	<joint name="13_to_24" type="fixed">
		<parent link="13"/>
		<child link="24"/>
		<axis xyz="1 0 0"/>
		<limit effort="1" velocity="1"/>
		<origin rpy="5.0912508561899035 4.482540211693693 2.5212869038653714" xyz="0.42934882003675234 0.5938646043363082 0.40037446801187415"/>
	</joint>
	<joint name="0_to_15" type="revolute">
		<parent link="0"/>
		<child link="15"/>
		<axis xyz="1 0 0"/>
		<limit effort="1" velocity="1"/>
		<origin rpy="20.965652153653778 1.1928635817862638 3.7910199246240417" xyz="0.906111785756376 0.6088507627519042 0.8074769347017581"/>
	</joint>
	<joint name="15_to_26" type="fixed">
		<parent link="15"/>
		<child link="26"/>
		<axis xyz="1 0 0"/>
		<limit effort="1" velocity="1"/>
		<origin rpy="5.0912508561899035 4.482540211693693 2.5212869038653714" xyz="0.42934882003675234 0.5938646043363082 0.40037446801187415"/>
	</joint>
</robot>
