<?xml version="1.0"?><robot name="ted">
	<link name="0">
		<visual>
			<geometry>
				<cylinder length="0.5962753807705925" radius="0.07679702040628522"/>
			</geometry>
		</visual>
		<collision>
			<geometry>
				<cylinder length="0.5962753807705925" radius="0.07679702040628522"/>
			</geometry>
		</collision>
		<inertial>
			<mass value="0.3504002401598274"/>
			<inertia ixx="0.0003" iyy="0.0003" izz="0.0003"/>
		</inertial>
	</link>
	<link name="11">
		<visual>
			<geometry>
				<cylinder length="0.7799979584429653" radius="0.5986185121146569"/>
			</geometry>
		</visual>
		<collision>
			<geometry>
				<cylinder length="0.7799979584429653" radius="0.5986185121146569"/>
			</geometry>
		</collision>
		<inertial>
			<mass value="0.42143478416734315"/>
			<inertia ixx="0.0003" iyy="0.0003" izz="0.0003"/>
		</inertial>
	</link>
	<link name="22">
		<visual>
			<geometry>
				<cylinder length="0.4545651918322573" radius="0.17144367791166415"/>
			</geometry>
		</visual>
		<collision>
			<geometry>
				<cylinder length="0.4545651918322573" radius="0.17144367791166415"/>
			</geometry>
		</collision>
		<inertial>
			<mass value="0.8241987209167628"/>
			<inertia ixx="0.0003" iyy="0.0003" izz="0.0003"/>
		</inertial>
	</link>
	<link name="23">
		<visual>
			<geometry>
				<cylinder length="0.4545651918322573" radius="0.17144367791166415"/>
			</geometry>
		</visual>
		<collision>
			<geometry>
				<cylinder length="0.4545651918322573" radius="0.17144367791166415"/>
			</geometry>
		</collision>
		<inertial>
			<mass value="0.8241987209167628"/>
			<inertia ixx="0.0003" iyy="0.0003" izz="0.0003"/>
		</inertial>
	</link>
	<link name="24">
		<visual>
			<geometry>
				<cylinder length="0.4545651918322573" radius="0.17144367791166415"/>
			</geometry>
		</visual>
		<collision>
			<geometry>
				<cylinder length="0.4545651918322573" radius="0.17144367791166415"/>
			</geometry>
		</collision>
		<inertial>
			<mass value="0.8241987209167628"/>
			<inertia ixx="0.0003" iyy="0.0003" izz="0.0003"/>
		</inertial>
	</link>
	<link name="25">
		<visual>
			<geometry>
				<cylinder length="0.4545651918322573" radius="0.17144367791166415"/>
			</geometry>
		</visual>
		<collision>
			<geometry>
				<cylinder length="0.4545651918322573" radius="0.17144367791166415"/>
			</geometry>
		</collision>
		<inertial>
			<mass value="0.8241987209167628"/>
			<inertia ixx="0.0003" iyy="0.0003" izz="0.0003"/>
		</inertial>
	</link>
	<link name="16">
		<visual>
			<geometry>
				<cylinder length="0.7799979584429653" radius="0.5986185121146569"/>
			</geometry>
		</visual>
		<collision>
			<geometry>
				<cylinder length="0.7799979584429653" radius="0.5986185121146569"/>
			</geometry>
		</collision>
		<inertial>
			<mass value="0.42143478416734315"/>
			<inertia ixx="0.0003" iyy="0.0003" izz="0.0003"/>
		</inertial>
	</link>
	<link name="27">
		<visual>
			<geometry>
				<cylinder length="0.4545651918322573" radius="0.17144367791166415"/>
			</geometry>
		</visual>
		<collision>
			<geometry>
				<cylinder length="0.4545651918322573" radius="0.17144367791166415"/>
			</geometry>
		</collision>
		<inertial>
			<mass value="0.8241987209167628"/>
			<inertia ixx="0.0003" iyy="0.0003" izz="0.0003"/>
		</inertial>
	</link>
	<link name="28">
		<visual>
			<geometry>
				<cylinder length="0.4545651918322573" radius="0.17144367791166415"/>
			</geometry>
		</visual>
		<collision>
			<geometry>
				<cylinder length="0.4545651918322573" radius="0.17144367791166415"/>
			</geometry>
		</collision>
		<inertial>
			<mass value="0.8241987209167628"/>
			<inertia ixx="0.0003" iyy="0.0003" izz="0.0003"/>
		</inertial>
	</link>
	<link name="29">
		<visual>
			<geometry>
				<cylinder length="0.4545651918322573" radius="0.17144367791166415"/>
			</geometry>
		</visual>
		<collision>
			<geometry>
				<cylinder length="0.4545651918322573" radius="0.17144367791166415"/>
			</geometry>
		</collision>
		<inertial>
			<mass value="0.8241987209167628"/>
			<inertia ixx="0.0003" iyy="0.0003" izz="0.0003"/>
		</inertial>
	</link>
	<link name="210">
		<visual>
			<geometry>
				<cylinder length="0.4545651918322573" radius="0.17144367791166415"/>
			</geometry>
		</visual>
		<collision>
			<geometry>
				<cylinder length="0.4545651918322573" radius="0.17144367791166415"/>
			</geometry>
		</collision>
		<inertial>
			<mass value="0.8241987209167628"/>
			<inertia ixx="0.0003" iyy="0.0003" izz="0.0003"/>
		</inertial>
	</link>
	<link name="111">
		<visual>
			<geometry>
				<cylinder length="0.7799979584429653" radius="0.5986185121146569"/>
			</geometry>
		</visual>
		<collision>
			<geometry>
				<cylinder length="0.7799979584429653" radius="0.5986185121146569"/>
			</geometry>
		</collision>
		<inertial>
			<mass value="0.42143478416734315"/>
			<inertia ixx="0.0003" iyy="0.0003" izz="0.0003"/>
		</inertial>
	</link>
	<link name="212">
		<visual>
			<geometry>
				<cylinder length="0.4545651918322573" radius="0.17144367791166415"/>
			</geometry>
		</visual>
		<collision>
			<geometry>
				<cylinder length="0.4545651918322573" radius="0.17144367791166415"/>
			</geometry>
		</collision>
		<inertial>
			<mass value="0.8241987209167628"/>
			<inertia ixx="0.0003" iyy="0.0003" izz="0.0003"/>
		</inertial>
	</link>
	<link name="213">
		<visual>
			<geometry>
				<cylinder length="0.4545651918322573" radius="0.17144367791166415"/>
			</geometry>
		</visual>
		<collision>
			<geometry>
				<cylinder length="0.4545651918322573" radius="0.17144367791166415"/>
			</geometry>
		</collision>
		<inertial>
			<mass value="0.8241987209167628"/>
			<inertia ixx="0.0003" iyy="0.0003" izz="0.0003"/>
		</inertial>
	</link>
	<link name="214">
		<visual>
			<geometry>
				<cylinder length="0.4545651918322573" radius="0.17144367791166415"/>
			</geometry>
		</visual>
		<collision>
			<geometry>
				<cylinder length="0.4545651918322573" radius="0.17144367791166415"/>
			</geometry>
		</collision>
		<inertial>
			<mass value="0.8241987209167628"/>
			<inertia ixx="0.0003" iyy="0.0003" izz="0.0003"/>
		</inertial>
	</link>
	<link name="215">
		<visual>
			<geometry>
				<cylinder length="0.4545651918322573" radius="0.17144367791166415"/>
			</geometry>
		</visual>
		<collision>
			<geometry>
				<cylinder length="0.4545651918322573" radius="0.17144367791166415"/>
			</geometry>
		</collision>
		<inertial>
			<mass value="0.8241987209167628"/>
			<inertia ixx="0.0003" iyy="0.0003" izz="0.0003"/>
		</inertial>
	</link>
	<joint name="0_to_11" type="revolute">
		<parent link="0"/>
		<child link="11"/>
		<axis xyz="1 0 0"/>
		<limit effort="1" velocity="1"/>
		<origin rpy="8.902146545721475 1.9277776971095466 5.8172402069666" xyz="0.22053987618566806 0.11791418867024372 0.23443846621962516"/>
	</joint>
	<joint name="11_to_22" type="revolute">
		<parent link="11"/>
		<child link="22"/>
		<axis xyz="1 0 0"/>
		<limit effort="1" velocity="1"/>
		<origin rpy="0.4149937271165128 1.5386317593199765 1.9275806566083498" xyz="0.6128328431496726 0.8579141484636779 0.19547059967940184"/>
	</joint>
	<joint name="11_to_23" type="revolute">
		<parent link="11"/>
		<child link="23"/>
		<axis xyz="1 0 0"/>
		<limit effort="1" velocity="1"/>
		<origin rpy="0.6224905906747692 1.5386317593199765 1.9275806566083498" xyz="0.6128328431496726 0.8579141484636779 0.19547059967940184"/>
	</joint>
	<joint name="11_to_24" type="revolute">
		<parent link="11"/>
		<child link="24"/>
		<axis xyz="1 0 0"/>
		<limit effort="1" velocity="1"/>
		<origin rpy="0.8299874542330256 1.5386317593199765 1.9275806566083498" xyz="0.6128328431496726 0.8579141484636779 0.19547059967940184"/>
	</joint>
	<joint name="11_to_25" type="revolute">
		<parent link="11"/>
		<child link="25"/>
		<axis xyz="1 0 0"/>
		<limit effort="1" velocity="1"/>
		<origin rpy="1.037484317791282 1.5386317593199765 1.9275806566083498" xyz="0.6128328431496726 0.8579141484636779 0.19547059967940184"/>
	</joint>
	<joint name="0_to_16" type="revolute">
		<parent link="0"/>
		<child link="16"/>
		<axis xyz="1 0 0"/>
		<limit effort="1" velocity="1"/>
		<origin rpy="13.353219818582213 1.9277776971095466 5.8172402069666" xyz="0.22053987618566806 0.11791418867024372 0.23443846621962516"/>
	</joint>
	<joint name="16_to_27" type="revolute">
		<parent link="16"/>
		<child link="27"/>
		<axis xyz="1 0 0"/>
		<limit effort="1" velocity="1"/>
		<origin rpy="0.4149937271165128 1.5386317593199765 1.9275806566083498" xyz="0.6128328431496726 0.8579141484636779 0.19547059967940184"/>
	</joint>
	<joint name="16_to_28" type="revolute">
		<parent link="16"/>
		<child link="28"/>
		<axis xyz="1 0 0"/>
		<limit effort="1" velocity="1"/>
		<origin rpy="0.6224905906747692 1.5386317593199765 1.9275806566083498" xyz="0.6128328431496726 0.8579141484636779 0.19547059967940184"/>
	</joint>
	<joint name="16_to_29" type="revolute">
		<parent link="16"/>
		<child link="29"/>
		<axis xyz="1 0 0"/>
		<limit effort="1" velocity="1"/>
		<origin rpy="0.8299874542330256 1.5386317593199765 1.9275806566083498" xyz="0.6128328431496726 0.8579141484636779 0.19547059967940184"/>
	</joint>
	<joint name="16_to_210" type="revolute">
		<parent link="16"/>
		<child link="210"/>
		<axis xyz="1 0 0"/>
		<limit effort="1" velocity="1"/>
		<origin rpy="1.037484317791282 1.5386317593199765 1.9275806566083498" xyz="0.6128328431496726 0.8579141484636779 0.19547059967940184"/>
	</joint>
	<joint name="0_to_111" type="revolute">
		<parent link="0"/>
		<child link="111"/>
		<axis xyz="1 0 0"/>
		<limit effort="1" velocity="1"/>
		<origin rpy="17.80429309144295 1.9277776971095466 5.8172402069666" xyz="0.22053987618566806 0.11791418867024372 0.23443846621962516"/>
	</joint>
	<joint name="111_to_212" type="revolute">
		<parent link="111"/>
		<child link="212"/>
		<axis xyz="1 0 0"/>
		<limit effort="1" velocity="1"/>
		<origin rpy="0.4149937271165128 1.5386317593199765 1.9275806566083498" xyz="0.6128328431496726 0.8579141484636779 0.19547059967940184"/>
	</joint>
	<joint name="111_to_213" type="revolute">
		<parent link="111"/>
		<child link="213"/>
		<axis xyz="1 0 0"/>
		<limit effort="1" velocity="1"/>
		<origin rpy="0.6224905906747692 1.5386317593199765 1.9275806566083498" xyz="0.6128328431496726 0.8579141484636779 0.19547059967940184"/>
	</joint>
	<joint name="111_to_214" type="revolute">
		<parent link="111"/>
		<child link="214"/>
		<axis xyz="1 0 0"/>
		<limit effort="1" velocity="1"/>
		<origin rpy="0.8299874542330256 1.5386317593199765 1.9275806566083498" xyz="0.6128328431496726 0.8579141484636779 0.19547059967940184"/>
	</joint>
	<joint name="111_to_215" type="revolute">
		<parent link="111"/>
		<child link="215"/>
		<axis xyz="1 0 0"/>
		<limit effort="1" velocity="1"/>
		<origin rpy="1.037484317791282 1.5386317593199765 1.9275806566083498" xyz="0.6128328431496726 0.8579141484636779 0.19547059967940184"/>
	</joint>
</robot>
