<?xml version="1.0"?><robot name="ted">
	<link name="0">
		<visual>
			<geometry>
				<cylinder length="0.6285274459571657" radius="0.4032061758622738"/>
			</geometry>
		</visual>
		<collision>
			<geometry>
				<cylinder length="0.6285274459571657" radius="0.4032061758622738"/>
			</geometry>
		</collision>
		<inertial>
			<mass value="0.20040804230037224"/>
			<inertia ixx="0.0003" iyy="0.0003" izz="0.0003"/>
		</inertial>
	</link>
	<link name="11">
		<visual>
			<geometry>
				<cylinder length="0.26018788447842545" radius="0.05697143507207447"/>
			</geometry>
		</visual>
		<collision>
			<geometry>
				<cylinder length="0.26018788447842545" radius="0.05697143507207447"/>
			</geometry>
		</collision>
		<inertial>
			<mass value="0.4101187942103659"/>
			<inertia ixx="0.0003" iyy="0.0003" izz="0.0003"/>
		</inertial>
	</link>
	<link name="22">
		<visual>
			<geometry>
				<cylinder length="0.9935105862173648" radius="0.21707211443682384"/>
			</geometry>
		</visual>
		<collision>
			<geometry>
				<cylinder length="0.9935105862173648" radius="0.21707211443682384"/>
			</geometry>
		</collision>
		<inertial>
			<mass value="0.8666044093986242"/>
			<inertia ixx="0.0003" iyy="0.0003" izz="0.0003"/>
		</inertial>
	</link>
	<link name="13">
		<visual>
			<geometry>
				<cylinder length="0.26018788447842545" radius="0.05697143507207447"/>
			</geometry>
		</visual>
		<collision>
			<geometry>
				<cylinder length="0.26018788447842545" radius="0.05697143507207447"/>
			</geometry>
		</collision>
		<inertial>
			<mass value="0.4101187942103659"/>
			<inertia ixx="0.0003" iyy="0.0003" izz="0.0003"/>
		</inertial>
	</link>
	<link name="24">
		<visual>
			<geometry>
				<cylinder length="0.9935105862173648" radius="0.21707211443682384"/>
			</geometry>
		</visual>
		<collision>
			<geometry>
				<cylinder length="0.9935105862173648" radius="0.21707211443682384"/>
			</geometry>
		</collision>
		<inertial>
			<mass value="0.8666044093986242"/>
			<inertia ixx="0.0003" iyy="0.0003" izz="0.0003"/>
		</inertial>
	</link>
	<joint name="0_to_11" type="revolute">
		<parent link="0"/>
		<child link="11"/>
		<axis xyz="1 0 0"/>
		<limit effort="1" velocity="1"/>
		<origin rpy="9.124570646585411 3.9609163029744696 1.757882737548315" xyz="0.09372381634914051 0.06267976152252164 0.9551972440053589"/>
	</joint>
	<joint name="11_to_22" type="fixed">
		<parent link="11"/>
		<child link="22"/>
		<axis xyz="1 0 0"/>
		<limit effort="1" velocity="1"/>
		<origin rpy="0.2837234362094006 4.8474643084669085 1.3773249952779743" xyz="0.5056671644955502 0.7705101703448557 0.26994159102630577"/>
	</joint>
	<joint name="0_to_13" type="revolute">
		<parent link="0"/>
		<child link="13"/>
		<axis xyz="1 0 0"/>
		<limit effort="1" velocity="1"/>
		<origin rpy="13.686855969878117 3.9609163029744696 1.757882737548315" xyz="0.09372381634914051 0.06267976152252164 0.9551972440053589"/>
	</joint>
	<joint name="13_to_24" type="fixed">
		<parent link="13"/>
		<child link="24"/>
		<axis xyz="1 0 0"/>
		<limit effort="1" velocity="1"/>
		<origin rpy="0.2837234362094006 4.8474643084669085 1.3773249952779743" xyz="0.5056671644955502 0.7705101703448557 0.26994159102630577"/>
	</joint>
</robot>
