<?xml version="1.0"?><robot name="ted">
	<link name="0">
		<visual>
			<geometry>
				<cylinder length="0.9397554022476087" radius="0.5474820718989449"/>
			</geometry>
		</visual>
		<collision>
			<geometry>
				<cylinder length="0.9397554022476087" radius="0.5474820718989449"/>
			</geometry>
		</collision>
		<inertial>
			<mass value="0.5915219888699443"/>
			<inertia ixx="0.0003" iyy="0.0003" izz="0.0003"/>
		</inertial>
	</link>
	<link name="11">
		<visual>
			<geometry>
				<cylinder length="0.26615686352681733" radius="0.1592615699535338"/>
			</geometry>
		</visual>
		<collision>
			<geometry>
				<cylinder length="0.26615686352681733" radius="0.1592615699535338"/>
			</geometry>
		</collision>
		<inertial>
			<mass value="0.5587351277461894"/>
			<inertia ixx="0.0003" iyy="0.0003" izz="0.0003"/>
		</inertial>
	</link>
	<link name="22">
		<visual>
			<geometry>
				<cylinder length="0.2048360851532155" radius="0.8249099208052233"/>
			</geometry>
		</visual>
		<collision>
			<geometry>
				<cylinder length="0.2048360851532155" radius="0.8249099208052233"/>
			</geometry>
		</collision>
		<inertial>
			<mass value="0.5927891381067416"/>
			<inertia ixx="0.0003" iyy="0.0003" izz="0.0003"/>
		</inertial>
	</link>
	<link name="23">
		<visual>
			<geometry>
				<cylinder length="0.2048360851532155" radius="0.8249099208052233"/>
			</geometry>
		</visual>
		<collision>
			<geometry>
				<cylinder length="0.2048360851532155" radius="0.8249099208052233"/>
			</geometry>
		</collision>
		<inertial>
			<mass value="0.5927891381067416"/>
			<inertia ixx="0.0003" iyy="0.0003" izz="0.0003"/>
		</inertial>
	</link>
	<link name="24">
		<visual>
			<geometry>
				<cylinder length="0.2048360851532155" radius="0.8249099208052233"/>
			</geometry>
		</visual>
		<collision>
			<geometry>
				<cylinder length="0.2048360851532155" radius="0.8249099208052233"/>
			</geometry>
		</collision>
		<inertial>
			<mass value="0.5927891381067416"/>
			<inertia ixx="0.0003" iyy="0.0003" izz="0.0003"/>
		</inertial>
	</link>
	<joint name="0_to_11" type="fixed">
		<parent link="0"/>
		<child link="11"/>
		<axis xyz="1 0 0"/>
		<limit effort="1" velocity="1"/>
		<origin rpy="12.5325441779656 4.158678781984297 2.503122342430801" xyz="0.9523668133272517 0.44254823454720327 0.25603083030857443"/>
	</joint>
	<joint name="11_to_22" type="revolute">
		<parent link="11"/>
		<child link="22"/>
		<axis xyz="1 0 0"/>
		<limit effort="1" velocity="1"/>
		<origin rpy="1.2249424253303265 0.5355970113587686 2.813703567044261" xyz="0.67259057424336 0.10110383213590424 0.22809037119767928"/>
	</joint>
	<joint name="11_to_23" type="revolute">
		<parent link="11"/>
		<child link="23"/>
		<axis xyz="1 0 0"/>
		<limit effort="1" velocity="1"/>
		<origin rpy="1.8374136379954897 0.5355970113587686 2.813703567044261" xyz="0.67259057424336 0.10110383213590424 0.22809037119767928"/>
	</joint>
	<joint name="11_to_24" type="revolute">
		<parent link="11"/>
		<child link="24"/>
		<axis xyz="1 0 0"/>
		<limit effort="1" velocity="1"/>
		<origin rpy="2.449884850660653 0.5355970113587686 2.813703567044261" xyz="0.67259057424336 0.10110383213590424 0.22809037119767928"/>
	</joint>
</robot>
