<?xml version="1.0"?><robot name="ted">
	<link name="0">
		<visual>
			<geometry>
				<cylinder length="0.6569259045236299" radius="0.43601755390666574"/>
			</geometry>
		</visual>
		<collision>
			<geometry>
				<cylinder length="0.6569259045236299" radius="0.43601755390666574"/>
			</geometry>
		</collision>
		<inertial>
			<mass value="0.45939679572431935"/>
			<inertia ixx="0.0003" iyy="0.0003" izz="0.0003"/>
		</inertial>
	</link>
	<link name="11">
		<visual>
			<geometry>
				<cylinder length="0.9017451512570069" radius="0.33481714281733466"/>
			</geometry>
		</visual>
		<collision>
			<geometry>
				<cylinder length="0.9017451512570069" radius="0.33481714281733466"/>
			</geometry>
		</collision>
		<inertial>
			<mass value="0.36807050749833503"/>
			<inertia ixx="0.0003" iyy="0.0003" izz="0.0003"/>
		</inertial>
	</link>
	<link name="22">
		<visual>
			<geometry>
				<cylinder length="0.2039466191523025" radius="0.6074229490993184"/>
			</geometry>
		</visual>
		<collision>
			<geometry>
				<cylinder length="0.2039466191523025" radius="0.6074229490993184"/>
			</geometry>
		</collision>
		<inertial>
			<mass value="0.03573135066767852"/>
			<inertia ixx="0.0003" iyy="0.0003" izz="0.0003"/>
		</inertial>
	</link>
	<link name="23">
		<visual>
			<geometry>
				<cylinder length="0.2039466191523025" radius="0.6074229490993184"/>
			</geometry>
		</visual>
		<collision>
			<geometry>
				<cylinder length="0.2039466191523025" radius="0.6074229490993184"/>
			</geometry>
		</collision>
		<inertial>
			<mass value="0.03573135066767852"/>
			<inertia ixx="0.0003" iyy="0.0003" izz="0.0003"/>
		</inertial>
	</link>
	<link name="24">
		<visual>
			<geometry>
				<cylinder length="0.2039466191523025" radius="0.6074229490993184"/>
			</geometry>
		</visual>
		<collision>
			<geometry>
				<cylinder length="0.2039466191523025" radius="0.6074229490993184"/>
			</geometry>
		</collision>
		<inertial>
			<mass value="0.03573135066767852"/>
			<inertia ixx="0.0003" iyy="0.0003" izz="0.0003"/>
		</inertial>
	</link>
	<joint name="0_to_11" type="revolute">
		<parent link="0"/>
		<child link="11"/>
		<axis xyz="1 0 0"/>
		<limit effort="1" velocity="1"/>
		<origin rpy="1.2437489466869613 3.179511477570287 2.2897091328982997" xyz="0.9104968082245044 0.8880739423737236 0.7791443113312373"/>
	</joint>
	<joint name="0_to_22" type="fixed">
		<parent link="0"/>
		<child link="22"/>
		<axis xyz="1 0 0"/>
		<limit effort="1" velocity="1"/>
		<origin rpy="13.231554385563193 0.7933656625450124 2.915325416153988" xyz="0.47043865866846335 0.35989810976740033 0.8046627738723747"/>
	</joint>
	<joint name="0_to_23" type="fixed">
		<parent link="0"/>
		<child link="23"/>
		<axis xyz="1 0 0"/>
		<limit effort="1" velocity="1"/>
		<origin rpy="17.64207251408426 0.7933656625450124 2.915325416153988" xyz="0.47043865866846335 0.35989810976740033 0.8046627738723747"/>
	</joint>
	<joint name="0_to_24" type="fixed">
		<parent link="0"/>
		<child link="24"/>
		<axis xyz="1 0 0"/>
		<limit effort="1" velocity="1"/>
		<origin rpy="22.052590642605324 0.7933656625450124 2.915325416153988" xyz="0.47043865866846335 0.35989810976740033 0.8046627738723747"/>
	</joint>
</robot>
