<?xml version="1.0"?><robot name="ted">
	<link name="0">
		<visual>
			<geometry>
				<cylinder length="0.27337669487151584" radius="0.5634259829770796"/>
			</geometry>
		</visual>
		<collision>
			<geometry>
				<cylinder length="0.27337669487151584" radius="0.5634259829770796"/>
			</geometry>
		</collision>
		<inertial>
			<mass value="0.9416563593579919"/>
			<inertia ixx="0.0003" iyy="0.0003" izz="0.0003"/>
		</inertial>
	</link>
	<link name="11">
		<visual>
			<geometry>
				<cylinder length="0.8610294575730548" radius="0.3439519426486871"/>
			</geometry>
		</visual>
		<collision>
			<geometry>
				<cylinder length="0.8610294575730548" radius="0.3439519426486871"/>
			</geometry>
		</collision>
		<inertial>
			<mass value="0.4771186923004319"/>
			<inertia ixx="0.0003" iyy="0.0003" izz="0.0003"/>
		</inertial>
	</link>
	<link name="22">
		<visual>
			<geometry>
				<cylinder length="0.6371326441123338" radius="0.25658454190482716"/>
			</geometry>
		</visual>
		<collision>
			<geometry>
				<cylinder length="0.6371326441123338" radius="0.25658454190482716"/>
			</geometry>
		</collision>
		<inertial>
			<mass value="0.9911401011812869"/>
			<inertia ixx="0.0003" iyy="0.0003" izz="0.0003"/>
		</inertial>
	</link>
	<link name="23">
		<visual>
			<geometry>
				<cylinder length="0.6371326441123338" radius="0.25658454190482716"/>
			</geometry>
		</visual>
		<collision>
			<geometry>
				<cylinder length="0.6371326441123338" radius="0.25658454190482716"/>
			</geometry>
		</collision>
		<inertial>
			<mass value="0.9911401011812869"/>
			<inertia ixx="0.0003" iyy="0.0003" izz="0.0003"/>
		</inertial>
	</link>
	<link name="14">
		<visual>
			<geometry>
				<cylinder length="0.8610294575730548" radius="0.3439519426486871"/>
			</geometry>
		</visual>
		<collision>
			<geometry>
				<cylinder length="0.8610294575730548" radius="0.3439519426486871"/>
			</geometry>
		</collision>
		<inertial>
			<mass value="0.4771186923004319"/>
			<inertia ixx="0.0003" iyy="0.0003" izz="0.0003"/>
		</inertial>
	</link>
	<link name="25">
		<visual>
			<geometry>
				<cylinder length="0.6371326441123338" radius="0.25658454190482716"/>
			</geometry>
		</visual>
		<collision>
			<geometry>
				<cylinder length="0.6371326441123338" radius="0.25658454190482716"/>
			</geometry>
		</collision>
		<inertial>
			<mass value="0.9911401011812869"/>
			<inertia ixx="0.0003" iyy="0.0003" izz="0.0003"/>
		</inertial>
	</link>
	<link name="26">
		<visual>
			<geometry>
				<cylinder length="0.6371326441123338" radius="0.25658454190482716"/>
			</geometry>
		</visual>
		<collision>
			<geometry>
				<cylinder length="0.6371326441123338" radius="0.25658454190482716"/>
			</geometry>
		</collision>
		<inertial>
			<mass value="0.9911401011812869"/>
			<inertia ixx="0.0003" iyy="0.0003" izz="0.0003"/>
		</inertial>
	</link>
	<link name="17">
		<visual>
			<geometry>
				<cylinder length="0.8610294575730548" radius="0.3439519426486871"/>
			</geometry>
		</visual>
		<collision>
			<geometry>
				<cylinder length="0.8610294575730548" radius="0.3439519426486871"/>
			</geometry>
		</collision>
		<inertial>
			<mass value="0.4771186923004319"/>
			<inertia ixx="0.0003" iyy="0.0003" izz="0.0003"/>
		</inertial>
	</link>
	<link name="28">
		<visual>
			<geometry>
				<cylinder length="0.6371326441123338" radius="0.25658454190482716"/>
			</geometry>
		</visual>
		<collision>
			<geometry>
				<cylinder length="0.6371326441123338" radius="0.25658454190482716"/>
			</geometry>
		</collision>
		<inertial>
			<mass value="0.9911401011812869"/>
			<inertia ixx="0.0003" iyy="0.0003" izz="0.0003"/>
		</inertial>
	</link>
	<link name="29">
		<visual>
			<geometry>
				<cylinder length="0.6371326441123338" radius="0.25658454190482716"/>
			</geometry>
		</visual>
		<collision>
			<geometry>
				<cylinder length="0.6371326441123338" radius="0.25658454190482716"/>
			</geometry>
		</collision>
		<inertial>
			<mass value="0.9911401011812869"/>
			<inertia ixx="0.0003" iyy="0.0003" izz="0.0003"/>
		</inertial>
	</link>
	<joint name="0_to_11" type="fixed">
		<parent link="0"/>
		<child link="11"/>
		<axis xyz="1 0 0"/>
		<limit effort="1" velocity="1"/>
		<origin rpy="3.8796278947222684 2.4397698640646737 2.7651980699006025" xyz="0.35982983696756854 0.4948210628693771 0.17870137160170452"/>
	</joint>
	<joint name="11_to_22" type="revolute">
		<parent link="11"/>
		<child link="22"/>
		<axis xyz="1 0 0"/>
		<limit effort="1" velocity="1"/>
		<origin rpy="10.95437704902278 4.713583049832389 0.8825021323515916" xyz="0.4957513689821834 0.4331426638181324 0.6581422151439972"/>
	</joint>
	<joint name="11_to_23" type="revolute">
		<parent link="11"/>
		<child link="23"/>
		<axis xyz="1 0 0"/>
		<limit effort="1" velocity="1"/>
		<origin rpy="16.43156557353417 4.713583049832389 0.8825021323515916" xyz="0.4957513689821834 0.4331426638181324 0.6581422151439972"/>
	</joint>
	<joint name="0_to_14" type="fixed">
		<parent link="0"/>
		<child link="14"/>
		<axis xyz="1 0 0"/>
		<limit effort="1" velocity="1"/>
		<origin rpy="5.819441842083402 2.4397698640646737 2.7651980699006025" xyz="0.35982983696756854 0.4948210628693771 0.17870137160170452"/>
	</joint>
	<joint name="14_to_25" type="revolute">
		<parent link="14"/>
		<child link="25"/>
		<axis xyz="1 0 0"/>
		<limit effort="1" velocity="1"/>
		<origin rpy="10.95437704902278 4.713583049832389 0.8825021323515916" xyz="0.4957513689821834 0.4331426638181324 0.6581422151439972"/>
	</joint>
	<joint name="14_to_26" type="revolute">
		<parent link="14"/>
		<child link="26"/>
		<axis xyz="1 0 0"/>
		<limit effort="1" velocity="1"/>
		<origin rpy="16.43156557353417 4.713583049832389 0.8825021323515916" xyz="0.4957513689821834 0.4331426638181324 0.6581422151439972"/>
	</joint>
	<joint name="0_to_17" type="fixed">
		<parent link="0"/>
		<child link="17"/>
		<axis xyz="1 0 0"/>
		<limit effort="1" velocity="1"/>
		<origin rpy="7.759255789444537 2.4397698640646737 2.7651980699006025" xyz="0.35982983696756854 0.4948210628693771 0.17870137160170452"/>
	</joint>
	<joint name="17_to_28" type="revolute">
		<parent link="17"/>
		<child link="28"/>
		<axis xyz="1 0 0"/>
		<limit effort="1" velocity="1"/>
		<origin rpy="10.95437704902278 4.713583049832389 0.8825021323515916" xyz="0.4957513689821834 0.4331426638181324 0.6581422151439972"/>
	</joint>
	<joint name="17_to_29" type="revolute">
		<parent link="17"/>
		<child link="29"/>
		<axis xyz="1 0 0"/>
		<limit effort="1" velocity="1"/>
		<origin rpy="16.43156557353417 4.713583049832389 0.8825021323515916" xyz="0.4957513689821834 0.4331426638181324 0.6581422151439972"/>
	</joint>
</robot>
