<?xml version="1.0"?><robot name="ted">
	<link name="0">
		<visual>
			<geometry>
				<cylinder length="0.9525406103622023" radius="0.13977010627818942"/>
			</geometry>
		</visual>
		<collision>
			<geometry>
				<cylinder length="0.9525406103622023" radius="0.13977010627818942"/>
			</geometry>
		</collision>
		<inertial>
			<mass value="0.26930780698329493"/>
			<inertia ixx="0.0003" iyy="0.0003" izz="0.0003"/>
		</inertial>
	</link>
	<link name="11">
		<visual>
			<geometry>
				<cylinder length="0.2914642392679181" radius="0.6742561542252038"/>
			</geometry>
		</visual>
		<collision>
			<geometry>
				<cylinder length="0.2914642392679181" radius="0.6742561542252038"/>
			</geometry>
		</collision>
		<inertial>
			<mass value="0.42071888053124684"/>
			<inertia ixx="0.0003" iyy="0.0003" izz="0.0003"/>
		</inertial>
	</link>
	<link name="22">
		<visual>
			<geometry>
				<cylinder length="0.7240004928647916" radius="0.41006124259894927"/>
			</geometry>
		</visual>
		<collision>
			<geometry>
				<cylinder length="0.7240004928647916" radius="0.41006124259894927"/>
			</geometry>
		</collision>
		<inertial>
			<mass value="0.5775649229263259"/>
			<inertia ixx="0.0003" iyy="0.0003" izz="0.0003"/>
		</inertial>
	</link>
	<joint name="0_to_11" type="revolute">
		<parent link="0"/>
		<child link="11"/>
		<axis xyz="1 0 0"/>
		<limit effort="1" velocity="1"/>
		<origin rpy="9.952891875863138 3.4420643372295614 1.722549525986585" xyz="0.6131601569090264 0.635322113696598 0.6758104740682828"/>
	</joint>
	<joint name="11_to_22" type="revolute">
		<parent link="11"/>
		<child link="22"/>
		<axis xyz="1 0 0"/>
		<limit effort="1" velocity="1"/>
		<origin rpy="7.576945201360048 2.881128569817142 1.7876134810044841" xyz="0.7301470040076475 0.439146727827623 0.5607710244391353"/>
	</joint>
</robot>
