<?xml version="1.0"?><robot name="ted">
	<link name="0">
		<visual>
			<geometry>
				<cylinder length="0.5594185856056871" radius="0.26532258228509176"/>
			</geometry>
		</visual>
		<collision>
			<geometry>
				<cylinder length="0.5594185856056871" radius="0.26532258228509176"/>
			</geometry>
		</collision>
		<inertial>
			<mass value="0.3935946548676942"/>
			<inertia ixx="0.0003" iyy="0.0003" izz="0.0003"/>
		</inertial>
	</link>
	<link name="11">
		<visual>
			<geometry>
				<cylinder length="0.8050791113265188" radius="0.7967652626707986"/>
			</geometry>
		</visual>
		<collision>
			<geometry>
				<cylinder length="0.8050791113265188" radius="0.7967652626707986"/>
			</geometry>
		</collision>
		<inertial>
			<mass value="0.9014012552777548"/>
			<inertia ixx="0.0003" iyy="0.0003" izz="0.0003"/>
		</inertial>
	</link>
	<link name="12">
		<visual>
			<geometry>
				<cylinder length="0.8050791113265188" radius="0.7967652626707986"/>
			</geometry>
		</visual>
		<collision>
			<geometry>
				<cylinder length="0.8050791113265188" radius="0.7967652626707986"/>
			</geometry>
		</collision>
		<inertial>
			<mass value="0.9014012552777548"/>
			<inertia ixx="0.0003" iyy="0.0003" izz="0.0003"/>
		</inertial>
	</link>
	<link name="13">
		<visual>
			<geometry>
				<cylinder length="0.8050791113265188" radius="0.7967652626707986"/>
			</geometry>
		</visual>
		<collision>
			<geometry>
				<cylinder length="0.8050791113265188" radius="0.7967652626707986"/>
			</geometry>
		</collision>
		<inertial>
			<mass value="0.9014012552777548"/>
			<inertia ixx="0.0003" iyy="0.0003" izz="0.0003"/>
		</inertial>
	</link>
	<link name="14">
		<visual>
			<geometry>
				<cylinder length="0.8050791113265188" radius="0.7967652626707986"/>
			</geometry>
		</visual>
		<collision>
			<geometry>
				<cylinder length="0.8050791113265188" radius="0.7967652626707986"/>
			</geometry>
		</collision>
		<inertial>
			<mass value="0.9014012552777548"/>
			<inertia ixx="0.0003" iyy="0.0003" izz="0.0003"/>
		</inertial>
	</link>
	<link name="25">
		<visual>
			<geometry>
				<cylinder length="0.08526561809607824" radius="0.8546981524996299"/>
			</geometry>
		</visual>
		<collision>
			<geometry>
				<cylinder length="0.08526561809607824" radius="0.8546981524996299"/>
			</geometry>
		</collision>
		<inertial>
			<mass value="0.8947832574563347"/>
			<inertia ixx="0.0003" iyy="0.0003" izz="0.0003"/>
		</inertial>
	</link>
	<link name="26">
		<visual>
			<geometry>
				<cylinder length="0.08526561809607824" radius="0.8546981524996299"/>
			</geometry>
		</visual>
		<collision>
			<geometry>
				<cylinder length="0.08526561809607824" radius="0.8546981524996299"/>
			</geometry>
		</collision>
		<inertial>
			<mass value="0.8947832574563347"/>
			<inertia ixx="0.0003" iyy="0.0003" izz="0.0003"/>
		</inertial>
	</link>
	<joint name="0_to_11" type="revolute">
		<parent link="0"/>
		<child link="11"/>
		<axis xyz="1 0 0"/>
		<limit effort="1" velocity="1"/>
		<origin rpy="0.5863936291898857 4.69806648274824 0.8247175925889169" xyz="0.770172108080939 0.8462387172466617 0.9739261721034488"/>
	</joint>
	<joint name="0_to_12" type="revolute">
		<parent link="0"/>
		<child link="12"/>
		<axis xyz="1 0 0"/>
		<limit effort="1" velocity="1"/>
		<origin rpy="0.8795904437848285 4.69806648274824 0.8247175925889169" xyz="0.770172108080939 0.8462387172466617 0.9739261721034488"/>
	</joint>
	<joint name="0_to_13" type="revolute">
		<parent link="0"/>
		<child link="13"/>
		<axis xyz="1 0 0"/>
		<limit effort="1" velocity="1"/>
		<origin rpy="1.1727872583797714 4.69806648274824 0.8247175925889169" xyz="0.770172108080939 0.8462387172466617 0.9739261721034488"/>
	</joint>
	<joint name="0_to_14" type="revolute">
		<parent link="0"/>
		<child link="14"/>
		<axis xyz="1 0 0"/>
		<limit effort="1" velocity="1"/>
		<origin rpy="1.4659840729747142 4.69806648274824 0.8247175925889169" xyz="0.770172108080939 0.8462387172466617 0.9739261721034488"/>
	</joint>
	<joint name="0_to_25" type="fixed">
		<parent link="0"/>
		<child link="25"/>
		<axis xyz="1 0 0"/>
		<limit effort="1" velocity="1"/>
		<origin rpy="27.36328307248862 0.3324729514883024 5.097917870326313" xyz="0.16014508372725011 0.7462137259312588 0.662594928742491"/>
	</joint>
	<joint name="0_to_26" type="fixed">
		<parent link="0"/>
		<child link="26"/>
		<axis xyz="1 0 0"/>
		<limit effort="1" velocity="1"/>
		<origin rpy="31.923830251236723 0.3324729514883024 5.097917870326313" xyz="0.16014508372725011 0.7462137259312588 0.662594928742491"/>
	</joint>
</robot>
