<?xml version="1.0"?><robot name="ted">
	<link name="0">
		<visual>
			<geometry>
				<cylinder length="0.6429270423449143" radius="0.9710204988893348"/>
			</geometry>
		</visual>
		<collision>
			<geometry>
				<cylinder length="0.6429270423449143" radius="0.9710204988893348"/>
			</geometry>
		</collision>
		<inertial>
			<mass value="0.918851376352353"/>
			<inertia ixx="0.0003" iyy="0.0003" izz="0.0003"/>
		</inertial>
	</link>
	<link name="11">
		<visual>
			<geometry>
				<cylinder length="0.18528122135910685" radius="0.08685378833162605"/>
			</geometry>
		</visual>
		<collision>
			<geometry>
				<cylinder length="0.18528122135910685" radius="0.08685378833162605"/>
			</geometry>
		</collision>
		<inertial>
			<mass value="0.5869899911583579"/>
			<inertia ixx="0.0003" iyy="0.0003" izz="0.0003"/>
		</inertial>
	</link>
	<link name="22">
		<visual>
			<geometry>
				<cylinder length="0.6225128736817918" radius="0.2840788856534705"/>
			</geometry>
		</visual>
		<collision>
			<geometry>
				<cylinder length="0.6225128736817918" radius="0.2840788856534705"/>
			</geometry>
		</collision>
		<inertial>
			<mass value="0.17690250276246489"/>
			<inertia ixx="0.0003" iyy="0.0003" izz="0.0003"/>
		</inertial>
	</link>
	<link name="23">
		<visual>
			<geometry>
				<cylinder length="0.6225128736817918" radius="0.2840788856534705"/>
			</geometry>
		</visual>
		<collision>
			<geometry>
				<cylinder length="0.6225128736817918" radius="0.2840788856534705"/>
			</geometry>
		</collision>
		<inertial>
			<mass value="0.17690250276246489"/>
			<inertia ixx="0.0003" iyy="0.0003" izz="0.0003"/>
		</inertial>
	</link>
	<joint name="0_to_11" type="revolute">
		<parent link="0"/>
		<child link="11"/>
		<axis xyz="1 0 0"/>
		<limit effort="1" velocity="1"/>
		<origin rpy="12.367558002888956 0.367235277655106 4.608598057269663" xyz="0.31356293640167177 0.7714657555208229 0.746370997194334"/>
	</joint>
	<joint name="11_to_22" type="fixed">
		<parent link="11"/>
		<child link="22"/>
		<axis xyz="1 0 0"/>
		<limit effort="1" velocity="1"/>
		<origin rpy="1.676996027096198 5.843553322684614 1.5541850768214387" xyz="0.650671638412766 0.939345301046582 0.7191100530265305"/>
	</joint>
	<joint name="11_to_23" type="fixed">
		<parent link="11"/>
		<child link="23"/>
		<axis xyz="1 0 0"/>
		<limit effort="1" velocity="1"/>
		<origin rpy="2.515494040644297 5.843553322684614 1.5541850768214387" xyz="0.650671638412766 0.939345301046582 0.7191100530265305"/>
	</joint>
</robot>
