<?xml version="1.0"?><robot name="ted">
	<link name="0">
		<visual>
			<geometry>
				<cylinder length="0.21275301331532537" radius="0.6738214328149634"/>
			</geometry>
		</visual>
		<collision>
			<geometry>
				<cylinder length="0.21275301331532537" radius="0.6738214328149634"/>
			</geometry>
		</collision>
		<inertial>
			<mass value="-0.041928476734819975"/>
			<inertia ixx="0.0003" iyy="0.0003" izz="0.0003"/>
		</inertial>
	</link>
	<link name="11">
		<visual>
			<geometry>
				<cylinder length="0.3192604814356006" radius="0.4691899845299726"/>
			</geometry>
		</visual>
		<collision>
			<geometry>
				<cylinder length="0.3192604814356006" radius="0.4691899845299726"/>
			</geometry>
		</collision>
		<inertial>
			<mass value="0.15762616033790156"/>
			<inertia ixx="0.0003" iyy="0.0003" izz="0.0003"/>
		</inertial>
	</link>
	<link name="12">
		<visual>
			<geometry>
				<cylinder length="0.3192604814356006" radius="0.4691899845299726"/>
			</geometry>
		</visual>
		<collision>
			<geometry>
				<cylinder length="0.3192604814356006" radius="0.4691899845299726"/>
			</geometry>
		</collision>
		<inertial>
			<mass value="0.15762616033790156"/>
			<inertia ixx="0.0003" iyy="0.0003" izz="0.0003"/>
		</inertial>
	</link>
	<link name="13">
		<visual>
			<geometry>
				<cylinder length="0.3192604814356006" radius="0.4691899845299726"/>
			</geometry>
		</visual>
		<collision>
			<geometry>
				<cylinder length="0.3192604814356006" radius="0.4691899845299726"/>
			</geometry>
		</collision>
		<inertial>
			<mass value="0.15762616033790156"/>
			<inertia ixx="0.0003" iyy="0.0003" izz="0.0003"/>
		</inertial>
	</link>
	<link name="14">
		<visual>
			<geometry>
				<cylinder length="0.3192604814356006" radius="0.4691899845299726"/>
			</geometry>
		</visual>
		<collision>
			<geometry>
				<cylinder length="0.3192604814356006" radius="0.4691899845299726"/>
			</geometry>
		</collision>
		<inertial>
			<mass value="0.15762616033790156"/>
			<inertia ixx="0.0003" iyy="0.0003" izz="0.0003"/>
		</inertial>
	</link>
	<joint name="0_to_11" type="revolute">
		<parent link="0"/>
		<child link="11"/>
		<axis xyz="1 0 0"/>
		<limit effort="1" velocity="1"/>
		<origin rpy="10.238532179472305 2.851366780098196 1.0995151100160443" xyz="0.9131297020884191 0.7471783354347086 0.5441474394424531"/>
	</joint>
	<joint name="0_to_12" type="revolute">
		<parent link="0"/>
		<child link="12"/>
		<axis xyz="1 0 0"/>
		<limit effort="1" velocity="1"/>
		<origin rpy="15.357798269208457 2.851366780098196 1.0995151100160443" xyz="0.9131297020884191 0.7471783354347086 0.5441474394424531"/>
	</joint>
	<joint name="0_to_13" type="revolute">
		<parent link="0"/>
		<child link="13"/>
		<axis xyz="1 0 0"/>
		<limit effort="1" velocity="1"/>
		<origin rpy="20.47706435894461 2.851366780098196 1.0995151100160443" xyz="0.9131297020884191 0.7471783354347086 0.5441474394424531"/>
	</joint>
	<joint name="0_to_14" type="revolute">
		<parent link="0"/>
		<child link="14"/>
		<axis xyz="1 0 0"/>
		<limit effort="1" velocity="1"/>
		<origin rpy="25.59633044868076 2.851366780098196 1.0995151100160443" xyz="0.9131297020884191 0.7471783354347086 0.5441474394424531"/>
	</joint>
</robot>
