<?xml version="1.0"?><robot name="ted">
	<link name="0">
		<visual>
			<geometry>
				<cylinder length="0.12440182087772711" radius="0.1527095031686587"/>
			</geometry>
		</visual>
		<collision>
			<geometry>
				<cylinder length="0.12440182087772711" radius="0.1527095031686587"/>
			</geometry>
		</collision>
		<inertial>
			<mass value="0.06407169962860215"/>
			<inertia ixx="0.0003" iyy="0.0003" izz="0.0003"/>
		</inertial>
	</link>
	<link name="11">
		<visual>
			<geometry>
				<cylinder length="0.04802856434970926" radius="0.12659549976073547"/>
			</geometry>
		</visual>
		<collision>
			<geometry>
				<cylinder length="0.04802856434970926" radius="0.12659549976073547"/>
			</geometry>
		</collision>
		<inertial>
			<mass value="0.629148095208603"/>
			<inertia ixx="0.0003" iyy="0.0003" izz="0.0003"/>
		</inertial>
	</link>
	<link name="22">
		<visual>
			<geometry>
				<cylinder length="0.9811320598336706" radius="0.08031974557518295"/>
			</geometry>
		</visual>
		<collision>
			<geometry>
				<cylinder length="0.9811320598336706" radius="0.08031974557518295"/>
			</geometry>
		</collision>
		<inertial>
			<mass value="0.09942286620343765"/>
			<inertia ixx="0.0003" iyy="0.0003" izz="0.0003"/>
		</inertial>
	</link>
	<link name="23">
		<visual>
			<geometry>
				<cylinder length="0.9811320598336706" radius="0.08031974557518295"/>
			</geometry>
		</visual>
		<collision>
			<geometry>
				<cylinder length="0.9811320598336706" radius="0.08031974557518295"/>
			</geometry>
		</collision>
		<inertial>
			<mass value="0.09942286620343765"/>
			<inertia ixx="0.0003" iyy="0.0003" izz="0.0003"/>
		</inertial>
	</link>
	<link name="24">
		<visual>
			<geometry>
				<cylinder length="0.9811320598336706" radius="0.08031974557518295"/>
			</geometry>
		</visual>
		<collision>
			<geometry>
				<cylinder length="0.9811320598336706" radius="0.08031974557518295"/>
			</geometry>
		</collision>
		<inertial>
			<mass value="0.09942286620343765"/>
			<inertia ixx="0.0003" iyy="0.0003" izz="0.0003"/>
		</inertial>
	</link>
	<link name="25">
		<visual>
			<geometry>
				<cylinder length="0.9811320598336706" radius="0.08031974557518295"/>
			</geometry>
		</visual>
		<collision>
			<geometry>
				<cylinder length="0.9811320598336706" radius="0.08031974557518295"/>
			</geometry>
		</collision>
		<inertial>
			<mass value="0.09942286620343765"/>
			<inertia ixx="0.0003" iyy="0.0003" izz="0.0003"/>
		</inertial>
	</link>
	<link name="36">
		<visual>
			<geometry>
				<cylinder length="0.7530188155348658" radius="0.5894251911623689"/>
			</geometry>
		</visual>
		<collision>
			<geometry>
				<cylinder length="0.7530188155348658" radius="0.5894251911623689"/>
			</geometry>
		</collision>
		<inertial>
			<mass value="0.5321042477332572"/>
			<inertia ixx="0.0003" iyy="0.0003" izz="0.0003"/>
		</inertial>
	</link>
	<link name="37">
		<visual>
			<geometry>
				<cylinder length="0.7530188155348658" radius="0.5894251911623689"/>
			</geometry>
		</visual>
		<collision>
			<geometry>
				<cylinder length="0.7530188155348658" radius="0.5894251911623689"/>
			</geometry>
		</collision>
		<inertial>
			<mass value="0.5321042477332572"/>
			<inertia ixx="0.0003" iyy="0.0003" izz="0.0003"/>
		</inertial>
	</link>
	<link name="38">
		<visual>
			<geometry>
				<cylinder length="0.7530188155348658" radius="0.5894251911623689"/>
			</geometry>
		</visual>
		<collision>
			<geometry>
				<cylinder length="0.7530188155348658" radius="0.5894251911623689"/>
			</geometry>
		</collision>
		<inertial>
			<mass value="0.5321042477332572"/>
			<inertia ixx="0.0003" iyy="0.0003" izz="0.0003"/>
		</inertial>
	</link>
	<link name="39">
		<visual>
			<geometry>
				<cylinder length="0.7530188155348658" radius="0.5894251911623689"/>
			</geometry>
		</visual>
		<collision>
			<geometry>
				<cylinder length="0.7530188155348658" radius="0.5894251911623689"/>
			</geometry>
		</collision>
		<inertial>
			<mass value="0.5321042477332572"/>
			<inertia ixx="0.0003" iyy="0.0003" izz="0.0003"/>
		</inertial>
	</link>
	<link name="110">
		<visual>
			<geometry>
				<cylinder length="0.04802856434970926" radius="0.12659549976073547"/>
			</geometry>
		</visual>
		<collision>
			<geometry>
				<cylinder length="0.04802856434970926" radius="0.12659549976073547"/>
			</geometry>
		</collision>
		<inertial>
			<mass value="0.629148095208603"/>
			<inertia ixx="0.0003" iyy="0.0003" izz="0.0003"/>
		</inertial>
	</link>
	<link name="211">
		<visual>
			<geometry>
				<cylinder length="0.9811320598336706" radius="0.08031974557518295"/>
			</geometry>
		</visual>
		<collision>
			<geometry>
				<cylinder length="0.9811320598336706" radius="0.08031974557518295"/>
			</geometry>
		</collision>
		<inertial>
			<mass value="0.09942286620343765"/>
			<inertia ixx="0.0003" iyy="0.0003" izz="0.0003"/>
		</inertial>
	</link>
	<link name="212">
		<visual>
			<geometry>
				<cylinder length="0.9811320598336706" radius="0.08031974557518295"/>
			</geometry>
		</visual>
		<collision>
			<geometry>
				<cylinder length="0.9811320598336706" radius="0.08031974557518295"/>
			</geometry>
		</collision>
		<inertial>
			<mass value="0.09942286620343765"/>
			<inertia ixx="0.0003" iyy="0.0003" izz="0.0003"/>
		</inertial>
	</link>
	<link name="213">
		<visual>
			<geometry>
				<cylinder length="0.9811320598336706" radius="0.08031974557518295"/>
			</geometry>
		</visual>
		<collision>
			<geometry>
				<cylinder length="0.9811320598336706" radius="0.08031974557518295"/>
			</geometry>
		</collision>
		<inertial>
			<mass value="0.09942286620343765"/>
			<inertia ixx="0.0003" iyy="0.0003" izz="0.0003"/>
		</inertial>
	</link>
	<link name="214">
		<visual>
			<geometry>
				<cylinder length="0.9811320598336706" radius="0.08031974557518295"/>
			</geometry>
		</visual>
		<collision>
			<geometry>
				<cylinder length="0.9811320598336706" radius="0.08031974557518295"/>
			</geometry>
		</collision>
		<inertial>
			<mass value="0.09942286620343765"/>
			<inertia ixx="0.0003" iyy="0.0003" izz="0.0003"/>
		</inertial>
	</link>
	<link name="315">
		<visual>
			<geometry>
				<cylinder length="0.7530188155348658" radius="0.5894251911623689"/>
			</geometry>
		</visual>
		<collision>
			<geometry>
				<cylinder length="0.7530188155348658" radius="0.5894251911623689"/>
			</geometry>
		</collision>
		<inertial>
			<mass value="0.5321042477332572"/>
			<inertia ixx="0.0003" iyy="0.0003" izz="0.0003"/>
		</inertial>
	</link>
	<link name="316">
		<visual>
			<geometry>
				<cylinder length="0.7530188155348658" radius="0.5894251911623689"/>
			</geometry>
		</visual>
		<collision>
			<geometry>
				<cylinder length="0.7530188155348658" radius="0.5894251911623689"/>
			</geometry>
		</collision>
		<inertial>
			<mass value="0.5321042477332572"/>
			<inertia ixx="0.0003" iyy="0.0003" izz="0.0003"/>
		</inertial>
	</link>
	<link name="317">
		<visual>
			<geometry>
				<cylinder length="0.7530188155348658" radius="0.5894251911623689"/>
			</geometry>
		</visual>
		<collision>
			<geometry>
				<cylinder length="0.7530188155348658" radius="0.5894251911623689"/>
			</geometry>
		</collision>
		<inertial>
			<mass value="0.5321042477332572"/>
			<inertia ixx="0.0003" iyy="0.0003" izz="0.0003"/>
		</inertial>
	</link>
	<link name="318">
		<visual>
			<geometry>
				<cylinder length="0.7530188155348658" radius="0.5894251911623689"/>
			</geometry>
		</visual>
		<collision>
			<geometry>
				<cylinder length="0.7530188155348658" radius="0.5894251911623689"/>
			</geometry>
		</collision>
		<inertial>
			<mass value="0.5321042477332572"/>
			<inertia ixx="0.0003" iyy="0.0003" izz="0.0003"/>
		</inertial>
	</link>
	<link name="119">
		<visual>
			<geometry>
				<cylinder length="0.04802856434970926" radius="0.12659549976073547"/>
			</geometry>
		</visual>
		<collision>
			<geometry>
				<cylinder length="0.04802856434970926" radius="0.12659549976073547"/>
			</geometry>
		</collision>
		<inertial>
			<mass value="0.629148095208603"/>
			<inertia ixx="0.0003" iyy="0.0003" izz="0.0003"/>
		</inertial>
	</link>
	<link name="220">
		<visual>
			<geometry>
				<cylinder length="0.9811320598336706" radius="0.08031974557518295"/>
			</geometry>
		</visual>
		<collision>
			<geometry>
				<cylinder length="0.9811320598336706" radius="0.08031974557518295"/>
			</geometry>
		</collision>
		<inertial>
			<mass value="0.09942286620343765"/>
			<inertia ixx="0.0003" iyy="0.0003" izz="0.0003"/>
		</inertial>
	</link>
	<link name="221">
		<visual>
			<geometry>
				<cylinder length="0.9811320598336706" radius="0.08031974557518295"/>
			</geometry>
		</visual>
		<collision>
			<geometry>
				<cylinder length="0.9811320598336706" radius="0.08031974557518295"/>
			</geometry>
		</collision>
		<inertial>
			<mass value="0.09942286620343765"/>
			<inertia ixx="0.0003" iyy="0.0003" izz="0.0003"/>
		</inertial>
	</link>
	<link name="222">
		<visual>
			<geometry>
				<cylinder length="0.9811320598336706" radius="0.08031974557518295"/>
			</geometry>
		</visual>
		<collision>
			<geometry>
				<cylinder length="0.9811320598336706" radius="0.08031974557518295"/>
			</geometry>
		</collision>
		<inertial>
			<mass value="0.09942286620343765"/>
			<inertia ixx="0.0003" iyy="0.0003" izz="0.0003"/>
		</inertial>
	</link>
	<link name="223">
		<visual>
			<geometry>
				<cylinder length="0.9811320598336706" radius="0.08031974557518295"/>
			</geometry>
		</visual>
		<collision>
			<geometry>
				<cylinder length="0.9811320598336706" radius="0.08031974557518295"/>
			</geometry>
		</collision>
		<inertial>
			<mass value="0.09942286620343765"/>
			<inertia ixx="0.0003" iyy="0.0003" izz="0.0003"/>
		</inertial>
	</link>
	<link name="324">
		<visual>
			<geometry>
				<cylinder length="0.7530188155348658" radius="0.5894251911623689"/>
			</geometry>
		</visual>
		<collision>
			<geometry>
				<cylinder length="0.7530188155348658" radius="0.5894251911623689"/>
			</geometry>
		</collision>
		<inertial>
			<mass value="0.5321042477332572"/>
			<inertia ixx="0.0003" iyy="0.0003" izz="0.0003"/>
		</inertial>
	</link>
	<link name="325">
		<visual>
			<geometry>
				<cylinder length="0.7530188155348658" radius="0.5894251911623689"/>
			</geometry>
		</visual>
		<collision>
			<geometry>
				<cylinder length="0.7530188155348658" radius="0.5894251911623689"/>
			</geometry>
		</collision>
		<inertial>
			<mass value="0.5321042477332572"/>
			<inertia ixx="0.0003" iyy="0.0003" izz="0.0003"/>
		</inertial>
	</link>
	<link name="326">
		<visual>
			<geometry>
				<cylinder length="0.7530188155348658" radius="0.5894251911623689"/>
			</geometry>
		</visual>
		<collision>
			<geometry>
				<cylinder length="0.7530188155348658" radius="0.5894251911623689"/>
			</geometry>
		</collision>
		<inertial>
			<mass value="0.5321042477332572"/>
			<inertia ixx="0.0003" iyy="0.0003" izz="0.0003"/>
		</inertial>
	</link>
	<link name="327">
		<visual>
			<geometry>
				<cylinder length="0.7530188155348658" radius="0.5894251911623689"/>
			</geometry>
		</visual>
		<collision>
			<geometry>
				<cylinder length="0.7530188155348658" radius="0.5894251911623689"/>
			</geometry>
		</collision>
		<inertial>
			<mass value="0.5321042477332572"/>
			<inertia ixx="0.0003" iyy="0.0003" izz="0.0003"/>
		</inertial>
	</link>
	<joint name="0_to_11" type="revolute">
		<parent link="0"/>
		<child link="11"/>
		<axis xyz="1 0 0"/>
		<limit effort="1" velocity="1"/>
		<origin rpy="11.239322130235905 0.4219768906325454 3.362741528276697" xyz="0.1514412611899113 0.8170815741802442 0.49473186585809537"/>
	</joint>
	<joint name="11_to_22" type="revolute">
		<parent link="11"/>
		<child link="22"/>
		<axis xyz="1 0 0"/>
		<limit effort="1" velocity="1"/>
		<origin rpy="1.365134209055266 3.861730201508749 2.3940423924812095" xyz="0.9259227834380324 0.393229984712666 0.07150675950979635"/>
	</joint>
	<joint name="11_to_23" type="revolute">
		<parent link="11"/>
		<child link="23"/>
		<axis xyz="1 0 0"/>
		<limit effort="1" velocity="1"/>
		<origin rpy="2.047701313582899 3.861730201508749 2.3940423924812095" xyz="0.9259227834380324 0.393229984712666 0.07150675950979635"/>
	</joint>
	<joint name="11_to_24" type="revolute">
		<parent link="11"/>
		<child link="24"/>
		<axis xyz="1 0 0"/>
		<limit effort="1" velocity="1"/>
		<origin rpy="2.730268418110532 3.861730201508749 2.3940423924812095" xyz="0.9259227834380324 0.393229984712666 0.07150675950979635"/>
	</joint>
	<joint name="11_to_25" type="revolute">
		<parent link="11"/>
		<child link="25"/>
		<axis xyz="1 0 0"/>
		<limit effort="1" velocity="1"/>
		<origin rpy="3.412835522638165 3.861730201508749 2.3940423924812095" xyz="0.9259227834380324 0.393229984712666 0.07150675950979635"/>
	</joint>
	<joint name="11_to_36" type="fixed">
		<parent link="11"/>
		<child link="36"/>
		<axis xyz="1 0 0"/>
		<limit effort="1" velocity="1"/>
		<origin rpy="15.94513899429036 4.912495397572739 0.24490561063041824" xyz="0.4905336252031922 0.672544282073186 0.12395250888422171"/>
	</joint>
	<joint name="11_to_37" type="fixed">
		<parent link="11"/>
		<child link="37"/>
		<axis xyz="1 0 0"/>
		<limit effort="1" velocity="1"/>
		<origin rpy="18.602662160005423 4.912495397572739 0.24490561063041824" xyz="0.4905336252031922 0.672544282073186 0.12395250888422171"/>
	</joint>
	<joint name="11_to_38" type="fixed">
		<parent link="11"/>
		<child link="38"/>
		<axis xyz="1 0 0"/>
		<limit effort="1" velocity="1"/>
		<origin rpy="21.26018532572048 4.912495397572739 0.24490561063041824" xyz="0.4905336252031922 0.672544282073186 0.12395250888422171"/>
	</joint>
	<joint name="11_to_39" type="fixed">
		<parent link="11"/>
		<child link="39"/>
		<axis xyz="1 0 0"/>
		<limit effort="1" velocity="1"/>
		<origin rpy="23.91770849143554 4.912495397572739 0.24490561063041824" xyz="0.4905336252031922 0.672544282073186 0.12395250888422171"/>
	</joint>
	<joint name="0_to_110" type="revolute">
		<parent link="0"/>
		<child link="110"/>
		<axis xyz="1 0 0"/>
		<limit effort="1" velocity="1"/>
		<origin rpy="16.858983195353858 0.4219768906325454 3.362741528276697" xyz="0.1514412611899113 0.8170815741802442 0.49473186585809537"/>
	</joint>
	<joint name="110_to_211" type="revolute">
		<parent link="110"/>
		<child link="211"/>
		<axis xyz="1 0 0"/>
		<limit effort="1" velocity="1"/>
		<origin rpy="1.365134209055266 3.861730201508749 2.3940423924812095" xyz="0.9259227834380324 0.393229984712666 0.07150675950979635"/>
	</joint>
	<joint name="110_to_212" type="revolute">
		<parent link="110"/>
		<child link="212"/>
		<axis xyz="1 0 0"/>
		<limit effort="1" velocity="1"/>
		<origin rpy="2.047701313582899 3.861730201508749 2.3940423924812095" xyz="0.9259227834380324 0.393229984712666 0.07150675950979635"/>
	</joint>
	<joint name="110_to_213" type="revolute">
		<parent link="110"/>
		<child link="213"/>
		<axis xyz="1 0 0"/>
		<limit effort="1" velocity="1"/>
		<origin rpy="2.730268418110532 3.861730201508749 2.3940423924812095" xyz="0.9259227834380324 0.393229984712666 0.07150675950979635"/>
	</joint>
	<joint name="110_to_214" type="revolute">
		<parent link="110"/>
		<child link="214"/>
		<axis xyz="1 0 0"/>
		<limit effort="1" velocity="1"/>
		<origin rpy="3.412835522638165 3.861730201508749 2.3940423924812095" xyz="0.9259227834380324 0.393229984712666 0.07150675950979635"/>
	</joint>
	<joint name="110_to_315" type="fixed">
		<parent link="110"/>
		<child link="315"/>
		<axis xyz="1 0 0"/>
		<limit effort="1" velocity="1"/>
		<origin rpy="15.94513899429036 4.912495397572739 0.24490561063041824" xyz="0.4905336252031922 0.672544282073186 0.12395250888422171"/>
	</joint>
	<joint name="110_to_316" type="fixed">
		<parent link="110"/>
		<child link="316"/>
		<axis xyz="1 0 0"/>
		<limit effort="1" velocity="1"/>
		<origin rpy="18.602662160005423 4.912495397572739 0.24490561063041824" xyz="0.4905336252031922 0.672544282073186 0.12395250888422171"/>
	</joint>
	<joint name="110_to_317" type="fixed">
		<parent link="110"/>
		<child link="317"/>
		<axis xyz="1 0 0"/>
		<limit effort="1" velocity="1"/>
		<origin rpy="21.26018532572048 4.912495397572739 0.24490561063041824" xyz="0.4905336252031922 0.672544282073186 0.12395250888422171"/>
	</joint>
	<joint name="110_to_318" type="fixed">
		<parent link="110"/>
		<child link="318"/>
		<axis xyz="1 0 0"/>
		<limit effort="1" velocity="1"/>
		<origin rpy="23.91770849143554 4.912495397572739 0.24490561063041824" xyz="0.4905336252031922 0.672544282073186 0.12395250888422171"/>
	</joint>
	<joint name="0_to_119" type="revolute">
		<parent link="0"/>
		<child link="119"/>
		<axis xyz="1 0 0"/>
		<limit effort="1" velocity="1"/>
		<origin rpy="22.47864426047181 0.4219768906325454 3.362741528276697" xyz="0.1514412611899113 0.8170815741802442 0.49473186585809537"/>
	</joint>
	<joint name="119_to_220" type="revolute">
		<parent link="119"/>
		<child link="220"/>
		<axis xyz="1 0 0"/>
		<limit effort="1" velocity="1"/>
		<origin rpy="1.365134209055266 3.861730201508749 2.3940423924812095" xyz="0.9259227834380324 0.393229984712666 0.07150675950979635"/>
	</joint>
	<joint name="119_to_221" type="revolute">
		<parent link="119"/>
		<child link="221"/>
		<axis xyz="1 0 0"/>
		<limit effort="1" velocity="1"/>
		<origin rpy="2.047701313582899 3.861730201508749 2.3940423924812095" xyz="0.9259227834380324 0.393229984712666 0.07150675950979635"/>
	</joint>
	<joint name="119_to_222" type="revolute">
		<parent link="119"/>
		<child link="222"/>
		<axis xyz="1 0 0"/>
		<limit effort="1" velocity="1"/>
		<origin rpy="2.730268418110532 3.861730201508749 2.3940423924812095" xyz="0.9259227834380324 0.393229984712666 0.07150675950979635"/>
	</joint>
	<joint name="119_to_223" type="revolute">
		<parent link="119"/>
		<child link="223"/>
		<axis xyz="1 0 0"/>
		<limit effort="1" velocity="1"/>
		<origin rpy="3.412835522638165 3.861730201508749 2.3940423924812095" xyz="0.9259227834380324 0.393229984712666 0.07150675950979635"/>
	</joint>
	<joint name="119_to_324" type="fixed">
		<parent link="119"/>
		<child link="324"/>
		<axis xyz="1 0 0"/>
		<limit effort="1" velocity="1"/>
		<origin rpy="15.94513899429036 4.912495397572739 0.24490561063041824" xyz="0.4905336252031922 0.672544282073186 0.12395250888422171"/>
	</joint>
	<joint name="119_to_325" type="fixed">
		<parent link="119"/>
		<child link="325"/>
		<axis xyz="1 0 0"/>
		<limit effort="1" velocity="1"/>
		<origin rpy="18.602662160005423 4.912495397572739 0.24490561063041824" xyz="0.4905336252031922 0.672544282073186 0.12395250888422171"/>
	</joint>
	<joint name="119_to_326" type="fixed">
		<parent link="119"/>
		<child link="326"/>
		<axis xyz="1 0 0"/>
		<limit effort="1" velocity="1"/>
		<origin rpy="21.26018532572048 4.912495397572739 0.24490561063041824" xyz="0.4905336252031922 0.672544282073186 0.12395250888422171"/>
	</joint>
	<joint name="119_to_327" type="fixed">
		<parent link="119"/>
		<child link="327"/>
		<axis xyz="1 0 0"/>
		<limit effort="1" velocity="1"/>
		<origin rpy="23.91770849143554 4.912495397572739 0.24490561063041824" xyz="0.4905336252031922 0.672544282073186 0.12395250888422171"/>
	</joint>
</robot>
