<?xml version="1.0"?><robot name="ted">
	<link name="0">
		<visual>
			<geometry>
				<cylinder length="0.6119584683593251" radius="0.4339244327853655"/>
			</geometry>
		</visual>
		<collision>
			<geometry>
				<cylinder length="0.6119584683593251" radius="0.4339244327853655"/>
			</geometry>
		</collision>
		<inertial>
			<mass value="0.4168076371655197"/>
			<inertia ixx="0.0003" iyy="0.0003" izz="0.0003"/>
		</inertial>
	</link>
	<link name="11">
		<visual>
			<geometry>
				<cylinder length="0.45671630138088715" radius="0.6762117956308141"/>
			</geometry>
		</visual>
		<collision>
			<geometry>
				<cylinder length="0.45671630138088715" radius="0.6762117956308141"/>
			</geometry>
		</collision>
		<inertial>
			<mass value="0.19512110023366225"/>
			<inertia ixx="0.0003" iyy="0.0003" izz="0.0003"/>
		</inertial>
	</link>
	<link name="22">
		<visual>
			<geometry>
				<cylinder length="0.43967144521324186" radius="0.3916268140937387"/>
			</geometry>
		</visual>
		<collision>
			<geometry>
				<cylinder length="0.43967144521324186" radius="0.3916268140937387"/>
			</geometry>
		</collision>
		<inertial>
			<mass value="0.8151653191789551"/>
			<inertia ixx="0.0003" iyy="0.0003" izz="0.0003"/>
		</inertial>
	</link>
	<link name="13">
		<visual>
			<geometry>
				<cylinder length="0.45671630138088715" radius="0.6762117956308141"/>
			</geometry>
		</visual>
		<collision>
			<geometry>
				<cylinder length="0.45671630138088715" radius="0.6762117956308141"/>
			</geometry>
		</collision>
		<inertial>
			<mass value="0.19512110023366225"/>
			<inertia ixx="0.0003" iyy="0.0003" izz="0.0003"/>
		</inertial>
	</link>
	<link name="24">
		<visual>
			<geometry>
				<cylinder length="0.43967144521324186" radius="0.3916268140937387"/>
			</geometry>
		</visual>
		<collision>
			<geometry>
				<cylinder length="0.43967144521324186" radius="0.3916268140937387"/>
			</geometry>
		</collision>
		<inertial>
			<mass value="0.8151653191789551"/>
			<inertia ixx="0.0003" iyy="0.0003" izz="0.0003"/>
		</inertial>
	</link>
	<joint name="0_to_11" type="revolute">
		<parent link="0"/>
		<child link="11"/>
		<axis xyz="1 0 0"/>
		<limit effort="1" velocity="1"/>
		<origin rpy="5.11171676556501 3.4066467326356085 1.2699115404688983" xyz="0.7206161006645317 0.09883725045434866 0.9739471090589862"/>
	</joint>
	<joint name="11_to_22" type="fixed">
		<parent link="11"/>
		<child link="22"/>
		<axis xyz="1 0 0"/>
		<limit effort="1" velocity="1"/>
		<origin rpy="6.7025010159798155 2.036197471241753 4.681843828602252" xyz="0.6630019361247073 0.2849131446403793 0.9259949593854481"/>
	</joint>
	<joint name="0_to_13" type="revolute">
		<parent link="0"/>
		<child link="13"/>
		<axis xyz="1 0 0"/>
		<limit effort="1" velocity="1"/>
		<origin rpy="7.667575148347515 3.4066467326356085 1.2699115404688983" xyz="0.7206161006645317 0.09883725045434866 0.9739471090589862"/>
	</joint>
	<joint name="13_to_24" type="fixed">
		<parent link="13"/>
		<child link="24"/>
		<axis xyz="1 0 0"/>
		<limit effort="1" velocity="1"/>
		<origin rpy="6.7025010159798155 2.036197471241753 4.681843828602252" xyz="0.6630019361247073 0.2849131446403793 0.9259949593854481"/>
	</joint>
</robot>
