<?xml version="1.0"?><robot name="ted">
	<link name="0">
		<visual>
			<geometry>
				<cylinder length="0.82849926566911" radius="0.9707825658879734"/>
			</geometry>
		</visual>
		<collision>
			<geometry>
				<cylinder length="0.82849926566911" radius="0.9707825658879734"/>
			</geometry>
		</collision>
		<inertial>
			<mass value="0.08024532698880871"/>
			<inertia ixx="0.0003" iyy="0.0003" izz="0.0003"/>
		</inertial>
	</link>
	<link name="11">
		<visual>
			<geometry>
				<cylinder length="0.8079490493559202" radius="0.3242207486120632"/>
			</geometry>
		</visual>
		<collision>
			<geometry>
				<cylinder length="0.8079490493559202" radius="0.3242207486120632"/>
			</geometry>
		</collision>
		<inertial>
			<mass value="0.8543097982994409"/>
			<inertia ixx="0.0003" iyy="0.0003" izz="0.0003"/>
		</inertial>
	</link>
	<link name="22">
		<visual>
			<geometry>
				<cylinder length="0.8803689865296115" radius="0.07315101733297436"/>
			</geometry>
		</visual>
		<collision>
			<geometry>
				<cylinder length="0.8803689865296115" radius="0.07315101733297436"/>
			</geometry>
		</collision>
		<inertial>
			<mass value="0.9163643432711779"/>
			<inertia ixx="0.0003" iyy="0.0003" izz="0.0003"/>
		</inertial>
	</link>
	<link name="33">
		<visual>
			<geometry>
				<cylinder length="0.7292657154196994" radius="0.16532493194688835"/>
			</geometry>
		</visual>
		<collision>
			<geometry>
				<cylinder length="0.7292657154196994" radius="0.16532493194688835"/>
			</geometry>
		</collision>
		<inertial>
			<mass value="0.8113456147884259"/>
			<inertia ixx="0.0003" iyy="0.0003" izz="0.0003"/>
		</inertial>
	</link>
	<link name="34">
		<visual>
			<geometry>
				<cylinder length="0.7292657154196994" radius="0.16532493194688835"/>
			</geometry>
		</visual>
		<collision>
			<geometry>
				<cylinder length="0.7292657154196994" radius="0.16532493194688835"/>
			</geometry>
		</collision>
		<inertial>
			<mass value="0.8113456147884259"/>
			<inertia ixx="0.0003" iyy="0.0003" izz="0.0003"/>
		</inertial>
	</link>
	<link name="25">
		<visual>
			<geometry>
				<cylinder length="0.8803689865296115" radius="0.07315101733297436"/>
			</geometry>
		</visual>
		<collision>
			<geometry>
				<cylinder length="0.8803689865296115" radius="0.07315101733297436"/>
			</geometry>
		</collision>
		<inertial>
			<mass value="0.9163643432711779"/>
			<inertia ixx="0.0003" iyy="0.0003" izz="0.0003"/>
		</inertial>
	</link>
	<link name="36">
		<visual>
			<geometry>
				<cylinder length="0.7292657154196994" radius="0.16532493194688835"/>
			</geometry>
		</visual>
		<collision>
			<geometry>
				<cylinder length="0.7292657154196994" radius="0.16532493194688835"/>
			</geometry>
		</collision>
		<inertial>
			<mass value="0.8113456147884259"/>
			<inertia ixx="0.0003" iyy="0.0003" izz="0.0003"/>
		</inertial>
	</link>
	<link name="37">
		<visual>
			<geometry>
				<cylinder length="0.7292657154196994" radius="0.16532493194688835"/>
			</geometry>
		</visual>
		<collision>
			<geometry>
				<cylinder length="0.7292657154196994" radius="0.16532493194688835"/>
			</geometry>
		</collision>
		<inertial>
			<mass value="0.8113456147884259"/>
			<inertia ixx="0.0003" iyy="0.0003" izz="0.0003"/>
		</inertial>
	</link>
	<link name="28">
		<visual>
			<geometry>
				<cylinder length="0.8803689865296115" radius="0.07315101733297436"/>
			</geometry>
		</visual>
		<collision>
			<geometry>
				<cylinder length="0.8803689865296115" radius="0.07315101733297436"/>
			</geometry>
		</collision>
		<inertial>
			<mass value="0.9163643432711779"/>
			<inertia ixx="0.0003" iyy="0.0003" izz="0.0003"/>
		</inertial>
	</link>
	<link name="39">
		<visual>
			<geometry>
				<cylinder length="0.7292657154196994" radius="0.16532493194688835"/>
			</geometry>
		</visual>
		<collision>
			<geometry>
				<cylinder length="0.7292657154196994" radius="0.16532493194688835"/>
			</geometry>
		</collision>
		<inertial>
			<mass value="0.8113456147884259"/>
			<inertia ixx="0.0003" iyy="0.0003" izz="0.0003"/>
		</inertial>
	</link>
	<link name="310">
		<visual>
			<geometry>
				<cylinder length="0.7292657154196994" radius="0.16532493194688835"/>
			</geometry>
		</visual>
		<collision>
			<geometry>
				<cylinder length="0.7292657154196994" radius="0.16532493194688835"/>
			</geometry>
		</collision>
		<inertial>
			<mass value="0.8113456147884259"/>
			<inertia ixx="0.0003" iyy="0.0003" izz="0.0003"/>
		</inertial>
	</link>
	<link name="211">
		<visual>
			<geometry>
				<cylinder length="0.8803689865296115" radius="0.07315101733297436"/>
			</geometry>
		</visual>
		<collision>
			<geometry>
				<cylinder length="0.8803689865296115" radius="0.07315101733297436"/>
			</geometry>
		</collision>
		<inertial>
			<mass value="0.9163643432711779"/>
			<inertia ixx="0.0003" iyy="0.0003" izz="0.0003"/>
		</inertial>
	</link>
	<link name="312">
		<visual>
			<geometry>
				<cylinder length="0.7292657154196994" radius="0.16532493194688835"/>
			</geometry>
		</visual>
		<collision>
			<geometry>
				<cylinder length="0.7292657154196994" radius="0.16532493194688835"/>
			</geometry>
		</collision>
		<inertial>
			<mass value="0.8113456147884259"/>
			<inertia ixx="0.0003" iyy="0.0003" izz="0.0003"/>
		</inertial>
	</link>
	<link name="313">
		<visual>
			<geometry>
				<cylinder length="0.7292657154196994" radius="0.16532493194688835"/>
			</geometry>
		</visual>
		<collision>
			<geometry>
				<cylinder length="0.7292657154196994" radius="0.16532493194688835"/>
			</geometry>
		</collision>
		<inertial>
			<mass value="0.8113456147884259"/>
			<inertia ixx="0.0003" iyy="0.0003" izz="0.0003"/>
		</inertial>
	</link>
	<joint name="0_to_11" type="revolute">
		<parent link="0"/>
		<child link="11"/>
		<axis xyz="1 0 0"/>
		<limit effort="1" velocity="1"/>
		<origin rpy="5.396826584901772 0.5193410864145511 0.5326220397299063" xyz="0.6733523492565321 0.12942244621041554 0.39750291479710775"/>
	</joint>
	<joint name="11_to_22" type="revolute">
		<parent link="11"/>
		<child link="22"/>
		<axis xyz="1 0 0"/>
		<limit effort="1" velocity="1"/>
		<origin rpy="9.358139367492143 3.282422824159685 5.173705150651962" xyz="0.38565215272970244 0.2795421257421108 0.29559042317319606"/>
	</joint>
	<joint name="22_to_33" type="revolute">
		<parent link="22"/>
		<child link="33"/>
		<axis xyz="1 0 0"/>
		<limit effort="1" velocity="1"/>
		<origin rpy="10.022722517743887 4.8232039311524 3.909501626297241" xyz="0.0763400790021933 0.9247836143409285 0.3438912343060887"/>
	</joint>
	<joint name="22_to_34" type="revolute">
		<parent link="22"/>
		<child link="34"/>
		<axis xyz="1 0 0"/>
		<limit effort="1" velocity="1"/>
		<origin rpy="15.03408377661583 4.8232039311524 3.909501626297241" xyz="0.0763400790021933 0.9247836143409285 0.3438912343060887"/>
	</joint>
	<joint name="11_to_25" type="revolute">
		<parent link="11"/>
		<child link="25"/>
		<axis xyz="1 0 0"/>
		<limit effort="1" velocity="1"/>
		<origin rpy="14.037209051238214 3.282422824159685 5.173705150651962" xyz="0.38565215272970244 0.2795421257421108 0.29559042317319606"/>
	</joint>
	<joint name="25_to_36" type="revolute">
		<parent link="25"/>
		<child link="36"/>
		<axis xyz="1 0 0"/>
		<limit effort="1" velocity="1"/>
		<origin rpy="10.022722517743887 4.8232039311524 3.909501626297241" xyz="0.0763400790021933 0.9247836143409285 0.3438912343060887"/>
	</joint>
	<joint name="25_to_37" type="revolute">
		<parent link="25"/>
		<child link="37"/>
		<axis xyz="1 0 0"/>
		<limit effort="1" velocity="1"/>
		<origin rpy="15.03408377661583 4.8232039311524 3.909501626297241" xyz="0.0763400790021933 0.9247836143409285 0.3438912343060887"/>
	</joint>
	<joint name="11_to_28" type="revolute">
		<parent link="11"/>
		<child link="28"/>
		<axis xyz="1 0 0"/>
		<limit effort="1" velocity="1"/>
		<origin rpy="18.716278734984286 3.282422824159685 5.173705150651962" xyz="0.38565215272970244 0.2795421257421108 0.29559042317319606"/>
	</joint>
	<joint name="28_to_39" type="revolute">
		<parent link="28"/>
		<child link="39"/>
		<axis xyz="1 0 0"/>
		<limit effort="1" velocity="1"/>
		<origin rpy="10.022722517743887 4.8232039311524 3.909501626297241" xyz="0.0763400790021933 0.9247836143409285 0.3438912343060887"/>
	</joint>
	<joint name="28_to_310" type="revolute">
		<parent link="28"/>
		<child link="310"/>
		<axis xyz="1 0 0"/>
		<limit effort="1" velocity="1"/>
		<origin rpy="15.03408377661583 4.8232039311524 3.909501626297241" xyz="0.0763400790021933 0.9247836143409285 0.3438912343060887"/>
	</joint>
	<joint name="11_to_211" type="revolute">
		<parent link="11"/>
		<child link="211"/>
		<axis xyz="1 0 0"/>
		<limit effort="1" velocity="1"/>
		<origin rpy="23.395348418730357 3.282422824159685 5.173705150651962" xyz="0.38565215272970244 0.2795421257421108 0.29559042317319606"/>
	</joint>
	<joint name="211_to_312" type="revolute">
		<parent link="211"/>
		<child link="312"/>
		<axis xyz="1 0 0"/>
		<limit effort="1" velocity="1"/>
		<origin rpy="10.022722517743887 4.8232039311524 3.909501626297241" xyz="0.0763400790021933 0.9247836143409285 0.3438912343060887"/>
	</joint>
	<joint name="211_to_313" type="revolute">
		<parent link="211"/>
		<child link="313"/>
		<axis xyz="1 0 0"/>
		<limit effort="1" velocity="1"/>
		<origin rpy="15.03408377661583 4.8232039311524 3.909501626297241" xyz="0.0763400790021933 0.9247836143409285 0.3438912343060887"/>
	</joint>
</robot>
