<?xml version="1.0"?><robot name="ted">
	<link name="0">
		<visual>
			<geometry>
				<cylinder length="0.6796474057055067" radius="0.06025397025807688"/>
			</geometry>
		</visual>
		<collision>
			<geometry>
				<cylinder length="0.6796474057055067" radius="0.06025397025807688"/>
			</geometry>
		</collision>
		<inertial>
			<mass value="0.9576674501473837"/>
			<inertia ixx="0.0003" iyy="0.0003" izz="0.0003"/>
		</inertial>
	</link>
	<link name="11">
		<visual>
			<geometry>
				<cylinder length="0.5104161326526147" radius="0.36796013857319376"/>
			</geometry>
		</visual>
		<collision>
			<geometry>
				<cylinder length="0.5104161326526147" radius="0.36796013857319376"/>
			</geometry>
		</collision>
		<inertial>
			<mass value="0.19260508477109606"/>
			<inertia ixx="0.0003" iyy="0.0003" izz="0.0003"/>
		</inertial>
	</link>
	<link name="22">
		<visual>
			<geometry>
				<cylinder length="0.43050715634404757" radius="0.9222927091926632"/>
			</geometry>
		</visual>
		<collision>
			<geometry>
				<cylinder length="0.43050715634404757" radius="0.9222927091926632"/>
			</geometry>
		</collision>
		<inertial>
			<mass value="0.674776319926726"/>
			<inertia ixx="0.0003" iyy="0.0003" izz="0.0003"/>
		</inertial>
	</link>
	<link name="23">
		<visual>
			<geometry>
				<cylinder length="0.43050715634404757" radius="0.9222927091926632"/>
			</geometry>
		</visual>
		<collision>
			<geometry>
				<cylinder length="0.43050715634404757" radius="0.9222927091926632"/>
			</geometry>
		</collision>
		<inertial>
			<mass value="0.674776319926726"/>
			<inertia ixx="0.0003" iyy="0.0003" izz="0.0003"/>
		</inertial>
	</link>
	<joint name="0_to_11" type="fixed">
		<parent link="0"/>
		<child link="11"/>
		<axis xyz="1 0 0"/>
		<limit effort="1" velocity="1"/>
		<origin rpy="6.045929688295032 5.215080526362034 5.332975148900843" xyz="0.0647123763930777 0.7159752044118834 0.7679146475609268"/>
	</joint>
	<joint name="0_to_22" type="revolute">
		<parent link="0"/>
		<child link="22"/>
		<axis xyz="1 0 0"/>
		<limit effort="1" velocity="1"/>
		<origin rpy="0.599829968856161 5.251168708810052 4.146831047012167" xyz="0.704286072567229 0.8285736280829977 0.45542272978667697"/>
	</joint>
	<joint name="0_to_23" type="revolute">
		<parent link="0"/>
		<child link="23"/>
		<axis xyz="1 0 0"/>
		<limit effort="1" velocity="1"/>
		<origin rpy="0.7997732918082147 5.251168708810052 4.146831047012167" xyz="0.704286072567229 0.8285736280829977 0.45542272978667697"/>
	</joint>
</robot>
