<?xml version="1.0"?><robot name="ted">
	<link name="0">
		<visual>
			<geometry>
				<cylinder length="0.6837529258832584" radius="0.9458604627998224"/>
			</geometry>
		</visual>
		<collision>
			<geometry>
				<cylinder length="0.6837529258832584" radius="0.9458604627998224"/>
			</geometry>
		</collision>
		<inertial>
			<mass value="0.7457402298794583"/>
			<inertia ixx="0.0003" iyy="0.0003" izz="0.0003"/>
		</inertial>
	</link>
	<link name="11">
		<visual>
			<geometry>
				<cylinder length="0.9549618377048786" radius="0.6301403256943768"/>
			</geometry>
		</visual>
		<collision>
			<geometry>
				<cylinder length="0.9549618377048786" radius="0.6301403256943768"/>
			</geometry>
		</collision>
		<inertial>
			<mass value="0.9059602521731824"/>
			<inertia ixx="0.0003" iyy="0.0003" izz="0.0003"/>
		</inertial>
	</link>
	<link name="12">
		<visual>
			<geometry>
				<cylinder length="0.9549618377048786" radius="0.6301403256943768"/>
			</geometry>
		</visual>
		<collision>
			<geometry>
				<cylinder length="0.9549618377048786" radius="0.6301403256943768"/>
			</geometry>
		</collision>
		<inertial>
			<mass value="0.9059602521731824"/>
			<inertia ixx="0.0003" iyy="0.0003" izz="0.0003"/>
		</inertial>
	</link>
	<link name="23">
		<visual>
			<geometry>
				<cylinder length="0.8894506098643382" radius="0.7559789026076871"/>
			</geometry>
		</visual>
		<collision>
			<geometry>
				<cylinder length="0.8894506098643382" radius="0.7559789026076871"/>
			</geometry>
		</collision>
		<inertial>
			<mass value="0.44736366272009565"/>
			<inertia ixx="0.0003" iyy="0.0003" izz="0.0003"/>
		</inertial>
	</link>
	<link name="24">
		<visual>
			<geometry>
				<cylinder length="0.8894506098643382" radius="0.7559789026076871"/>
			</geometry>
		</visual>
		<collision>
			<geometry>
				<cylinder length="0.8894506098643382" radius="0.7559789026076871"/>
			</geometry>
		</collision>
		<inertial>
			<mass value="0.44736366272009565"/>
			<inertia ixx="0.0003" iyy="0.0003" izz="0.0003"/>
		</inertial>
	</link>
	<link name="25">
		<visual>
			<geometry>
				<cylinder length="0.8894506098643382" radius="0.7559789026076871"/>
			</geometry>
		</visual>
		<collision>
			<geometry>
				<cylinder length="0.8894506098643382" radius="0.7559789026076871"/>
			</geometry>
		</collision>
		<inertial>
			<mass value="0.44736366272009565"/>
			<inertia ixx="0.0003" iyy="0.0003" izz="0.0003"/>
		</inertial>
	</link>
	<joint name="0_to_11" type="revolute">
		<parent link="0"/>
		<child link="11"/>
		<axis xyz="1 0 0"/>
		<limit effort="1" velocity="1"/>
		<origin rpy="9.63129901465597 0.5170502488772097 3.5920418865609864" xyz="0.3932748374880398 0.616263810309897 0.15444660257576093"/>
	</joint>
	<joint name="0_to_12" type="revolute">
		<parent link="0"/>
		<child link="12"/>
		<axis xyz="1 0 0"/>
		<limit effort="1" velocity="1"/>
		<origin rpy="14.446948521983954 0.5170502488772097 3.5920418865609864" xyz="0.3932748374880398 0.616263810309897 0.15444660257576093"/>
	</joint>
	<joint name="0_to_23" type="fixed">
		<parent link="0"/>
		<child link="23"/>
		<axis xyz="1 0 0"/>
		<limit effort="1" velocity="1"/>
		<origin rpy="22.893433190242998 4.694204409711059 0.8944217081213673" xyz="0.723265815982453 0.879537257236429 0.7359739094194797"/>
	</joint>
	<joint name="0_to_24" type="fixed">
		<parent link="0"/>
		<child link="24"/>
		<axis xyz="1 0 0"/>
		<limit effort="1" velocity="1"/>
		<origin rpy="28.61679148780375 4.694204409711059 0.8944217081213673" xyz="0.723265815982453 0.879537257236429 0.7359739094194797"/>
	</joint>
	<joint name="0_to_25" type="fixed">
		<parent link="0"/>
		<child link="25"/>
		<axis xyz="1 0 0"/>
		<limit effort="1" velocity="1"/>
		<origin rpy="34.340149785364495 4.694204409711059 0.8944217081213673" xyz="0.723265815982453 0.879537257236429 0.7359739094194797"/>
	</joint>
</robot>
