<?xml version="1.0"?><robot name="ted">
	<link name="0">
		<visual>
			<geometry>
				<cylinder length="0.28398240251131923" radius="0.7390878413404952"/>
			</geometry>
		</visual>
		<collision>
			<geometry>
				<cylinder length="0.28398240251131923" radius="0.7390878413404952"/>
			</geometry>
		</collision>
		<inertial>
			<mass value="0.46066775353622313"/>
			<inertia ixx="0.0003" iyy="0.0003" izz="0.0003"/>
		</inertial>
	</link>
	<link name="11">
		<visual>
			<geometry>
				<cylinder length="0.042797832434671834" radius="0.9870472196025623"/>
			</geometry>
		</visual>
		<collision>
			<geometry>
				<cylinder length="0.042797832434671834" radius="0.9870472196025623"/>
			</geometry>
		</collision>
		<inertial>
			<mass value="0.02649475875294538"/>
			<inertia ixx="0.0003" iyy="0.0003" izz="0.0003"/>
		</inertial>
	</link>
	<link name="12">
		<visual>
			<geometry>
				<cylinder length="0.042797832434671834" radius="0.9870472196025623"/>
			</geometry>
		</visual>
		<collision>
			<geometry>
				<cylinder length="0.042797832434671834" radius="0.9870472196025623"/>
			</geometry>
		</collision>
		<inertial>
			<mass value="0.02649475875294538"/>
			<inertia ixx="0.0003" iyy="0.0003" izz="0.0003"/>
		</inertial>
	</link>
	<link name="13">
		<visual>
			<geometry>
				<cylinder length="0.042797832434671834" radius="0.9870472196025623"/>
			</geometry>
		</visual>
		<collision>
			<geometry>
				<cylinder length="0.042797832434671834" radius="0.9870472196025623"/>
			</geometry>
		</collision>
		<inertial>
			<mass value="0.02649475875294538"/>
			<inertia ixx="0.0003" iyy="0.0003" izz="0.0003"/>
		</inertial>
	</link>
	<link name="14">
		<visual>
			<geometry>
				<cylinder length="0.042797832434671834" radius="0.9870472196025623"/>
			</geometry>
		</visual>
		<collision>
			<geometry>
				<cylinder length="0.042797832434671834" radius="0.9870472196025623"/>
			</geometry>
		</collision>
		<inertial>
			<mass value="0.02649475875294538"/>
			<inertia ixx="0.0003" iyy="0.0003" izz="0.0003"/>
		</inertial>
	</link>
	<link name="25">
		<visual>
			<geometry>
				<cylinder length="0.0033241599462673355" radius="0.43409758858946834"/>
			</geometry>
		</visual>
		<collision>
			<geometry>
				<cylinder length="0.0033241599462673355" radius="0.43409758858946834"/>
			</geometry>
		</collision>
		<inertial>
			<mass value="0.7997861727955152"/>
			<inertia ixx="0.0003" iyy="0.0003" izz="0.0003"/>
		</inertial>
	</link>
	<link name="26">
		<visual>
			<geometry>
				<cylinder length="0.0033241599462673355" radius="0.43409758858946834"/>
			</geometry>
		</visual>
		<collision>
			<geometry>
				<cylinder length="0.0033241599462673355" radius="0.43409758858946834"/>
			</geometry>
		</collision>
		<inertial>
			<mass value="0.7997861727955152"/>
			<inertia ixx="0.0003" iyy="0.0003" izz="0.0003"/>
		</inertial>
	</link>
	<link name="27">
		<visual>
			<geometry>
				<cylinder length="0.0033241599462673355" radius="0.43409758858946834"/>
			</geometry>
		</visual>
		<collision>
			<geometry>
				<cylinder length="0.0033241599462673355" radius="0.43409758858946834"/>
			</geometry>
		</collision>
		<inertial>
			<mass value="0.7997861727955152"/>
			<inertia ixx="0.0003" iyy="0.0003" izz="0.0003"/>
		</inertial>
	</link>
	<link name="28">
		<visual>
			<geometry>
				<cylinder length="0.0033241599462673355" radius="0.43409758858946834"/>
			</geometry>
		</visual>
		<collision>
			<geometry>
				<cylinder length="0.0033241599462673355" radius="0.43409758858946834"/>
			</geometry>
		</collision>
		<inertial>
			<mass value="0.7997861727955152"/>
			<inertia ixx="0.0003" iyy="0.0003" izz="0.0003"/>
		</inertial>
	</link>
	<joint name="0_to_11" type="revolute">
		<parent link="0"/>
		<child link="11"/>
		<axis xyz="1 0 0"/>
		<limit effort="1" velocity="1"/>
		<origin rpy="3.4866270233156262 3.1845115729762425 1.870276071862189" xyz="0.07032620838734782 0.7247642311892147 0.3969425369952374"/>
	</joint>
	<joint name="0_to_12" type="revolute">
		<parent link="0"/>
		<child link="12"/>
		<axis xyz="1 0 0"/>
		<limit effort="1" velocity="1"/>
		<origin rpy="5.229940534973439 3.1845115729762425 1.870276071862189" xyz="0.07032620838734782 0.7247642311892147 0.3969425369952374"/>
	</joint>
	<joint name="0_to_13" type="revolute">
		<parent link="0"/>
		<child link="13"/>
		<axis xyz="1 0 0"/>
		<limit effort="1" velocity="1"/>
		<origin rpy="6.9732540466312525 3.1845115729762425 1.870276071862189" xyz="0.07032620838734782 0.7247642311892147 0.3969425369952374"/>
	</joint>
	<joint name="0_to_14" type="revolute">
		<parent link="0"/>
		<child link="14"/>
		<axis xyz="1 0 0"/>
		<limit effort="1" velocity="1"/>
		<origin rpy="8.716567558289066 3.1845115729762425 1.870276071862189" xyz="0.07032620838734782 0.7247642311892147 0.3969425369952374"/>
	</joint>
	<joint name="0_to_25" type="fixed">
		<parent link="0"/>
		<child link="25"/>
		<axis xyz="1 0 0"/>
		<limit effort="1" velocity="1"/>
		<origin rpy="16.01713458198456 6.1164764893119745 1.7471893296671286" xyz="0.7423841743265314 0.5084425653916115 0.10457052155715774"/>
	</joint>
	<joint name="0_to_26" type="fixed">
		<parent link="0"/>
		<child link="26"/>
		<axis xyz="1 0 0"/>
		<limit effort="1" velocity="1"/>
		<origin rpy="18.686657012315322 6.1164764893119745 1.7471893296671286" xyz="0.7423841743265314 0.5084425653916115 0.10457052155715774"/>
	</joint>
	<joint name="0_to_27" type="fixed">
		<parent link="0"/>
		<child link="27"/>
		<axis xyz="1 0 0"/>
		<limit effort="1" velocity="1"/>
		<origin rpy="21.35617944264608 6.1164764893119745 1.7471893296671286" xyz="0.7423841743265314 0.5084425653916115 0.10457052155715774"/>
	</joint>
	<joint name="0_to_28" type="fixed">
		<parent link="0"/>
		<child link="28"/>
		<axis xyz="1 0 0"/>
		<limit effort="1" velocity="1"/>
		<origin rpy="24.02570187297684 6.1164764893119745 1.7471893296671286" xyz="0.7423841743265314 0.5084425653916115 0.10457052155715774"/>
	</joint>
</robot>
