<?xml version="1.0"?><robot name="ted">
	<link name="0">
		<visual>
			<geometry>
				<cylinder length="0.9979380049141086" radius="0.5689781072425203"/>
			</geometry>
		</visual>
		<collision>
			<geometry>
				<cylinder length="0.9979380049141086" radius="0.5689781072425203"/>
			</geometry>
		</collision>
		<inertial>
			<mass value="0.11227140365302335"/>
			<inertia ixx="0.0003" iyy="0.0003" izz="0.0003"/>
		</inertial>
	</link>
	<link name="11">
		<visual>
			<geometry>
				<cylinder length="0.4678907257033019" radius="0.36190288194175513"/>
			</geometry>
		</visual>
		<collision>
			<geometry>
				<cylinder length="0.4678907257033019" radius="0.36190288194175513"/>
			</geometry>
		</collision>
		<inertial>
			<mass value="0.12413472495150135"/>
			<inertia ixx="0.0003" iyy="0.0003" izz="0.0003"/>
		</inertial>
	</link>
	<link name="22">
		<visual>
			<geometry>
				<cylinder length="0.1460011650728299" radius="0.6157159791016855"/>
			</geometry>
		</visual>
		<collision>
			<geometry>
				<cylinder length="0.1460011650728299" radius="0.6157159791016855"/>
			</geometry>
		</collision>
		<inertial>
			<mass value="0.33360636649503206"/>
			<inertia ixx="0.0003" iyy="0.0003" izz="0.0003"/>
		</inertial>
	</link>
	<link name="13">
		<visual>
			<geometry>
				<cylinder length="0.4678907257033019" radius="0.36190288194175513"/>
			</geometry>
		</visual>
		<collision>
			<geometry>
				<cylinder length="0.4678907257033019" radius="0.36190288194175513"/>
			</geometry>
		</collision>
		<inertial>
			<mass value="0.12413472495150135"/>
			<inertia ixx="0.0003" iyy="0.0003" izz="0.0003"/>
		</inertial>
	</link>
	<link name="24">
		<visual>
			<geometry>
				<cylinder length="0.1460011650728299" radius="0.6157159791016855"/>
			</geometry>
		</visual>
		<collision>
			<geometry>
				<cylinder length="0.1460011650728299" radius="0.6157159791016855"/>
			</geometry>
		</collision>
		<inertial>
			<mass value="0.33360636649503206"/>
			<inertia ixx="0.0003" iyy="0.0003" izz="0.0003"/>
		</inertial>
	</link>
	<link name="15">
		<visual>
			<geometry>
				<cylinder length="0.4678907257033019" radius="0.36190288194175513"/>
			</geometry>
		</visual>
		<collision>
			<geometry>
				<cylinder length="0.4678907257033019" radius="0.36190288194175513"/>
			</geometry>
		</collision>
		<inertial>
			<mass value="0.12413472495150135"/>
			<inertia ixx="0.0003" iyy="0.0003" izz="0.0003"/>
		</inertial>
	</link>
	<link name="26">
		<visual>
			<geometry>
				<cylinder length="0.1460011650728299" radius="0.6157159791016855"/>
			</geometry>
		</visual>
		<collision>
			<geometry>
				<cylinder length="0.1460011650728299" radius="0.6157159791016855"/>
			</geometry>
		</collision>
		<inertial>
			<mass value="0.33360636649503206"/>
			<inertia ixx="0.0003" iyy="0.0003" izz="0.0003"/>
		</inertial>
	</link>
	<joint name="0_to_11" type="revolute">
		<parent link="0"/>
		<child link="11"/>
		<axis xyz="1 0 0"/>
		<limit effort="1" velocity="1"/>
		<origin rpy="1.1626555114622266 0.2742304399599992 4.27978909705314" xyz="0.7077684314526331 0.4931539853348531 0.9156447343460126"/>
	</joint>
	<joint name="11_to_22" type="revolute">
		<parent link="11"/>
		<child link="22"/>
		<axis xyz="1 0 0"/>
		<limit effort="1" velocity="1"/>
		<origin rpy="3.413581349285127 1.4298693351717962 0.37258806580208176" xyz="0.1934766238311394 0.19834920057797856 0.24399083554301337"/>
	</joint>
	<joint name="0_to_13" type="revolute">
		<parent link="0"/>
		<child link="13"/>
		<axis xyz="1 0 0"/>
		<limit effort="1" velocity="1"/>
		<origin rpy="1.74398326719334 0.2742304399599992 4.27978909705314" xyz="0.7077684314526331 0.4931539853348531 0.9156447343460126"/>
	</joint>
	<joint name="13_to_24" type="revolute">
		<parent link="13"/>
		<child link="24"/>
		<axis xyz="1 0 0"/>
		<limit effort="1" velocity="1"/>
		<origin rpy="3.413581349285127 1.4298693351717962 0.37258806580208176" xyz="0.1934766238311394 0.19834920057797856 0.24399083554301337"/>
	</joint>
	<joint name="0_to_15" type="revolute">
		<parent link="0"/>
		<child link="15"/>
		<axis xyz="1 0 0"/>
		<limit effort="1" velocity="1"/>
		<origin rpy="2.325311022924453 0.2742304399599992 4.27978909705314" xyz="0.7077684314526331 0.4931539853348531 0.9156447343460126"/>
	</joint>
	<joint name="15_to_26" type="revolute">
		<parent link="15"/>
		<child link="26"/>
		<axis xyz="1 0 0"/>
		<limit effort="1" velocity="1"/>
		<origin rpy="3.413581349285127 1.4298693351717962 0.37258806580208176" xyz="0.1934766238311394 0.19834920057797856 0.24399083554301337"/>
	</joint>
</robot>
