<?xml version="1.0"?><robot name="ted">
	<link name="0">
		<visual>
			<geometry>
				<cylinder length="0.12440182087772711" radius="0.17046075665882787"/>
			</geometry>
		</visual>
		<collision>
			<geometry>
				<cylinder length="0.12440182087772711" radius="0.17046075665882787"/>
			</geometry>
		</collision>
		<inertial>
			<mass value="0.06407169962860215"/>
			<inertia ixx="0.0003" iyy="0.0003" izz="0.0003"/>
		</inertial>
	</link>
	<link name="11">
		<visual>
			<geometry>
				<cylinder length="0.04802856434970926" radius="0.12659549976073547"/>
			</geometry>
		</visual>
		<collision>
			<geometry>
				<cylinder length="0.04802856434970926" radius="0.12659549976073547"/>
			</geometry>
		</collision>
		<inertial>
			<mass value="0.629148095208603"/>
			<inertia ixx="0.0003" iyy="0.0003" izz="0.0003"/>
		</inertial>
	</link>
	<link name="22">
		<visual>
			<geometry>
				<cylinder length="0.9811320598336706" radius="0.08031974557518295"/>
			</geometry>
		</visual>
		<collision>
			<geometry>
				<cylinder length="0.9811320598336706" radius="0.08031974557518295"/>
			</geometry>
		</collision>
		<inertial>
			<mass value="0.09942286620343765"/>
			<inertia ixx="0.0003" iyy="0.0003" izz="0.0003"/>
		</inertial>
	</link>
	<link name="23">
		<visual>
			<geometry>
				<cylinder length="0.9811320598336706" radius="0.08031974557518295"/>
			</geometry>
		</visual>
		<collision>
			<geometry>
				<cylinder length="0.9811320598336706" radius="0.08031974557518295"/>
			</geometry>
		</collision>
		<inertial>
			<mass value="0.09942286620343765"/>
			<inertia ixx="0.0003" iyy="0.0003" izz="0.0003"/>
		</inertial>
	</link>
	<link name="24">
		<visual>
			<geometry>
				<cylinder length="0.9811320598336706" radius="0.08031974557518295"/>
			</geometry>
		</visual>
		<collision>
			<geometry>
				<cylinder length="0.9811320598336706" radius="0.08031974557518295"/>
			</geometry>
		</collision>
		<inertial>
			<mass value="0.09942286620343765"/>
			<inertia ixx="0.0003" iyy="0.0003" izz="0.0003"/>
		</inertial>
	</link>
	<link name="25">
		<visual>
			<geometry>
				<cylinder length="0.9811320598336706" radius="0.08031974557518295"/>
			</geometry>
		</visual>
		<collision>
			<geometry>
				<cylinder length="0.9811320598336706" radius="0.08031974557518295"/>
			</geometry>
		</collision>
		<inertial>
			<mass value="0.09942286620343765"/>
			<inertia ixx="0.0003" iyy="0.0003" izz="0.0003"/>
		</inertial>
	</link>
	<link name="16">
		<visual>
			<geometry>
				<cylinder length="0.04802856434970926" radius="0.12659549976073547"/>
			</geometry>
		</visual>
		<collision>
			<geometry>
				<cylinder length="0.04802856434970926" radius="0.12659549976073547"/>
			</geometry>
		</collision>
		<inertial>
			<mass value="0.629148095208603"/>
			<inertia ixx="0.0003" iyy="0.0003" izz="0.0003"/>
		</inertial>
	</link>
	<link name="27">
		<visual>
			<geometry>
				<cylinder length="0.9811320598336706" radius="0.08031974557518295"/>
			</geometry>
		</visual>
		<collision>
			<geometry>
				<cylinder length="0.9811320598336706" radius="0.08031974557518295"/>
			</geometry>
		</collision>
		<inertial>
			<mass value="0.09942286620343765"/>
			<inertia ixx="0.0003" iyy="0.0003" izz="0.0003"/>
		</inertial>
	</link>
	<link name="28">
		<visual>
			<geometry>
				<cylinder length="0.9811320598336706" radius="0.08031974557518295"/>
			</geometry>
		</visual>
		<collision>
			<geometry>
				<cylinder length="0.9811320598336706" radius="0.08031974557518295"/>
			</geometry>
		</collision>
		<inertial>
			<mass value="0.09942286620343765"/>
			<inertia ixx="0.0003" iyy="0.0003" izz="0.0003"/>
		</inertial>
	</link>
	<link name="29">
		<visual>
			<geometry>
				<cylinder length="0.9811320598336706" radius="0.08031974557518295"/>
			</geometry>
		</visual>
		<collision>
			<geometry>
				<cylinder length="0.9811320598336706" radius="0.08031974557518295"/>
			</geometry>
		</collision>
		<inertial>
			<mass value="0.09942286620343765"/>
			<inertia ixx="0.0003" iyy="0.0003" izz="0.0003"/>
		</inertial>
	</link>
	<link name="210">
		<visual>
			<geometry>
				<cylinder length="0.9811320598336706" radius="0.08031974557518295"/>
			</geometry>
		</visual>
		<collision>
			<geometry>
				<cylinder length="0.9811320598336706" radius="0.08031974557518295"/>
			</geometry>
		</collision>
		<inertial>
			<mass value="0.09942286620343765"/>
			<inertia ixx="0.0003" iyy="0.0003" izz="0.0003"/>
		</inertial>
	</link>
	<link name="111">
		<visual>
			<geometry>
				<cylinder length="0.04802856434970926" radius="0.12659549976073547"/>
			</geometry>
		</visual>
		<collision>
			<geometry>
				<cylinder length="0.04802856434970926" radius="0.12659549976073547"/>
			</geometry>
		</collision>
		<inertial>
			<mass value="0.629148095208603"/>
			<inertia ixx="0.0003" iyy="0.0003" izz="0.0003"/>
		</inertial>
	</link>
	<link name="212">
		<visual>
			<geometry>
				<cylinder length="0.9811320598336706" radius="0.08031974557518295"/>
			</geometry>
		</visual>
		<collision>
			<geometry>
				<cylinder length="0.9811320598336706" radius="0.08031974557518295"/>
			</geometry>
		</collision>
		<inertial>
			<mass value="0.09942286620343765"/>
			<inertia ixx="0.0003" iyy="0.0003" izz="0.0003"/>
		</inertial>
	</link>
	<link name="213">
		<visual>
			<geometry>
				<cylinder length="0.9811320598336706" radius="0.08031974557518295"/>
			</geometry>
		</visual>
		<collision>
			<geometry>
				<cylinder length="0.9811320598336706" radius="0.08031974557518295"/>
			</geometry>
		</collision>
		<inertial>
			<mass value="0.09942286620343765"/>
			<inertia ixx="0.0003" iyy="0.0003" izz="0.0003"/>
		</inertial>
	</link>
	<link name="214">
		<visual>
			<geometry>
				<cylinder length="0.9811320598336706" radius="0.08031974557518295"/>
			</geometry>
		</visual>
		<collision>
			<geometry>
				<cylinder length="0.9811320598336706" radius="0.08031974557518295"/>
			</geometry>
		</collision>
		<inertial>
			<mass value="0.09942286620343765"/>
			<inertia ixx="0.0003" iyy="0.0003" izz="0.0003"/>
		</inertial>
	</link>
	<link name="215">
		<visual>
			<geometry>
				<cylinder length="0.9811320598336706" radius="0.08031974557518295"/>
			</geometry>
		</visual>
		<collision>
			<geometry>
				<cylinder length="0.9811320598336706" radius="0.08031974557518295"/>
			</geometry>
		</collision>
		<inertial>
			<mass value="0.09942286620343765"/>
			<inertia ixx="0.0003" iyy="0.0003" izz="0.0003"/>
		</inertial>
	</link>
	<joint name="0_to_11" type="revolute">
		<parent link="0"/>
		<child link="11"/>
		<axis xyz="1 0 0"/>
		<limit effort="1" velocity="1"/>
		<origin rpy="11.239322130235905 0.4219768906325454 3.4474283427065426" xyz="0.1514412611899113 0.8170815741802442 0.49473186585809537"/>
	</joint>
	<joint name="11_to_22" type="revolute">
		<parent link="11"/>
		<child link="22"/>
		<axis xyz="1 0 0"/>
		<limit effort="1" velocity="1"/>
		<origin rpy="1.365134209055266 3.861730201508749 2.3940423924812095" xyz="0.9259227834380324 0.4392173494824769 0.07150675950979635"/>
	</joint>
	<joint name="11_to_23" type="revolute">
		<parent link="11"/>
		<child link="23"/>
		<axis xyz="1 0 0"/>
		<limit effort="1" velocity="1"/>
		<origin rpy="2.047701313582899 3.861730201508749 2.3940423924812095" xyz="0.9259227834380324 0.4392173494824769 0.07150675950979635"/>
	</joint>
	<joint name="11_to_24" type="revolute">
		<parent link="11"/>
		<child link="24"/>
		<axis xyz="1 0 0"/>
		<limit effort="1" velocity="1"/>
		<origin rpy="2.730268418110532 3.861730201508749 2.3940423924812095" xyz="0.9259227834380324 0.4392173494824769 0.07150675950979635"/>
	</joint>
	<joint name="11_to_25" type="revolute">
		<parent link="11"/>
		<child link="25"/>
		<axis xyz="1 0 0"/>
		<limit effort="1" velocity="1"/>
		<origin rpy="3.412835522638165 3.861730201508749 2.3940423924812095" xyz="0.9259227834380324 0.4392173494824769 0.07150675950979635"/>
	</joint>
	<joint name="0_to_16" type="revolute">
		<parent link="0"/>
		<child link="16"/>
		<axis xyz="1 0 0"/>
		<limit effort="1" velocity="1"/>
		<origin rpy="16.858983195353858 0.4219768906325454 3.4474283427065426" xyz="0.1514412611899113 0.8170815741802442 0.49473186585809537"/>
	</joint>
	<joint name="16_to_27" type="revolute">
		<parent link="16"/>
		<child link="27"/>
		<axis xyz="1 0 0"/>
		<limit effort="1" velocity="1"/>
		<origin rpy="1.365134209055266 3.861730201508749 2.3940423924812095" xyz="0.9259227834380324 0.4392173494824769 0.07150675950979635"/>
	</joint>
	<joint name="16_to_28" type="revolute">
		<parent link="16"/>
		<child link="28"/>
		<axis xyz="1 0 0"/>
		<limit effort="1" velocity="1"/>
		<origin rpy="2.047701313582899 3.861730201508749 2.3940423924812095" xyz="0.9259227834380324 0.4392173494824769 0.07150675950979635"/>
	</joint>
	<joint name="16_to_29" type="revolute">
		<parent link="16"/>
		<child link="29"/>
		<axis xyz="1 0 0"/>
		<limit effort="1" velocity="1"/>
		<origin rpy="2.730268418110532 3.861730201508749 2.3940423924812095" xyz="0.9259227834380324 0.4392173494824769 0.07150675950979635"/>
	</joint>
	<joint name="16_to_210" type="revolute">
		<parent link="16"/>
		<child link="210"/>
		<axis xyz="1 0 0"/>
		<limit effort="1" velocity="1"/>
		<origin rpy="3.412835522638165 3.861730201508749 2.3940423924812095" xyz="0.9259227834380324 0.4392173494824769 0.07150675950979635"/>
	</joint>
	<joint name="0_to_111" type="revolute">
		<parent link="0"/>
		<child link="111"/>
		<axis xyz="1 0 0"/>
		<limit effort="1" velocity="1"/>
		<origin rpy="22.47864426047181 0.4219768906325454 3.4474283427065426" xyz="0.1514412611899113 0.8170815741802442 0.49473186585809537"/>
	</joint>
	<joint name="111_to_212" type="revolute">
		<parent link="111"/>
		<child link="212"/>
		<axis xyz="1 0 0"/>
		<limit effort="1" velocity="1"/>
		<origin rpy="1.365134209055266 3.861730201508749 2.3940423924812095" xyz="0.9259227834380324 0.4392173494824769 0.07150675950979635"/>
	</joint>
	<joint name="111_to_213" type="revolute">
		<parent link="111"/>
		<child link="213"/>
		<axis xyz="1 0 0"/>
		<limit effort="1" velocity="1"/>
		<origin rpy="2.047701313582899 3.861730201508749 2.3940423924812095" xyz="0.9259227834380324 0.4392173494824769 0.07150675950979635"/>
	</joint>
	<joint name="111_to_214" type="revolute">
		<parent link="111"/>
		<child link="214"/>
		<axis xyz="1 0 0"/>
		<limit effort="1" velocity="1"/>
		<origin rpy="2.730268418110532 3.861730201508749 2.3940423924812095" xyz="0.9259227834380324 0.4392173494824769 0.07150675950979635"/>
	</joint>
	<joint name="111_to_215" type="revolute">
		<parent link="111"/>
		<child link="215"/>
		<axis xyz="1 0 0"/>
		<limit effort="1" velocity="1"/>
		<origin rpy="3.412835522638165 3.861730201508749 2.3940423924812095" xyz="0.9259227834380324 0.4392173494824769 0.07150675950979635"/>
	</joint>
</robot>
