<?xml version="1.0"?><robot name="ted">
	<link name="0">
		<visual>
			<geometry>
				<cylinder length="0.054306300377287675" radius="0.5892146989850408"/>
			</geometry>
		</visual>
		<collision>
			<geometry>
				<cylinder length="0.054306300377287675" radius="0.5892146989850408"/>
			</geometry>
		</collision>
		<inertial>
			<mass value="0.7526891226514645"/>
			<inertia ixx="0.0003" iyy="0.0003" izz="0.0003"/>
		</inertial>
	</link>
	<link name="11">
		<visual>
			<geometry>
				<cylinder length="0.187087532994329" radius="0.572992621291648"/>
			</geometry>
		</visual>
		<collision>
			<geometry>
				<cylinder length="0.187087532994329" radius="0.572992621291648"/>
			</geometry>
		</collision>
		<inertial>
			<mass value="0.15636075680340045"/>
			<inertia ixx="0.0003" iyy="0.0003" izz="0.0003"/>
		</inertial>
	</link>
	<link name="12">
		<visual>
			<geometry>
				<cylinder length="0.187087532994329" radius="0.572992621291648"/>
			</geometry>
		</visual>
		<collision>
			<geometry>
				<cylinder length="0.187087532994329" radius="0.572992621291648"/>
			</geometry>
		</collision>
		<inertial>
			<mass value="0.15636075680340045"/>
			<inertia ixx="0.0003" iyy="0.0003" izz="0.0003"/>
		</inertial>
	</link>
	<link name="13">
		<visual>
			<geometry>
				<cylinder length="0.187087532994329" radius="0.572992621291648"/>
			</geometry>
		</visual>
		<collision>
			<geometry>
				<cylinder length="0.187087532994329" radius="0.572992621291648"/>
			</geometry>
		</collision>
		<inertial>
			<mass value="0.15636075680340045"/>
			<inertia ixx="0.0003" iyy="0.0003" izz="0.0003"/>
		</inertial>
	</link>
	<joint name="0_to_11" type="revolute">
		<parent link="0"/>
		<child link="11"/>
		<axis xyz="1 0 0"/>
		<limit effort="1" velocity="1"/>
		<origin rpy="6.019850997760448 5.9951599234050486 1.8002804145308209" xyz="0.8809305489802048 0.38411808954313476 0.20415605373873158"/>
	</joint>
	<joint name="0_to_12" type="revolute">
		<parent link="0"/>
		<child link="12"/>
		<axis xyz="1 0 0"/>
		<limit effort="1" velocity="1"/>
		<origin rpy="9.029776496640672 5.9951599234050486 1.8002804145308209" xyz="0.8809305489802048 0.38411808954313476 0.20415605373873158"/>
	</joint>
	<joint name="0_to_13" type="revolute">
		<parent link="0"/>
		<child link="13"/>
		<axis xyz="1 0 0"/>
		<limit effort="1" velocity="1"/>
		<origin rpy="12.039701995520897 5.9951599234050486 1.8002804145308209" xyz="0.8809305489802048 0.38411808954313476 0.20415605373873158"/>
	</joint>
</robot>
