<?xml version="1.0"?><robot name="ted">
	<link name="0">
		<visual>
			<geometry>
				<cylinder length="0.054306300377287675" radius="0.5892146989850408"/>
			</geometry>
		</visual>
		<collision>
			<geometry>
				<cylinder length="0.054306300377287675" radius="0.5892146989850408"/>
			</geometry>
		</collision>
		<inertial>
			<mass value="0.7526891226514645"/>
			<inertia ixx="0.0003" iyy="0.0003" izz="0.0003"/>
		</inertial>
	</link>
	<link name="11">
		<visual>
			<geometry>
				<cylinder length="0.09947828364326727" radius="0.06566944613952708"/>
			</geometry>
		</visual>
		<collision>
			<geometry>
				<cylinder length="0.09947828364326727" radius="0.06566944613952708"/>
			</geometry>
		</collision>
		<inertial>
			<mass value="0.9933860252397347"/>
			<inertia ixx="0.0003" iyy="0.0003" izz="0.0003"/>
		</inertial>
	</link>
	<link name="22">
		<visual>
			<geometry>
				<cylinder length="0.16063551896294537" radius="0.8597203587150178"/>
			</geometry>
		</visual>
		<collision>
			<geometry>
				<cylinder length="0.16063551896294537" radius="0.8597203587150178"/>
			</geometry>
		</collision>
		<inertial>
			<mass value="0.08249661977674638"/>
			<inertia ixx="0.0003" iyy="0.0003" izz="0.0003"/>
		</inertial>
	</link>
	<link name="23">
		<visual>
			<geometry>
				<cylinder length="0.16063551896294537" radius="0.8597203587150178"/>
			</geometry>
		</visual>
		<collision>
			<geometry>
				<cylinder length="0.16063551896294537" radius="0.8597203587150178"/>
			</geometry>
		</collision>
		<inertial>
			<mass value="0.08249661977674638"/>
			<inertia ixx="0.0003" iyy="0.0003" izz="0.0003"/>
		</inertial>
	</link>
	<link name="24">
		<visual>
			<geometry>
				<cylinder length="0.16063551896294537" radius="0.8597203587150178"/>
			</geometry>
		</visual>
		<collision>
			<geometry>
				<cylinder length="0.16063551896294537" radius="0.8597203587150178"/>
			</geometry>
		</collision>
		<inertial>
			<mass value="0.08249661977674638"/>
			<inertia ixx="0.0003" iyy="0.0003" izz="0.0003"/>
		</inertial>
	</link>
	<link name="25">
		<visual>
			<geometry>
				<cylinder length="0.16063551896294537" radius="0.8597203587150178"/>
			</geometry>
		</visual>
		<collision>
			<geometry>
				<cylinder length="0.16063551896294537" radius="0.8597203587150178"/>
			</geometry>
		</collision>
		<inertial>
			<mass value="0.08249661977674638"/>
			<inertia ixx="0.0003" iyy="0.0003" izz="0.0003"/>
		</inertial>
	</link>
	<joint name="0_to_11" type="revolute">
		<parent link="0"/>
		<child link="11"/>
		<axis xyz="1 0 0"/>
		<limit effort="1" velocity="1"/>
		<origin rpy="11.166033840113736 3.8542756614023634 6.040632625578819" xyz="0.5439193980779878 0.37444840678331615 0.7189470771365731"/>
	</joint>
	<joint name="0_to_22" type="revolute">
		<parent link="0"/>
		<child link="22"/>
		<axis xyz="1 0 0"/>
		<limit effort="1" velocity="1"/>
		<origin rpy="17.794309710543555 4.053688992947098 4.732238250770481" xyz="0.13446711138752465 0.33383683205248205 0.33318985105572585"/>
	</joint>
	<joint name="0_to_23" type="revolute">
		<parent link="0"/>
		<child link="23"/>
		<axis xyz="1 0 0"/>
		<limit effort="1" velocity="1"/>
		<origin rpy="23.72574628072474 4.053688992947098 4.732238250770481" xyz="0.13446711138752465 0.33383683205248205 0.33318985105572585"/>
	</joint>
	<joint name="0_to_24" type="revolute">
		<parent link="0"/>
		<child link="24"/>
		<axis xyz="1 0 0"/>
		<limit effort="1" velocity="1"/>
		<origin rpy="29.657182850905922 4.053688992947098 4.732238250770481" xyz="0.13446711138752465 0.33383683205248205 0.33318985105572585"/>
	</joint>
	<joint name="0_to_25" type="revolute">
		<parent link="0"/>
		<child link="25"/>
		<axis xyz="1 0 0"/>
		<limit effort="1" velocity="1"/>
		<origin rpy="35.58861942108711 4.053688992947098 4.732238250770481" xyz="0.13446711138752465 0.33383683205248205 0.33318985105572585"/>
	</joint>
</robot>
