<?xml version="1.0"?><robot name="ted">
	<link name="0">
		<visual>
			<geometry>
				<cylinder length="0.30804062851760383" radius="0.6738214328149634"/>
			</geometry>
		</visual>
		<collision>
			<geometry>
				<cylinder length="0.30804062851760383" radius="0.6738214328149634"/>
			</geometry>
		</collision>
		<inertial>
			<mass value="-0.041928476734819975"/>
			<inertia ixx="0.0003" iyy="0.0003" izz="0.0003"/>
		</inertial>
	</link>
	<link name="11">
		<visual>
			<geometry>
				<cylinder length="0.20148864524368926" radius="0.39336189641222474"/>
			</geometry>
		</visual>
		<collision>
			<geometry>
				<cylinder length="0.20148864524368926" radius="0.39336189641222474"/>
			</geometry>
		</collision>
		<inertial>
			<mass value="0.11888556824783847"/>
			<inertia ixx="0.0003" iyy="0.0003" izz="0.0003"/>
		</inertial>
	</link>
	<link name="12">
		<visual>
			<geometry>
				<cylinder length="0.20148864524368926" radius="0.39336189641222474"/>
			</geometry>
		</visual>
		<collision>
			<geometry>
				<cylinder length="0.20148864524368926" radius="0.39336189641222474"/>
			</geometry>
		</collision>
		<inertial>
			<mass value="0.11888556824783847"/>
			<inertia ixx="0.0003" iyy="0.0003" izz="0.0003"/>
		</inertial>
	</link>
	<link name="13">
		<visual>
			<geometry>
				<cylinder length="0.20148864524368926" radius="0.39336189641222474"/>
			</geometry>
		</visual>
		<collision>
			<geometry>
				<cylinder length="0.20148864524368926" radius="0.39336189641222474"/>
			</geometry>
		</collision>
		<inertial>
			<mass value="0.11888556824783847"/>
			<inertia ixx="0.0003" iyy="0.0003" izz="0.0003"/>
		</inertial>
	</link>
	<link name="24">
		<visual>
			<geometry>
				<cylinder length="0.6914661831663674" radius="0.8007755610867969"/>
			</geometry>
		</visual>
		<collision>
			<geometry>
				<cylinder length="0.6914661831663674" radius="0.8007755610867969"/>
			</geometry>
		</collision>
		<inertial>
			<mass value="0.21899950248364408"/>
			<inertia ixx="0.0003" iyy="0.0003" izz="0.0003"/>
		</inertial>
	</link>
	<link name="25">
		<visual>
			<geometry>
				<cylinder length="0.6914661831663674" radius="0.8007755610867969"/>
			</geometry>
		</visual>
		<collision>
			<geometry>
				<cylinder length="0.6914661831663674" radius="0.8007755610867969"/>
			</geometry>
		</collision>
		<inertial>
			<mass value="0.21899950248364408"/>
			<inertia ixx="0.0003" iyy="0.0003" izz="0.0003"/>
		</inertial>
	</link>
	<joint name="0_to_11" type="revolute">
		<parent link="0"/>
		<child link="11"/>
		<axis xyz="1 0 0"/>
		<limit effort="1" velocity="1"/>
		<origin rpy="1.0264651742255158 2.8809326456153213 2.0432824326917585" xyz="0.8406967620585992 0.17178042112934833 0.5677756171937046"/>
	</joint>
	<joint name="0_to_12" type="revolute">
		<parent link="0"/>
		<child link="12"/>
		<axis xyz="1 0 0"/>
		<limit effort="1" velocity="1"/>
		<origin rpy="1.5396977613382736 2.8809326456153213 2.0432824326917585" xyz="0.8406967620585992 0.17178042112934833 0.5677756171937046"/>
	</joint>
	<joint name="0_to_13" type="revolute">
		<parent link="0"/>
		<child link="13"/>
		<axis xyz="1 0 0"/>
		<limit effort="1" velocity="1"/>
		<origin rpy="2.0529303484510315 2.8809326456153213 2.0432824326917585" xyz="0.8406967620585992 0.17178042112934833 0.5677756171937046"/>
	</joint>
	<joint name="0_to_24" type="revolute">
		<parent link="0"/>
		<child link="24"/>
		<axis xyz="1 0 0"/>
		<limit effort="1" velocity="1"/>
		<origin rpy="8.195870269966074 0.5896338279879213 6.0474511397840685" xyz="0.6393194556138254 0.591008357849777 0.6075456806105207"/>
	</joint>
	<joint name="0_to_25" type="revolute">
		<parent link="0"/>
		<child link="25"/>
		<axis xyz="1 0 0"/>
		<limit effort="1" velocity="1"/>
		<origin rpy="9.835044323959288 0.5896338279879213 6.0474511397840685" xyz="0.6393194556138254 0.591008357849777 0.6075456806105207"/>
	</joint>
</robot>
