<?xml version="1.0"?><robot name="ted">
	<link name="0">
		<visual>
			<geometry>
				<cylinder length="0.9979380049141086" radius="0.5689781072425203"/>
			</geometry>
		</visual>
		<collision>
			<geometry>
				<cylinder length="0.9979380049141086" radius="0.5689781072425203"/>
			</geometry>
		</collision>
		<inertial>
			<mass value="0.11227140365302335"/>
			<inertia ixx="0.0003" iyy="0.0003" izz="0.0003"/>
		</inertial>
	</link>
	<link name="11">
		<visual>
			<geometry>
				<cylinder length="0.4678907257033019" radius="0.36190288194175513"/>
			</geometry>
		</visual>
		<collision>
			<geometry>
				<cylinder length="0.4678907257033019" radius="0.36190288194175513"/>
			</geometry>
		</collision>
		<inertial>
			<mass value="0.12413472495150135"/>
			<inertia ixx="0.0003" iyy="0.0003" izz="0.0003"/>
		</inertial>
	</link>
	<link name="22">
		<visual>
			<geometry>
				<cylinder length="0.1460011650728299" radius="0.6157159791016855"/>
			</geometry>
		</visual>
		<collision>
			<geometry>
				<cylinder length="0.1460011650728299" radius="0.6157159791016855"/>
			</geometry>
		</collision>
		<inertial>
			<mass value="0.33360636649503206"/>
			<inertia ixx="0.0003" iyy="0.0003" izz="0.0003"/>
		</inertial>
	</link>
	<link name="33">
		<visual>
			<geometry>
				<cylinder length="0.23915874746208066" radius="0.36194338447626084"/>
			</geometry>
		</visual>
		<collision>
			<geometry>
				<cylinder length="0.23915874746208066" radius="0.36194338447626084"/>
			</geometry>
		</collision>
		<inertial>
			<mass value="0.04004598085070821"/>
			<inertia ixx="0.0003" iyy="0.0003" izz="0.0003"/>
		</inertial>
	</link>
	<link name="34">
		<visual>
			<geometry>
				<cylinder length="0.23915874746208066" radius="0.36194338447626084"/>
			</geometry>
		</visual>
		<collision>
			<geometry>
				<cylinder length="0.23915874746208066" radius="0.36194338447626084"/>
			</geometry>
		</collision>
		<inertial>
			<mass value="0.04004598085070821"/>
			<inertia ixx="0.0003" iyy="0.0003" izz="0.0003"/>
		</inertial>
	</link>
	<link name="35">
		<visual>
			<geometry>
				<cylinder length="0.23915874746208066" radius="0.36194338447626084"/>
			</geometry>
		</visual>
		<collision>
			<geometry>
				<cylinder length="0.23915874746208066" radius="0.36194338447626084"/>
			</geometry>
		</collision>
		<inertial>
			<mass value="0.04004598085070821"/>
			<inertia ixx="0.0003" iyy="0.0003" izz="0.0003"/>
		</inertial>
	</link>
	<link name="36">
		<visual>
			<geometry>
				<cylinder length="0.23915874746208066" radius="0.36194338447626084"/>
			</geometry>
		</visual>
		<collision>
			<geometry>
				<cylinder length="0.23915874746208066" radius="0.36194338447626084"/>
			</geometry>
		</collision>
		<inertial>
			<mass value="0.04004598085070821"/>
			<inertia ixx="0.0003" iyy="0.0003" izz="0.0003"/>
		</inertial>
	</link>
	<link name="17">
		<visual>
			<geometry>
				<cylinder length="0.4678907257033019" radius="0.36190288194175513"/>
			</geometry>
		</visual>
		<collision>
			<geometry>
				<cylinder length="0.4678907257033019" radius="0.36190288194175513"/>
			</geometry>
		</collision>
		<inertial>
			<mass value="0.12413472495150135"/>
			<inertia ixx="0.0003" iyy="0.0003" izz="0.0003"/>
		</inertial>
	</link>
	<link name="28">
		<visual>
			<geometry>
				<cylinder length="0.1460011650728299" radius="0.6157159791016855"/>
			</geometry>
		</visual>
		<collision>
			<geometry>
				<cylinder length="0.1460011650728299" radius="0.6157159791016855"/>
			</geometry>
		</collision>
		<inertial>
			<mass value="0.33360636649503206"/>
			<inertia ixx="0.0003" iyy="0.0003" izz="0.0003"/>
		</inertial>
	</link>
	<link name="39">
		<visual>
			<geometry>
				<cylinder length="0.23915874746208066" radius="0.36194338447626084"/>
			</geometry>
		</visual>
		<collision>
			<geometry>
				<cylinder length="0.23915874746208066" radius="0.36194338447626084"/>
			</geometry>
		</collision>
		<inertial>
			<mass value="0.04004598085070821"/>
			<inertia ixx="0.0003" iyy="0.0003" izz="0.0003"/>
		</inertial>
	</link>
	<link name="310">
		<visual>
			<geometry>
				<cylinder length="0.23915874746208066" radius="0.36194338447626084"/>
			</geometry>
		</visual>
		<collision>
			<geometry>
				<cylinder length="0.23915874746208066" radius="0.36194338447626084"/>
			</geometry>
		</collision>
		<inertial>
			<mass value="0.04004598085070821"/>
			<inertia ixx="0.0003" iyy="0.0003" izz="0.0003"/>
		</inertial>
	</link>
	<link name="311">
		<visual>
			<geometry>
				<cylinder length="0.23915874746208066" radius="0.36194338447626084"/>
			</geometry>
		</visual>
		<collision>
			<geometry>
				<cylinder length="0.23915874746208066" radius="0.36194338447626084"/>
			</geometry>
		</collision>
		<inertial>
			<mass value="0.04004598085070821"/>
			<inertia ixx="0.0003" iyy="0.0003" izz="0.0003"/>
		</inertial>
	</link>
	<link name="312">
		<visual>
			<geometry>
				<cylinder length="0.23915874746208066" radius="0.36194338447626084"/>
			</geometry>
		</visual>
		<collision>
			<geometry>
				<cylinder length="0.23915874746208066" radius="0.36194338447626084"/>
			</geometry>
		</collision>
		<inertial>
			<mass value="0.04004598085070821"/>
			<inertia ixx="0.0003" iyy="0.0003" izz="0.0003"/>
		</inertial>
	</link>
	<link name="113">
		<visual>
			<geometry>
				<cylinder length="0.4678907257033019" radius="0.36190288194175513"/>
			</geometry>
		</visual>
		<collision>
			<geometry>
				<cylinder length="0.4678907257033019" radius="0.36190288194175513"/>
			</geometry>
		</collision>
		<inertial>
			<mass value="0.12413472495150135"/>
			<inertia ixx="0.0003" iyy="0.0003" izz="0.0003"/>
		</inertial>
	</link>
	<link name="214">
		<visual>
			<geometry>
				<cylinder length="0.1460011650728299" radius="0.6157159791016855"/>
			</geometry>
		</visual>
		<collision>
			<geometry>
				<cylinder length="0.1460011650728299" radius="0.6157159791016855"/>
			</geometry>
		</collision>
		<inertial>
			<mass value="0.33360636649503206"/>
			<inertia ixx="0.0003" iyy="0.0003" izz="0.0003"/>
		</inertial>
	</link>
	<link name="315">
		<visual>
			<geometry>
				<cylinder length="0.23915874746208066" radius="0.36194338447626084"/>
			</geometry>
		</visual>
		<collision>
			<geometry>
				<cylinder length="0.23915874746208066" radius="0.36194338447626084"/>
			</geometry>
		</collision>
		<inertial>
			<mass value="0.04004598085070821"/>
			<inertia ixx="0.0003" iyy="0.0003" izz="0.0003"/>
		</inertial>
	</link>
	<link name="316">
		<visual>
			<geometry>
				<cylinder length="0.23915874746208066" radius="0.36194338447626084"/>
			</geometry>
		</visual>
		<collision>
			<geometry>
				<cylinder length="0.23915874746208066" radius="0.36194338447626084"/>
			</geometry>
		</collision>
		<inertial>
			<mass value="0.04004598085070821"/>
			<inertia ixx="0.0003" iyy="0.0003" izz="0.0003"/>
		</inertial>
	</link>
	<link name="317">
		<visual>
			<geometry>
				<cylinder length="0.23915874746208066" radius="0.36194338447626084"/>
			</geometry>
		</visual>
		<collision>
			<geometry>
				<cylinder length="0.23915874746208066" radius="0.36194338447626084"/>
			</geometry>
		</collision>
		<inertial>
			<mass value="0.04004598085070821"/>
			<inertia ixx="0.0003" iyy="0.0003" izz="0.0003"/>
		</inertial>
	</link>
	<link name="318">
		<visual>
			<geometry>
				<cylinder length="0.23915874746208066" radius="0.36194338447626084"/>
			</geometry>
		</visual>
		<collision>
			<geometry>
				<cylinder length="0.23915874746208066" radius="0.36194338447626084"/>
			</geometry>
		</collision>
		<inertial>
			<mass value="0.04004598085070821"/>
			<inertia ixx="0.0003" iyy="0.0003" izz="0.0003"/>
		</inertial>
	</link>
	<joint name="0_to_11" type="revolute">
		<parent link="0"/>
		<child link="11"/>
		<axis xyz="1 0 0"/>
		<limit effort="1" velocity="1"/>
		<origin rpy="1.1626555114622266 0.2742304399599992 4.27978909705314" xyz="0.7077684314526331 0.4931539853348531 0.9156447343460126"/>
	</joint>
	<joint name="11_to_22" type="revolute">
		<parent link="11"/>
		<child link="22"/>
		<axis xyz="1 0 0"/>
		<limit effort="1" velocity="1"/>
		<origin rpy="3.413581349285127 1.4298693351717962 0.37258806580208176" xyz="0.1934766238311394 0.19834920057797856 0.24399083554301337"/>
	</joint>
	<joint name="11_to_33" type="revolute">
		<parent link="11"/>
		<child link="33"/>
		<axis xyz="1 0 0"/>
		<limit effort="1" velocity="1"/>
		<origin rpy="5.733200491187245 2.67332603986551 3.068627847671473" xyz="0.43158850866682186 0.12353077698733517 0.5786838806855852"/>
	</joint>
	<joint name="11_to_34" type="revolute">
		<parent link="11"/>
		<child link="34"/>
		<axis xyz="1 0 0"/>
		<limit effort="1" velocity="1"/>
		<origin rpy="7.644267321582993 2.67332603986551 3.068627847671473" xyz="0.43158850866682186 0.12353077698733517 0.5786838806855852"/>
	</joint>
	<joint name="11_to_35" type="revolute">
		<parent link="11"/>
		<child link="35"/>
		<axis xyz="1 0 0"/>
		<limit effort="1" velocity="1"/>
		<origin rpy="9.555334151978741 2.67332603986551 3.068627847671473" xyz="0.43158850866682186 0.12353077698733517 0.5786838806855852"/>
	</joint>
	<joint name="11_to_36" type="revolute">
		<parent link="11"/>
		<child link="36"/>
		<axis xyz="1 0 0"/>
		<limit effort="1" velocity="1"/>
		<origin rpy="11.46640098237449 2.67332603986551 3.068627847671473" xyz="0.43158850866682186 0.12353077698733517 0.5786838806855852"/>
	</joint>
	<joint name="0_to_17" type="revolute">
		<parent link="0"/>
		<child link="17"/>
		<axis xyz="1 0 0"/>
		<limit effort="1" velocity="1"/>
		<origin rpy="1.74398326719334 0.2742304399599992 4.27978909705314" xyz="0.7077684314526331 0.4931539853348531 0.9156447343460126"/>
	</joint>
	<joint name="17_to_28" type="revolute">
		<parent link="17"/>
		<child link="28"/>
		<axis xyz="1 0 0"/>
		<limit effort="1" velocity="1"/>
		<origin rpy="3.413581349285127 1.4298693351717962 0.37258806580208176" xyz="0.1934766238311394 0.19834920057797856 0.24399083554301337"/>
	</joint>
	<joint name="17_to_39" type="revolute">
		<parent link="17"/>
		<child link="39"/>
		<axis xyz="1 0 0"/>
		<limit effort="1" velocity="1"/>
		<origin rpy="5.733200491187245 2.67332603986551 3.068627847671473" xyz="0.43158850866682186 0.12353077698733517 0.5786838806855852"/>
	</joint>
	<joint name="17_to_310" type="revolute">
		<parent link="17"/>
		<child link="310"/>
		<axis xyz="1 0 0"/>
		<limit effort="1" velocity="1"/>
		<origin rpy="7.644267321582993 2.67332603986551 3.068627847671473" xyz="0.43158850866682186 0.12353077698733517 0.5786838806855852"/>
	</joint>
	<joint name="17_to_311" type="revolute">
		<parent link="17"/>
		<child link="311"/>
		<axis xyz="1 0 0"/>
		<limit effort="1" velocity="1"/>
		<origin rpy="9.555334151978741 2.67332603986551 3.068627847671473" xyz="0.43158850866682186 0.12353077698733517 0.5786838806855852"/>
	</joint>
	<joint name="17_to_312" type="revolute">
		<parent link="17"/>
		<child link="312"/>
		<axis xyz="1 0 0"/>
		<limit effort="1" velocity="1"/>
		<origin rpy="11.46640098237449 2.67332603986551 3.068627847671473" xyz="0.43158850866682186 0.12353077698733517 0.5786838806855852"/>
	</joint>
	<joint name="0_to_113" type="revolute">
		<parent link="0"/>
		<child link="113"/>
		<axis xyz="1 0 0"/>
		<limit effort="1" velocity="1"/>
		<origin rpy="2.325311022924453 0.2742304399599992 4.27978909705314" xyz="0.7077684314526331 0.4931539853348531 0.9156447343460126"/>
	</joint>
	<joint name="113_to_214" type="revolute">
		<parent link="113"/>
		<child link="214"/>
		<axis xyz="1 0 0"/>
		<limit effort="1" velocity="1"/>
		<origin rpy="3.413581349285127 1.4298693351717962 0.37258806580208176" xyz="0.1934766238311394 0.19834920057797856 0.24399083554301337"/>
	</joint>
	<joint name="113_to_315" type="revolute">
		<parent link="113"/>
		<child link="315"/>
		<axis xyz="1 0 0"/>
		<limit effort="1" velocity="1"/>
		<origin rpy="5.733200491187245 2.67332603986551 3.068627847671473" xyz="0.43158850866682186 0.12353077698733517 0.5786838806855852"/>
	</joint>
	<joint name="113_to_316" type="revolute">
		<parent link="113"/>
		<child link="316"/>
		<axis xyz="1 0 0"/>
		<limit effort="1" velocity="1"/>
		<origin rpy="7.644267321582993 2.67332603986551 3.068627847671473" xyz="0.43158850866682186 0.12353077698733517 0.5786838806855852"/>
	</joint>
	<joint name="113_to_317" type="revolute">
		<parent link="113"/>
		<child link="317"/>
		<axis xyz="1 0 0"/>
		<limit effort="1" velocity="1"/>
		<origin rpy="9.555334151978741 2.67332603986551 3.068627847671473" xyz="0.43158850866682186 0.12353077698733517 0.5786838806855852"/>
	</joint>
	<joint name="113_to_318" type="revolute">
		<parent link="113"/>
		<child link="318"/>
		<axis xyz="1 0 0"/>
		<limit effort="1" velocity="1"/>
		<origin rpy="11.46640098237449 2.67332603986551 3.068627847671473" xyz="0.43158850866682186 0.12353077698733517 0.5786838806855852"/>
	</joint>
</robot>
