<?xml version="1.0"?><robot name="ted">
	<link name="0">
		<visual>
			<geometry>
				<cylinder length="0.15113824252047015" radius="0.4296970259490408"/>
			</geometry>
		</visual>
		<collision>
			<geometry>
				<cylinder length="0.15113824252047015" radius="0.4296970259490408"/>
			</geometry>
		</collision>
		<inertial>
			<mass value="0.6406075354898184"/>
			<inertia ixx="0.0003" iyy="0.0003" izz="0.0003"/>
		</inertial>
	</link>
	<link name="11">
		<visual>
			<geometry>
				<cylinder length="0.32768364753998247" radius="0.6765220306374614"/>
			</geometry>
		</visual>
		<collision>
			<geometry>
				<cylinder length="0.32768364753998247" radius="0.6765220306374614"/>
			</geometry>
		</collision>
		<inertial>
			<mass value="0.21962730422956667"/>
			<inertia ixx="0.0003" iyy="0.0003" izz="0.0003"/>
		</inertial>
	</link>
	<link name="22">
		<visual>
			<geometry>
				<cylinder length="0.5895765108887729" radius="0.607391736853669"/>
			</geometry>
		</visual>
		<collision>
			<geometry>
				<cylinder length="0.5895765108887729" radius="0.607391736853669"/>
			</geometry>
		</collision>
		<inertial>
			<mass value="0.41090573523269014"/>
			<inertia ixx="0.0003" iyy="0.0003" izz="0.0003"/>
		</inertial>
	</link>
	<link name="23">
		<visual>
			<geometry>
				<cylinder length="0.5895765108887729" radius="0.607391736853669"/>
			</geometry>
		</visual>
		<collision>
			<geometry>
				<cylinder length="0.5895765108887729" radius="0.607391736853669"/>
			</geometry>
		</collision>
		<inertial>
			<mass value="0.41090573523269014"/>
			<inertia ixx="0.0003" iyy="0.0003" izz="0.0003"/>
		</inertial>
	</link>
	<link name="24">
		<visual>
			<geometry>
				<cylinder length="0.5895765108887729" radius="0.607391736853669"/>
			</geometry>
		</visual>
		<collision>
			<geometry>
				<cylinder length="0.5895765108887729" radius="0.607391736853669"/>
			</geometry>
		</collision>
		<inertial>
			<mass value="0.41090573523269014"/>
			<inertia ixx="0.0003" iyy="0.0003" izz="0.0003"/>
		</inertial>
	</link>
	<link name="15">
		<visual>
			<geometry>
				<cylinder length="0.32768364753998247" radius="0.6765220306374614"/>
			</geometry>
		</visual>
		<collision>
			<geometry>
				<cylinder length="0.32768364753998247" radius="0.6765220306374614"/>
			</geometry>
		</collision>
		<inertial>
			<mass value="0.21962730422956667"/>
			<inertia ixx="0.0003" iyy="0.0003" izz="0.0003"/>
		</inertial>
	</link>
	<link name="26">
		<visual>
			<geometry>
				<cylinder length="0.5895765108887729" radius="0.607391736853669"/>
			</geometry>
		</visual>
		<collision>
			<geometry>
				<cylinder length="0.5895765108887729" radius="0.607391736853669"/>
			</geometry>
		</collision>
		<inertial>
			<mass value="0.41090573523269014"/>
			<inertia ixx="0.0003" iyy="0.0003" izz="0.0003"/>
		</inertial>
	</link>
	<link name="27">
		<visual>
			<geometry>
				<cylinder length="0.5895765108887729" radius="0.607391736853669"/>
			</geometry>
		</visual>
		<collision>
			<geometry>
				<cylinder length="0.5895765108887729" radius="0.607391736853669"/>
			</geometry>
		</collision>
		<inertial>
			<mass value="0.41090573523269014"/>
			<inertia ixx="0.0003" iyy="0.0003" izz="0.0003"/>
		</inertial>
	</link>
	<link name="28">
		<visual>
			<geometry>
				<cylinder length="0.5895765108887729" radius="0.607391736853669"/>
			</geometry>
		</visual>
		<collision>
			<geometry>
				<cylinder length="0.5895765108887729" radius="0.607391736853669"/>
			</geometry>
		</collision>
		<inertial>
			<mass value="0.41090573523269014"/>
			<inertia ixx="0.0003" iyy="0.0003" izz="0.0003"/>
		</inertial>
	</link>
	<joint name="0_to_11" type="revolute">
		<parent link="0"/>
		<child link="11"/>
		<axis xyz="1 0 0"/>
		<limit effort="1" velocity="1"/>
		<origin rpy="9.772587138913252 6.135237077640203 4.673844728901479" xyz="0.41173728907590745 0.7121282447210531 0.5824931766248451"/>
	</joint>
	<joint name="11_to_22" type="revolute">
		<parent link="11"/>
		<child link="22"/>
		<axis xyz="1 0 0"/>
		<limit effort="1" velocity="1"/>
		<origin rpy="2.102332137072244 1.5801231317912616 6.119977702978318" xyz="0.953866148735442 0.6548537646260819 0.11013515940345642"/>
	</joint>
	<joint name="11_to_23" type="revolute">
		<parent link="11"/>
		<child link="23"/>
		<axis xyz="1 0 0"/>
		<limit effort="1" velocity="1"/>
		<origin rpy="3.153498205608366 1.5801231317912616 6.119977702978318" xyz="0.953866148735442 0.6548537646260819 0.11013515940345642"/>
	</joint>
	<joint name="11_to_24" type="revolute">
		<parent link="11"/>
		<child link="24"/>
		<axis xyz="1 0 0"/>
		<limit effort="1" velocity="1"/>
		<origin rpy="4.204664274144488 1.5801231317912616 6.119977702978318" xyz="0.953866148735442 0.6548537646260819 0.11013515940345642"/>
	</joint>
	<joint name="0_to_15" type="revolute">
		<parent link="0"/>
		<child link="15"/>
		<axis xyz="1 0 0"/>
		<limit effort="1" velocity="1"/>
		<origin rpy="14.658880708369878 6.135237077640203 4.673844728901479" xyz="0.41173728907590745 0.7121282447210531 0.5824931766248451"/>
	</joint>
	<joint name="15_to_26" type="revolute">
		<parent link="15"/>
		<child link="26"/>
		<axis xyz="1 0 0"/>
		<limit effort="1" velocity="1"/>
		<origin rpy="2.102332137072244 1.5801231317912616 6.119977702978318" xyz="0.953866148735442 0.6548537646260819 0.11013515940345642"/>
	</joint>
	<joint name="15_to_27" type="revolute">
		<parent link="15"/>
		<child link="27"/>
		<axis xyz="1 0 0"/>
		<limit effort="1" velocity="1"/>
		<origin rpy="3.153498205608366 1.5801231317912616 6.119977702978318" xyz="0.953866148735442 0.6548537646260819 0.11013515940345642"/>
	</joint>
	<joint name="15_to_28" type="revolute">
		<parent link="15"/>
		<child link="28"/>
		<axis xyz="1 0 0"/>
		<limit effort="1" velocity="1"/>
		<origin rpy="4.204664274144488 1.5801231317912616 6.119977702978318" xyz="0.953866148735442 0.6548537646260819 0.11013515940345642"/>
	</joint>
</robot>
