<?xml version="1.0"?><robot name="ted">
	<link name="0">
		<visual>
			<geometry>
				<cylinder length="0.21275301331532537" radius="0.6738214328149634"/>
			</geometry>
		</visual>
		<collision>
			<geometry>
				<cylinder length="0.21275301331532537" radius="0.6738214328149634"/>
			</geometry>
		</collision>
		<inertial>
			<mass value="-0.041928476734819975"/>
			<inertia ixx="0.0003" iyy="0.0003" izz="0.0003"/>
		</inertial>
	</link>
	<link name="11">
		<visual>
			<geometry>
				<cylinder length="0.20148864524368926" radius="0.39336189641222474"/>
			</geometry>
		</visual>
		<collision>
			<geometry>
				<cylinder length="0.20148864524368926" radius="0.39336189641222474"/>
			</geometry>
		</collision>
		<inertial>
			<mass value="0.11888556824783847"/>
			<inertia ixx="0.0003" iyy="0.0003" izz="0.0003"/>
		</inertial>
	</link>
	<link name="12">
		<visual>
			<geometry>
				<cylinder length="0.20148864524368926" radius="0.39336189641222474"/>
			</geometry>
		</visual>
		<collision>
			<geometry>
				<cylinder length="0.20148864524368926" radius="0.39336189641222474"/>
			</geometry>
		</collision>
		<inertial>
			<mass value="0.11888556824783847"/>
			<inertia ixx="0.0003" iyy="0.0003" izz="0.0003"/>
		</inertial>
	</link>
	<link name="13">
		<visual>
			<geometry>
				<cylinder length="0.20148864524368926" radius="0.39336189641222474"/>
			</geometry>
		</visual>
		<collision>
			<geometry>
				<cylinder length="0.20148864524368926" radius="0.39336189641222474"/>
			</geometry>
		</collision>
		<inertial>
			<mass value="0.11888556824783847"/>
			<inertia ixx="0.0003" iyy="0.0003" izz="0.0003"/>
		</inertial>
	</link>
	<joint name="0_to_11" type="revolute">
		<parent link="0"/>
		<child link="11"/>
		<axis xyz="1 0 0"/>
		<limit effort="1" velocity="1"/>
		<origin rpy="1.0264651742255158 2.8809326456153213 2.0432824326917585" xyz="0.8406967620585992 0.17178042112934833 0.5677756171937046"/>
	</joint>
	<joint name="0_to_12" type="revolute">
		<parent link="0"/>
		<child link="12"/>
		<axis xyz="1 0 0"/>
		<limit effort="1" velocity="1"/>
		<origin rpy="1.5396977613382736 2.8809326456153213 2.0432824326917585" xyz="0.8406967620585992 0.17178042112934833 0.5677756171937046"/>
	</joint>
	<joint name="0_to_13" type="revolute">
		<parent link="0"/>
		<child link="13"/>
		<axis xyz="1 0 0"/>
		<limit effort="1" velocity="1"/>
		<origin rpy="2.0529303484510315 2.8809326456153213 2.0432824326917585" xyz="0.8406967620585992 0.17178042112934833 0.5677756171937046"/>
	</joint>
</robot>
