<?xml version="1.0"?><robot name="ted">
	<link name="0">
		<visual>
			<geometry>
				<cylinder length="0.8572744288386839" radius="0.27774521493392745"/>
			</geometry>
		</visual>
		<collision>
			<geometry>
				<cylinder length="0.8572744288386839" radius="0.27774521493392745"/>
			</geometry>
		</collision>
		<inertial>
			<mass value="0.5727515049594439"/>
			<inertia ixx="0.0003" iyy="0.0003" izz="0.0003"/>
		</inertial>
	</link>
	<link name="11">
		<visual>
			<geometry>
				<cylinder length="0.5298200372119601" radius="0.9061586023718584"/>
			</geometry>
		</visual>
		<collision>
			<geometry>
				<cylinder length="0.5298200372119601" radius="0.9061586023718584"/>
			</geometry>
		</collision>
		<inertial>
			<mass value="0.1682654256186824"/>
			<inertia ixx="0.0003" iyy="0.0003" izz="0.0003"/>
		</inertial>
	</link>
	<link name="12">
		<visual>
			<geometry>
				<cylinder length="0.5298200372119601" radius="0.9061586023718584"/>
			</geometry>
		</visual>
		<collision>
			<geometry>
				<cylinder length="0.5298200372119601" radius="0.9061586023718584"/>
			</geometry>
		</collision>
		<inertial>
			<mass value="0.1682654256186824"/>
			<inertia ixx="0.0003" iyy="0.0003" izz="0.0003"/>
		</inertial>
	</link>
	<link name="23">
		<visual>
			<geometry>
				<cylinder length="0.6917308004086973" radius="0.08620360313467035"/>
			</geometry>
		</visual>
		<collision>
			<geometry>
				<cylinder length="0.6917308004086973" radius="0.08620360313467035"/>
			</geometry>
		</collision>
		<inertial>
			<mass value="0.5348341843777173"/>
			<inertia ixx="0.0003" iyy="0.0003" izz="0.0003"/>
		</inertial>
	</link>
	<joint name="0_to_11" type="revolute">
		<parent link="0"/>
		<child link="11"/>
		<axis xyz="1 0 0"/>
		<limit effort="1" velocity="1"/>
		<origin rpy="9.927502455383138 2.9538544921693948 1.67510710532705" xyz="0.0854493099546173 0.5597876151517075 0.8133481299798041"/>
	</joint>
	<joint name="0_to_12" type="revolute">
		<parent link="0"/>
		<child link="12"/>
		<axis xyz="1 0 0"/>
		<limit effort="1" velocity="1"/>
		<origin rpy="14.891253683074707 2.9538544921693948 1.67510710532705" xyz="0.0854493099546173 0.5597876151517075 0.8133481299798041"/>
	</joint>
	<joint name="0_to_23" type="fixed">
		<parent link="0"/>
		<child link="23"/>
		<axis xyz="1 0 0"/>
		<limit effort="1" velocity="1"/>
		<origin rpy="13.248666557600203 6.064974791973338 2.1507414822589466" xyz="0.8135121865456393 0.39925524710584415 0.6843857510679386"/>
	</joint>
</robot>
