<?xml version="1.0"?><robot name="ted">
	<link name="0">
		<visual>
			<geometry>
				<cylinder length="0.08362857678284821" radius="0.12659549976073547"/>
			</geometry>
		</visual>
		<collision>
			<geometry>
				<cylinder length="0.08362857678284821" radius="0.12659549976073547"/>
			</geometry>
		</collision>
		<inertial>
			<mass value="0.629148095208603"/>
			<inertia ixx="0.0003" iyy="0.0003" izz="0.0003"/>
		</inertial>
	</link>
	<link name="11">
		<visual>
			<geometry>
				<cylinder length="0.9811320598336706" radius="0.08031974557518295"/>
			</geometry>
		</visual>
		<collision>
			<geometry>
				<cylinder length="0.9811320598336706" radius="0.08031974557518295"/>
			</geometry>
		</collision>
		<inertial>
			<mass value="0.09942286620343765"/>
			<inertia ixx="0.0003" iyy="0.0003" izz="0.0003"/>
		</inertial>
	</link>
	<link name="22">
		<visual>
			<geometry>
				<cylinder length="0.6991898790985246" radius="0.19123660263291598"/>
			</geometry>
		</visual>
		<collision>
			<geometry>
				<cylinder length="0.6991898790985246" radius="0.19123660263291598"/>
			</geometry>
		</collision>
		<inertial>
			<mass value="0.7540583787106416"/>
			<inertia ixx="0.0003" iyy="0.0003" izz="0.0003"/>
		</inertial>
	</link>
	<link name="23">
		<visual>
			<geometry>
				<cylinder length="0.6991898790985246" radius="0.19123660263291598"/>
			</geometry>
		</visual>
		<collision>
			<geometry>
				<cylinder length="0.6991898790985246" radius="0.19123660263291598"/>
			</geometry>
		</collision>
		<inertial>
			<mass value="0.7540583787106416"/>
			<inertia ixx="0.0003" iyy="0.0003" izz="0.0003"/>
		</inertial>
	</link>
	<link name="24">
		<visual>
			<geometry>
				<cylinder length="0.6991898790985246" radius="0.19123660263291598"/>
			</geometry>
		</visual>
		<collision>
			<geometry>
				<cylinder length="0.6991898790985246" radius="0.19123660263291598"/>
			</geometry>
		</collision>
		<inertial>
			<mass value="0.7540583787106416"/>
			<inertia ixx="0.0003" iyy="0.0003" izz="0.0003"/>
		</inertial>
	</link>
	<link name="25">
		<visual>
			<geometry>
				<cylinder length="0.6991898790985246" radius="0.19123660263291598"/>
			</geometry>
		</visual>
		<collision>
			<geometry>
				<cylinder length="0.6991898790985246" radius="0.19123660263291598"/>
			</geometry>
		</collision>
		<inertial>
			<mass value="0.7540583787106416"/>
			<inertia ixx="0.0003" iyy="0.0003" izz="0.0003"/>
		</inertial>
	</link>
	<link name="16">
		<visual>
			<geometry>
				<cylinder length="0.9811320598336706" radius="0.08031974557518295"/>
			</geometry>
		</visual>
		<collision>
			<geometry>
				<cylinder length="0.9811320598336706" radius="0.08031974557518295"/>
			</geometry>
		</collision>
		<inertial>
			<mass value="0.09942286620343765"/>
			<inertia ixx="0.0003" iyy="0.0003" izz="0.0003"/>
		</inertial>
	</link>
	<link name="27">
		<visual>
			<geometry>
				<cylinder length="0.6991898790985246" radius="0.19123660263291598"/>
			</geometry>
		</visual>
		<collision>
			<geometry>
				<cylinder length="0.6991898790985246" radius="0.19123660263291598"/>
			</geometry>
		</collision>
		<inertial>
			<mass value="0.7540583787106416"/>
			<inertia ixx="0.0003" iyy="0.0003" izz="0.0003"/>
		</inertial>
	</link>
	<link name="28">
		<visual>
			<geometry>
				<cylinder length="0.6991898790985246" radius="0.19123660263291598"/>
			</geometry>
		</visual>
		<collision>
			<geometry>
				<cylinder length="0.6991898790985246" radius="0.19123660263291598"/>
			</geometry>
		</collision>
		<inertial>
			<mass value="0.7540583787106416"/>
			<inertia ixx="0.0003" iyy="0.0003" izz="0.0003"/>
		</inertial>
	</link>
	<link name="29">
		<visual>
			<geometry>
				<cylinder length="0.6991898790985246" radius="0.19123660263291598"/>
			</geometry>
		</visual>
		<collision>
			<geometry>
				<cylinder length="0.6991898790985246" radius="0.19123660263291598"/>
			</geometry>
		</collision>
		<inertial>
			<mass value="0.7540583787106416"/>
			<inertia ixx="0.0003" iyy="0.0003" izz="0.0003"/>
		</inertial>
	</link>
	<link name="210">
		<visual>
			<geometry>
				<cylinder length="0.6991898790985246" radius="0.19123660263291598"/>
			</geometry>
		</visual>
		<collision>
			<geometry>
				<cylinder length="0.6991898790985246" radius="0.19123660263291598"/>
			</geometry>
		</collision>
		<inertial>
			<mass value="0.7540583787106416"/>
			<inertia ixx="0.0003" iyy="0.0003" izz="0.0003"/>
		</inertial>
	</link>
	<link name="111">
		<visual>
			<geometry>
				<cylinder length="0.9811320598336706" radius="0.08031974557518295"/>
			</geometry>
		</visual>
		<collision>
			<geometry>
				<cylinder length="0.9811320598336706" radius="0.08031974557518295"/>
			</geometry>
		</collision>
		<inertial>
			<mass value="0.09942286620343765"/>
			<inertia ixx="0.0003" iyy="0.0003" izz="0.0003"/>
		</inertial>
	</link>
	<link name="212">
		<visual>
			<geometry>
				<cylinder length="0.6991898790985246" radius="0.19123660263291598"/>
			</geometry>
		</visual>
		<collision>
			<geometry>
				<cylinder length="0.6991898790985246" radius="0.19123660263291598"/>
			</geometry>
		</collision>
		<inertial>
			<mass value="0.7540583787106416"/>
			<inertia ixx="0.0003" iyy="0.0003" izz="0.0003"/>
		</inertial>
	</link>
	<link name="213">
		<visual>
			<geometry>
				<cylinder length="0.6991898790985246" radius="0.19123660263291598"/>
			</geometry>
		</visual>
		<collision>
			<geometry>
				<cylinder length="0.6991898790985246" radius="0.19123660263291598"/>
			</geometry>
		</collision>
		<inertial>
			<mass value="0.7540583787106416"/>
			<inertia ixx="0.0003" iyy="0.0003" izz="0.0003"/>
		</inertial>
	</link>
	<link name="214">
		<visual>
			<geometry>
				<cylinder length="0.6991898790985246" radius="0.19123660263291598"/>
			</geometry>
		</visual>
		<collision>
			<geometry>
				<cylinder length="0.6991898790985246" radius="0.19123660263291598"/>
			</geometry>
		</collision>
		<inertial>
			<mass value="0.7540583787106416"/>
			<inertia ixx="0.0003" iyy="0.0003" izz="0.0003"/>
		</inertial>
	</link>
	<link name="215">
		<visual>
			<geometry>
				<cylinder length="0.6991898790985246" radius="0.19123660263291598"/>
			</geometry>
		</visual>
		<collision>
			<geometry>
				<cylinder length="0.6991898790985246" radius="0.19123660263291598"/>
			</geometry>
		</collision>
		<inertial>
			<mass value="0.7540583787106416"/>
			<inertia ixx="0.0003" iyy="0.0003" izz="0.0003"/>
		</inertial>
	</link>
	<link name="116">
		<visual>
			<geometry>
				<cylinder length="0.9811320598336706" radius="0.08031974557518295"/>
			</geometry>
		</visual>
		<collision>
			<geometry>
				<cylinder length="0.9811320598336706" radius="0.08031974557518295"/>
			</geometry>
		</collision>
		<inertial>
			<mass value="0.09942286620343765"/>
			<inertia ixx="0.0003" iyy="0.0003" izz="0.0003"/>
		</inertial>
	</link>
	<link name="217">
		<visual>
			<geometry>
				<cylinder length="0.6991898790985246" radius="0.19123660263291598"/>
			</geometry>
		</visual>
		<collision>
			<geometry>
				<cylinder length="0.6991898790985246" radius="0.19123660263291598"/>
			</geometry>
		</collision>
		<inertial>
			<mass value="0.7540583787106416"/>
			<inertia ixx="0.0003" iyy="0.0003" izz="0.0003"/>
		</inertial>
	</link>
	<link name="218">
		<visual>
			<geometry>
				<cylinder length="0.6991898790985246" radius="0.19123660263291598"/>
			</geometry>
		</visual>
		<collision>
			<geometry>
				<cylinder length="0.6991898790985246" radius="0.19123660263291598"/>
			</geometry>
		</collision>
		<inertial>
			<mass value="0.7540583787106416"/>
			<inertia ixx="0.0003" iyy="0.0003" izz="0.0003"/>
		</inertial>
	</link>
	<link name="219">
		<visual>
			<geometry>
				<cylinder length="0.6991898790985246" radius="0.19123660263291598"/>
			</geometry>
		</visual>
		<collision>
			<geometry>
				<cylinder length="0.6991898790985246" radius="0.19123660263291598"/>
			</geometry>
		</collision>
		<inertial>
			<mass value="0.7540583787106416"/>
			<inertia ixx="0.0003" iyy="0.0003" izz="0.0003"/>
		</inertial>
	</link>
	<link name="220">
		<visual>
			<geometry>
				<cylinder length="0.6991898790985246" radius="0.19123660263291598"/>
			</geometry>
		</visual>
		<collision>
			<geometry>
				<cylinder length="0.6991898790985246" radius="0.19123660263291598"/>
			</geometry>
		</collision>
		<inertial>
			<mass value="0.7540583787106416"/>
			<inertia ixx="0.0003" iyy="0.0003" izz="0.0003"/>
		</inertial>
	</link>
	<joint name="0_to_11" type="revolute">
		<parent link="0"/>
		<child link="11"/>
		<axis xyz="1 0 0"/>
		<limit effort="1" velocity="1"/>
		<origin rpy="1.365134209055266 3.861730201508749 2.3940423924812095" xyz="0.9259227834380324 0.4392173494824769 0.07150675950979635"/>
	</joint>
	<joint name="11_to_22" type="fixed">
		<parent link="11"/>
		<child link="22"/>
		<axis xyz="1 0 0"/>
		<limit effort="1" velocity="1"/>
		<origin rpy="5.763305392891427 5.232060108314862 1.0089175033444535" xyz="0.11033322378713772 0.8908296461292531 0.2933557551745225"/>
	</joint>
	<joint name="11_to_23" type="fixed">
		<parent link="11"/>
		<child link="23"/>
		<axis xyz="1 0 0"/>
		<limit effort="1" velocity="1"/>
		<origin rpy="8.644958089337141 5.232060108314862 1.0089175033444535" xyz="0.11033322378713772 0.8908296461292531 0.2933557551745225"/>
	</joint>
	<joint name="11_to_24" type="fixed">
		<parent link="11"/>
		<child link="24"/>
		<axis xyz="1 0 0"/>
		<limit effort="1" velocity="1"/>
		<origin rpy="11.526610785782854 5.232060108314862 1.0089175033444535" xyz="0.11033322378713772 0.8908296461292531 0.2933557551745225"/>
	</joint>
	<joint name="11_to_25" type="fixed">
		<parent link="11"/>
		<child link="25"/>
		<axis xyz="1 0 0"/>
		<limit effort="1" velocity="1"/>
		<origin rpy="14.408263482228566 5.232060108314862 1.0089175033444535" xyz="0.11033322378713772 0.8908296461292531 0.2933557551745225"/>
	</joint>
	<joint name="0_to_16" type="revolute">
		<parent link="0"/>
		<child link="16"/>
		<axis xyz="1 0 0"/>
		<limit effort="1" velocity="1"/>
		<origin rpy="2.047701313582899 3.861730201508749 2.3940423924812095" xyz="0.9259227834380324 0.4392173494824769 0.07150675950979635"/>
	</joint>
	<joint name="16_to_27" type="fixed">
		<parent link="16"/>
		<child link="27"/>
		<axis xyz="1 0 0"/>
		<limit effort="1" velocity="1"/>
		<origin rpy="5.763305392891427 5.232060108314862 1.0089175033444535" xyz="0.11033322378713772 0.8908296461292531 0.2933557551745225"/>
	</joint>
	<joint name="16_to_28" type="fixed">
		<parent link="16"/>
		<child link="28"/>
		<axis xyz="1 0 0"/>
		<limit effort="1" velocity="1"/>
		<origin rpy="8.644958089337141 5.232060108314862 1.0089175033444535" xyz="0.11033322378713772 0.8908296461292531 0.2933557551745225"/>
	</joint>
	<joint name="16_to_29" type="fixed">
		<parent link="16"/>
		<child link="29"/>
		<axis xyz="1 0 0"/>
		<limit effort="1" velocity="1"/>
		<origin rpy="11.526610785782854 5.232060108314862 1.0089175033444535" xyz="0.11033322378713772 0.8908296461292531 0.2933557551745225"/>
	</joint>
	<joint name="16_to_210" type="fixed">
		<parent link="16"/>
		<child link="210"/>
		<axis xyz="1 0 0"/>
		<limit effort="1" velocity="1"/>
		<origin rpy="14.408263482228566 5.232060108314862 1.0089175033444535" xyz="0.11033322378713772 0.8908296461292531 0.2933557551745225"/>
	</joint>
	<joint name="0_to_111" type="revolute">
		<parent link="0"/>
		<child link="111"/>
		<axis xyz="1 0 0"/>
		<limit effort="1" velocity="1"/>
		<origin rpy="2.730268418110532 3.861730201508749 2.3940423924812095" xyz="0.9259227834380324 0.4392173494824769 0.07150675950979635"/>
	</joint>
	<joint name="111_to_212" type="fixed">
		<parent link="111"/>
		<child link="212"/>
		<axis xyz="1 0 0"/>
		<limit effort="1" velocity="1"/>
		<origin rpy="5.763305392891427 5.232060108314862 1.0089175033444535" xyz="0.11033322378713772 0.8908296461292531 0.2933557551745225"/>
	</joint>
	<joint name="111_to_213" type="fixed">
		<parent link="111"/>
		<child link="213"/>
		<axis xyz="1 0 0"/>
		<limit effort="1" velocity="1"/>
		<origin rpy="8.644958089337141 5.232060108314862 1.0089175033444535" xyz="0.11033322378713772 0.8908296461292531 0.2933557551745225"/>
	</joint>
	<joint name="111_to_214" type="fixed">
		<parent link="111"/>
		<child link="214"/>
		<axis xyz="1 0 0"/>
		<limit effort="1" velocity="1"/>
		<origin rpy="11.526610785782854 5.232060108314862 1.0089175033444535" xyz="0.11033322378713772 0.8908296461292531 0.2933557551745225"/>
	</joint>
	<joint name="111_to_215" type="fixed">
		<parent link="111"/>
		<child link="215"/>
		<axis xyz="1 0 0"/>
		<limit effort="1" velocity="1"/>
		<origin rpy="14.408263482228566 5.232060108314862 1.0089175033444535" xyz="0.11033322378713772 0.8908296461292531 0.2933557551745225"/>
	</joint>
	<joint name="0_to_116" type="revolute">
		<parent link="0"/>
		<child link="116"/>
		<axis xyz="1 0 0"/>
		<limit effort="1" velocity="1"/>
		<origin rpy="3.412835522638165 3.861730201508749 2.3940423924812095" xyz="0.9259227834380324 0.4392173494824769 0.07150675950979635"/>
	</joint>
	<joint name="116_to_217" type="fixed">
		<parent link="116"/>
		<child link="217"/>
		<axis xyz="1 0 0"/>
		<limit effort="1" velocity="1"/>
		<origin rpy="5.763305392891427 5.232060108314862 1.0089175033444535" xyz="0.11033322378713772 0.8908296461292531 0.2933557551745225"/>
	</joint>
	<joint name="116_to_218" type="fixed">
		<parent link="116"/>
		<child link="218"/>
		<axis xyz="1 0 0"/>
		<limit effort="1" velocity="1"/>
		<origin rpy="8.644958089337141 5.232060108314862 1.0089175033444535" xyz="0.11033322378713772 0.8908296461292531 0.2933557551745225"/>
	</joint>
	<joint name="116_to_219" type="fixed">
		<parent link="116"/>
		<child link="219"/>
		<axis xyz="1 0 0"/>
		<limit effort="1" velocity="1"/>
		<origin rpy="11.526610785782854 5.232060108314862 1.0089175033444535" xyz="0.11033322378713772 0.8908296461292531 0.2933557551745225"/>
	</joint>
	<joint name="116_to_220" type="fixed">
		<parent link="116"/>
		<child link="220"/>
		<axis xyz="1 0 0"/>
		<limit effort="1" velocity="1"/>
		<origin rpy="14.408263482228566 5.232060108314862 1.0089175033444535" xyz="0.11033322378713772 0.8908296461292531 0.2933557551745225"/>
	</joint>
</robot>
