<?xml version="1.0"?>
<robot name="car">
  <link name="chassis">
    <visual>
      <geometry>
        <box size="1.6 0.8 0.2"/>
      </geometry>
    </visual>
    <collision>
      <geometry>
        <box size="1.6 0.8 0.2"/>
      </geometry>
    </collision>
    <inertial>
      <mass value="10.0"/>
      <inertia ixx="0.0003" ixy="0.0003" ixz="0.0003" iyy="0" iyz="0" izz="0"/>
    </inertial>
  </link>

  <joint name="axel_01" type="revolute">
    <parent link="chassis"/>
    <child link="wheel_01"/>
    <axis xyz="0 0 1"/>
    <limit lower="0" upper="10" effort="10" velocity="1"/>
    <origin xyz="0.5 0.5 0.0" rpy="1.6 0 0"/>
  </joint>

  <link name="wheel_01">
    <visual>
      <geometry>
        <cylinder length="0.2" radius="0.4"/>
      </geometry>
    </visual>
    <collision>
      <geometry>
        <cylinder length="0.2" radius="0.4"/>
      </geometry>
    </collision>
    <inertial>
      <mass value="5"/>
      <inertia ixx="0.0003" ixy="0.0003" ixz="0.0003" iyy="0" iyz="0" izz="0"/>
    </inertial>
  </link>

  <joint name="axel_02" type="revolute">
    <parent link="chassis"/>
    <child link="wheel_02"/>
    <axis xyz="0 0 1"/>
    <limit lower="0" upper="10" effort="10" velocity="1"/>
    <origin xyz="-0.5 0.5 0.0" rpy="1.6 0 0"/>
  </joint>

  <link name="wheel_02">
    <visual>
      <geometry>
        <cylinder length="0.2" radius="0.4"/>
      </geometry>
    </visual>
    <collision>
      <geometry>
        <cylinder length="0.2" radius="0.4"/>
      </geometry>
    </collision>
    <inertial>
      <mass value="5"/>
      <inertia ixx="0.0003" ixy="0.0003" ixz="0.0003" iyy="0" iyz="0" izz="0"/>
    </inertial>
  </link>

  <joint name="axel_03" type="revolute">
    <parent link="chassis"/>
    <child link="wheel_03"/>
    <axis xyz="0 0 1"/>
    <limit lower="0" upper="10" effort="10" velocity="1"/>
    <origin xyz="0.5 -0.5 0.0" rpy="1.6 0 0"/>
  </joint>

  <link name="wheel_03">
    <visual>
      <geometry>
        <cylinder length="0.2" radius="0.4"/>
      </geometry>
    </visual>
    <collision>
      <geometry>
        <cylinder length="0.2" radius="0.4"/>
      </geometry>
    </collision>
    <inertial>
      <mass value="5"/>
      <inertia ixx="0.0003" ixy="0.0003" ixz="0.0003" iyy="0" iyz="0" izz="0"/>
    </inertial>
  </link>

  <joint name="axel_04" type="revolute">
    <parent link="chassis"/>
    <child link="wheel_04"/>
    <axis xyz="0 0 1"/>
    <limit lower="0" upper="10" effort="10" velocity="1"/>
    <origin xyz="-0.5 -0.5 0.0" rpy="1.6 0 0"/>
  </joint>

  <link name="wheel_04">
    <visual>
      <geometry>
        <cylinder length="0.2" radius="0.4"/>
      </geometry>
    </visual>
    <collision>
      <geometry>
        <cylinder length="0.2" radius="0.4"/>
      </geometry>
    </collision>
    <inertial>
      <mass value="5"/>
      <inertia ixx="0.0003" ixy="0.0003" ixz="0.0003" iyy="0" iyz="0" izz="0"/>
    </inertial>
  </link>

</robot>
