<?xml version="1.0"?>
<robot name="myfirst">
	<!--	LINK DATA-->
	<link name="base_link">
	<visual>
		<geometry>
			<cylinder length="0.1" radius="0.3" />
		</geometry>
					<material name="Red1">
		<color rgba="1 0 0 1.0" />
	</material>
	</visual>
	<collision>
		<geometry>
			<cylinder length="0.1" radius="0.3" />
		</geometry>
	</collision>
	<inertial>
		<mass value="0.25" />
		<inertia ixx="0.0003" iyy="0.0003" izz="0.0003" ixy="0" ixz="0" iyz="0" />
	</inertial>
	</link>
	<link name="wheel_1">
	<visual>
		<geometry>
			<cylinder length="0.05" radius="0.08" />
		</geometry>
		<material name="Cyan1">
			<color rgba="0 0.9 0.9 1.0" />
		</material>
	</visual>
	<collision>
		<geometry>
			<cylinder length="0.05" radius="0.08" />
		</geometry>
	</collision>
	<inertial>
		<mass value="0.25" />
		<inertia ixx="0.0003" iyy="0.0003" izz="0.0003" ixy="0" ixz="0" iyz="0" />
	</inertial>
	</link>
	<link name="wheel_2">
	<visual>
		<geometry>
			<cylinder length="0.05" radius="0.08" />
		</geometry>
		<material name="Cyan1">
			<color rgba="0 0.9 0.9 1.0" />
		</material>
	</visual>
	<collision>
		<geometry>
			<cylinder length="0.05" radius="0.08" />
		</geometry>
	</collision>
	<inertial>
		<mass value="0.25" />
		<inertia ixx="0.0003" iyy="0.0003" izz="0.0003" ixy="0" ixz="0" iyz="0" />
	</inertial>
	</link>

<!--	JOINT DATA-->
	<joint name="base_to_wheel_1" type="revolute">
		<parent link="base_link" />
		<child link="wheel_1" />
		<axis xyz="0 0 1" />
		<limit effort="10" upper="0" lower="10" velocity="1" />
		<origin rpy="-1.55 0 0" xyz="0 -0.3 -0.06" />
	</joint>
	<joint name="base_to_wheel_2" type="revolute">
		<parent link="base_link" />
		<child link="wheel_2" />
		<axis xyz="0 0 1" />
		<limit effort="10" upper="0" lower="10" velocity="1" />
		<origin rpy="-1.55 0 0" xyz="0 0.3 -0.06" />
	</joint>
</robot>
